[2022-09-03 15:37:23,306] {taskinstance.py:1032} INFO - Dependencies all met for <TaskInstance: etl_airflow.Load scheduled__2022-09-03T00:00:00+00:00 [queued]>
[2022-09-03 15:37:23,310] {taskinstance.py:1032} INFO - Dependencies all met for <TaskInstance: etl_airflow.Load scheduled__2022-09-03T00:00:00+00:00 [queued]>
[2022-09-03 15:37:23,310] {taskinstance.py:1238} INFO - 
--------------------------------------------------------------------------------
[2022-09-03 15:37:23,310] {taskinstance.py:1239} INFO - Starting attempt 1 of 1
[2022-09-03 15:37:23,310] {taskinstance.py:1240} INFO - 
--------------------------------------------------------------------------------
[2022-09-03 15:37:23,315] {taskinstance.py:1259} INFO - Executing <Task(PythonOperator): Load> on 2022-09-03 00:00:00+00:00
[2022-09-03 15:37:23,322] {standard_task_runner.py:52} INFO - Started process 43867 to run task
[2022-09-03 15:37:23,327] {standard_task_runner.py:76} INFO - Running: ['airflow', 'tasks', 'run', 'etl_airflow', 'Load', 'scheduled__2022-09-03T00:00:00+00:00', '--job-id', '694', '--raw', '--subdir', 'DAGS_FOLDER/etl_airflowv2.py', '--cfg-path', '/var/folders/35/pzst1sv14yld_nkt23lk_vmr0000gn/T/tmph2tepxzt', '--error-file', '/var/folders/35/pzst1sv14yld_nkt23lk_vmr0000gn/T/tmprtfymb7d']
[2022-09-03 15:37:23,328] {standard_task_runner.py:77} INFO - Job 694: Subtask Load
[2022-09-03 15:37:23,351] {logging_mixin.py:109} INFO - Running <TaskInstance: etl_airflow.Load scheduled__2022-09-03T00:00:00+00:00 [running]> on host 1.0.0.127.in-addr.arpa
[2022-09-03 15:37:23,372] {taskinstance.py:1424} INFO - Exporting the following env vars:
AIRFLOW_CTX_DAG_EMAIL=jonathan.dejesus.azor@gmail.com
AIRFLOW_CTX_DAG_OWNER=admin
AIRFLOW_CTX_DAG_ID=etl_airflow
AIRFLOW_CTX_TASK_ID=Load
AIRFLOW_CTX_EXECUTION_DATE=2022-09-03T00:00:00+00:00
AIRFLOW_CTX_DAG_RUN_ID=scheduled__2022-09-03T00:00:00+00:00
[2022-09-03 15:37:26,587] {_metadata.py:99} WARNING - Compute Engine Metadata server unavailable on attempt 1 of 3. Reason: timed out
[2022-09-03 15:37:29,590] {_metadata.py:99} WARNING - Compute Engine Metadata server unavailable on attempt 2 of 3. Reason: timed out
[2022-09-03 15:37:29,592] {_metadata.py:99} WARNING - Compute Engine Metadata server unavailable on attempt 3 of 3. Reason: [Errno 64] Host is down
[2022-09-03 15:37:29,593] {_default.py:290} WARNING - Authentication failed using Compute Engine authentication due to unavailable metadata server.
[2022-09-03 15:37:30,756] {logging_mixin.py:109} WARNING - Downloading:   0%|          | 0/10 [00:00<?, ?rows/s]
[2022-09-03 15:37:30,991] {logging_mixin.py:109} WARNING - Downloading: 100%|##########| 10/10 [00:00<00:00, 43.06rows/s]
[2022-09-03 15:37:30,993] {logging_mixin.py:109} WARNING - Downloading: 100%|##########| 10/10 [00:00<00:00, 42.32rows/s]
[2022-09-03 15:37:30,994] {logging_mixin.py:109} WARNING - 
[2022-09-03 15:37:36,465] {logging_mixin.py:109} WARNING -   0%|          | 0/1 [00:00<?, ?it/s]
[2022-09-03 15:37:36,466] {gbq.py:604} INFO - 10 out of 10 rows loaded.
[2022-09-03 15:37:36,468] {logging_mixin.py:109} WARNING - 100%|##########| 1/1 [00:00<00:00, 771.01it/s]
[2022-09-03 15:37:36,469] {logging_mixin.py:109} WARNING - 
[2022-09-03 15:37:36,469] {logging_mixin.py:109} INFO - Done, please check the table
[2022-09-03 15:37:36,470] {python.py:175} INFO - Done. Returned value was: None
[2022-09-03 15:37:36,485] {taskinstance.py:1267} INFO - Marking task as SUCCESS. dag_id=etl_airflow, task_id=Load, execution_date=20220903T000000, start_date=20220903T203723, end_date=20220903T203736
[2022-09-03 15:37:36,522] {local_task_job.py:154} INFO - Task exited with return code 0
[2022-09-03 15:37:36,532] {local_task_job.py:264} INFO - 1 downstream tasks scheduled from follow-on schedule check
