[2022-09-02 12:20:53,118] {taskinstance.py:1032} INFO - Dependencies all met for <TaskInstance: etl_crime.Load scheduled__2022-08-28T01:20:00+00:00 [queued]>
[2022-09-02 12:20:53,121] {taskinstance.py:1032} INFO - Dependencies all met for <TaskInstance: etl_crime.Load scheduled__2022-08-28T01:20:00+00:00 [queued]>
[2022-09-02 12:20:53,121] {taskinstance.py:1238} INFO - 
--------------------------------------------------------------------------------
[2022-09-02 12:20:53,121] {taskinstance.py:1239} INFO - Starting attempt 1 of 1
[2022-09-02 12:20:53,121] {taskinstance.py:1240} INFO - 
--------------------------------------------------------------------------------
[2022-09-02 12:20:53,126] {taskinstance.py:1259} INFO - Executing <Task(PythonOperator): Load> on 2022-08-28 01:20:00+00:00
[2022-09-02 12:20:53,132] {standard_task_runner.py:52} INFO - Started process 36540 to run task
[2022-09-02 12:20:53,137] {standard_task_runner.py:76} INFO - Running: ['airflow', 'tasks', 'run', 'etl_crime', 'Load', 'scheduled__2022-08-28T01:20:00+00:00', '--job-id', '549', '--raw', '--subdir', 'DAGS_FOLDER/etl_bigquery.py', '--cfg-path', '/var/folders/35/pzst1sv14yld_nkt23lk_vmr0000gn/T/tmpinmdokfl', '--error-file', '/var/folders/35/pzst1sv14yld_nkt23lk_vmr0000gn/T/tmpjze8w0dr']
[2022-09-02 12:20:53,138] {standard_task_runner.py:77} INFO - Job 549: Subtask Load
[2022-09-02 12:20:53,162] {logging_mixin.py:109} INFO - Running <TaskInstance: etl_crime.Load scheduled__2022-08-28T01:20:00+00:00 [running]> on host 1.0.0.127.in-addr.arpa
[2022-09-02 12:20:53,184] {taskinstance.py:1424} INFO - Exporting the following env vars:
AIRFLOW_CTX_DAG_EMAIL=jonathan.dejesus.azor@gmail.com
AIRFLOW_CTX_DAG_OWNER=admin
AIRFLOW_CTX_DAG_ID=etl_crime
AIRFLOW_CTX_TASK_ID=Load
AIRFLOW_CTX_EXECUTION_DATE=2022-08-28T01:20:00+00:00
AIRFLOW_CTX_DAG_RUN_ID=scheduled__2022-08-28T01:20:00+00:00
[2022-09-02 12:20:53,395] {_metadata.py:99} WARNING - Compute Engine Metadata server unavailable on attempt 1 of 3. Reason: [Errno 64] Host is down
[2022-09-02 12:20:53,395] {_metadata.py:99} WARNING - Compute Engine Metadata server unavailable on attempt 2 of 3. Reason: [Errno 64] Host is down
[2022-09-02 12:20:53,396] {_metadata.py:99} WARNING - Compute Engine Metadata server unavailable on attempt 3 of 3. Reason: [Errno 64] Host is down
[2022-09-02 12:20:53,396] {_default.py:290} WARNING - Authentication failed using Compute Engine authentication due to unavailable metadata server.
[2022-09-02 12:20:54,519] {logging_mixin.py:109} WARNING - Downloading:   0%|          | 0/200 [00:00<?, ?rows/s]
[2022-09-02 12:20:54,743] {logging_mixin.py:109} WARNING - Downloading: 100%|##########| 200/200 [00:00<00:00, 895.60rows/s]
[2022-09-02 12:20:54,744] {logging_mixin.py:109} WARNING - Downloading: 100%|##########| 200/200 [00:00<00:00, 891.94rows/s]
[2022-09-02 12:20:54,744] {logging_mixin.py:109} WARNING - 
[2022-09-02 12:21:02,700] {logging_mixin.py:109} WARNING -   0%|          | 0/1 [00:00<?, ?it/s]
[2022-09-02 12:21:02,702] {gbq.py:604} INFO - 200 out of 200 rows loaded.
[2022-09-02 12:21:02,704] {logging_mixin.py:109} WARNING - 100%|##########| 1/1 [00:00<00:00, 909.24it/s]
[2022-09-02 12:21:02,705] {logging_mixin.py:109} WARNING - 
[2022-09-02 12:21:02,706] {logging_mixin.py:109} INFO - Done, please check the table
[2022-09-02 12:21:02,707] {python.py:175} INFO - Done. Returned value was: None
[2022-09-02 12:21:02,724] {taskinstance.py:1267} INFO - Marking task as SUCCESS. dag_id=etl_crime, task_id=Load, execution_date=20220828T012000, start_date=20220902T172053, end_date=20220902T172102
[2022-09-02 12:21:02,777] {local_task_job.py:154} INFO - Task exited with return code 0
[2022-09-02 12:21:02,785] {local_task_job.py:264} INFO - 0 downstream tasks scheduled from follow-on schedule check
