[2022-08-28 15:25:22,438] {taskinstance.py:1032} INFO - Dependencies all met for <TaskInstance: ETL_Examples.Transform scheduled__2022-08-28T01:20:00+00:00 [queued]>
[2022-08-28 15:25:22,442] {taskinstance.py:1032} INFO - Dependencies all met for <TaskInstance: ETL_Examples.Transform scheduled__2022-08-28T01:20:00+00:00 [queued]>
[2022-08-28 15:25:22,442] {taskinstance.py:1238} INFO - 
--------------------------------------------------------------------------------
[2022-08-28 15:25:22,442] {taskinstance.py:1239} INFO - Starting attempt 1 of 2
[2022-08-28 15:25:22,442] {taskinstance.py:1240} INFO - 
--------------------------------------------------------------------------------
[2022-08-28 15:25:22,446] {taskinstance.py:1259} INFO - Executing <Task(PythonOperator): Transform> on 2022-08-28 01:20:00+00:00
[2022-08-28 15:25:22,453] {standard_task_runner.py:52} INFO - Started process 30370 to run task
[2022-08-28 15:25:22,457] {standard_task_runner.py:76} INFO - Running: ['airflow', 'tasks', 'run', 'ETL_Examples', 'Transform', 'scheduled__2022-08-28T01:20:00+00:00', '--job-id', '359', '--raw', '--subdir', 'DAGS_FOLDER/Pushtobigquery2.py', '--cfg-path', '/var/folders/35/pzst1sv14yld_nkt23lk_vmr0000gn/T/tmpwhman404', '--error-file', '/var/folders/35/pzst1sv14yld_nkt23lk_vmr0000gn/T/tmpgp1xz9o2']
[2022-08-28 15:25:22,458] {standard_task_runner.py:77} INFO - Job 359: Subtask Transform
[2022-08-28 15:25:22,481] {logging_mixin.py:109} INFO - Running <TaskInstance: ETL_Examples.Transform scheduled__2022-08-28T01:20:00+00:00 [running]> on host 1.0.0.127.in-addr.arpa
[2022-08-28 15:25:22,500] {taskinstance.py:1424} INFO - Exporting the following env vars:
AIRFLOW_CTX_DAG_EMAIL=jonathan.dejesus.azor@gmail.com
AIRFLOW_CTX_DAG_OWNER=admin
AIRFLOW_CTX_DAG_ID=ETL_Examples
AIRFLOW_CTX_TASK_ID=Transform
AIRFLOW_CTX_EXECUTION_DATE=2022-08-28T01:20:00+00:00
AIRFLOW_CTX_DAG_RUN_ID=scheduled__2022-08-28T01:20:00+00:00
[2022-08-28 15:25:22,501] {taskinstance.py:1700} ERROR - Task failed with exception
Traceback (most recent call last):
  File "/opt/anaconda3/lib/python3.9/site-packages/airflow/models/taskinstance.py", line 1329, in _run_raw_task
    self._execute_task_with_callbacks(context)
  File "/opt/anaconda3/lib/python3.9/site-packages/airflow/models/taskinstance.py", line 1455, in _execute_task_with_callbacks
    result = self._execute_task(context, self.task)
  File "/opt/anaconda3/lib/python3.9/site-packages/airflow/models/taskinstance.py", line 1511, in _execute_task
    result = execute_callable(context=context)
  File "/opt/anaconda3/lib/python3.9/site-packages/airflow/operators/python.py", line 174, in execute
    return_value = self.execute_callable()
  File "/opt/anaconda3/lib/python3.9/site-packages/airflow/operators/python.py", line 185, in execute_callable
    return self.python_callable(*self.op_args, **self.op_kwargs)
TypeError: crime_stats_transformation() missing 1 required positional argument: 'filter_df'
[2022-08-28 15:25:22,505] {taskinstance.py:1267} INFO - Marking task as UP_FOR_RETRY. dag_id=ETL_Examples, task_id=Transform, execution_date=20220828T012000, start_date=20220828T202522, end_date=20220828T202522
[2022-08-28 15:25:22,511] {logging_mixin.py:109} WARNING - /opt/anaconda3/lib/python3.9/site-packages/airflow/utils/context.py:152 AirflowContextDeprecationWarning: Accessing 'execution_date' from the template is deprecated and will be removed in a future version. Please use 'data_interval_start' or 'logical_date' instead.
[2022-08-28 15:25:22,512] {logging_mixin.py:109} WARNING - /opt/anaconda3/lib/python3.9/site-packages/airflow/utils/context.py:152 AirflowContextDeprecationWarning: Accessing 'next_ds' from the template is deprecated and will be removed in a future version. Please use '{{ data_interval_end | ds }}' instead.
[2022-08-28 15:25:22,513] {logging_mixin.py:109} WARNING - /opt/anaconda3/lib/python3.9/site-packages/airflow/utils/context.py:152 AirflowContextDeprecationWarning: Accessing 'next_ds_nodash' from the template is deprecated and will be removed in a future version. Please use '{{ data_interval_end | ds_nodash }}' instead.
[2022-08-28 15:25:22,514] {logging_mixin.py:109} WARNING - /opt/anaconda3/lib/python3.9/site-packages/airflow/utils/context.py:152 AirflowContextDeprecationWarning: Accessing 'next_execution_date' from the template is deprecated and will be removed in a future version. Please use 'data_interval_end' instead.
[2022-08-28 15:25:22,514] {logging_mixin.py:109} WARNING - /opt/anaconda3/lib/python3.9/site-packages/airflow/utils/context.py:152 AirflowContextDeprecationWarning: Accessing 'prev_ds' from the template is deprecated and will be removed in a future version.
[2022-08-28 15:25:22,515] {logging_mixin.py:109} WARNING - /opt/anaconda3/lib/python3.9/site-packages/airflow/utils/context.py:152 AirflowContextDeprecationWarning: Accessing 'prev_ds_nodash' from the template is deprecated and will be removed in a future version.
[2022-08-28 15:25:22,515] {logging_mixin.py:109} WARNING - /opt/anaconda3/lib/python3.9/site-packages/airflow/utils/context.py:152 AirflowContextDeprecationWarning: Accessing 'prev_execution_date' from the template is deprecated and will be removed in a future version.
[2022-08-28 15:25:22,516] {logging_mixin.py:109} WARNING - /opt/anaconda3/lib/python3.9/site-packages/airflow/utils/context.py:152 AirflowContextDeprecationWarning: Accessing 'prev_execution_date_success' from the template is deprecated and will be removed in a future version. Please use 'prev_data_interval_start_success' instead.
[2022-08-28 15:25:22,516] {logging_mixin.py:109} WARNING - /opt/anaconda3/lib/python3.9/site-packages/airflow/utils/context.py:152 AirflowContextDeprecationWarning: Accessing 'tomorrow_ds' from the template is deprecated and will be removed in a future version.
[2022-08-28 15:25:22,517] {logging_mixin.py:109} WARNING - /opt/anaconda3/lib/python3.9/site-packages/airflow/utils/context.py:152 AirflowContextDeprecationWarning: Accessing 'tomorrow_ds_nodash' from the template is deprecated and will be removed in a future version.
[2022-08-28 15:25:22,517] {logging_mixin.py:109} WARNING - /opt/anaconda3/lib/python3.9/site-packages/airflow/utils/context.py:152 AirflowContextDeprecationWarning: Accessing 'yesterday_ds' from the template is deprecated and will be removed in a future version.
[2022-08-28 15:25:22,518] {logging_mixin.py:109} WARNING - /opt/anaconda3/lib/python3.9/site-packages/airflow/utils/context.py:152 AirflowContextDeprecationWarning: Accessing 'yesterday_ds_nodash' from the template is deprecated and will be removed in a future version.
[2022-08-28 15:25:22,524] {logging_mixin.py:109} WARNING - /opt/anaconda3/lib/python3.9/site-packages/airflow/utils/email.py:102 PendingDeprecationWarning: Fetching SMTP credentials from configuration variables will be deprecated in a future release. Please set credentials using a connection instead.
[2022-08-28 15:25:22,524] {configuration.py:381} WARNING - section/key [smtp/smtp_user] not found in config
[2022-08-28 15:25:22,524] {email.py:208} INFO - Email alerting: attempt 1
[2022-08-28 15:25:22,527] {configuration.py:381} WARNING - section/key [smtp/smtp_user] not found in config
[2022-08-28 15:25:22,527] {email.py:208} INFO - Email alerting: attempt 1
[2022-08-28 15:25:22,528] {taskinstance.py:1751} ERROR - Failed to send email to: jonathan.dejesus.azor@gmail.com
Traceback (most recent call last):
  File "/opt/anaconda3/lib/python3.9/site-packages/airflow/models/taskinstance.py", line 1329, in _run_raw_task
    self._execute_task_with_callbacks(context)
  File "/opt/anaconda3/lib/python3.9/site-packages/airflow/models/taskinstance.py", line 1455, in _execute_task_with_callbacks
    result = self._execute_task(context, self.task)
  File "/opt/anaconda3/lib/python3.9/site-packages/airflow/models/taskinstance.py", line 1511, in _execute_task
    result = execute_callable(context=context)
  File "/opt/anaconda3/lib/python3.9/site-packages/airflow/operators/python.py", line 174, in execute
    return_value = self.execute_callable()
  File "/opt/anaconda3/lib/python3.9/site-packages/airflow/operators/python.py", line 185, in execute_callable
    return self.python_callable(*self.op_args, **self.op_kwargs)
TypeError: crime_stats_transformation() missing 1 required positional argument: 'filter_df'

During handling of the above exception, another exception occurred:

Traceback (most recent call last):
  File "/opt/anaconda3/lib/python3.9/site-packages/airflow/models/taskinstance.py", line 2093, in email_alert
    send_email(self.task.email, subject, html_content)
  File "/opt/anaconda3/lib/python3.9/site-packages/airflow/utils/email.py", line 55, in send_email
    return backend(
  File "/opt/anaconda3/lib/python3.9/site-packages/airflow/utils/email.py", line 102, in send_email_smtp
    send_mime_email(e_from=smtp_mail_from, e_to=recipients, mime_msg=msg, conn_id=conn_id, dryrun=dryrun)
  File "/opt/anaconda3/lib/python3.9/site-packages/airflow/utils/email.py", line 210, in send_mime_email
    conn = _get_smtp_connection(smtp_host, smtp_port, smtp_timeout, smtp_ssl)
  File "/opt/anaconda3/lib/python3.9/site-packages/airflow/utils/email.py", line 244, in _get_smtp_connection
    else smtplib.SMTP(host=host, port=port, timeout=timeout)
  File "/opt/anaconda3/lib/python3.9/smtplib.py", line 255, in __init__
    (code, msg) = self.connect(host, port)
  File "/opt/anaconda3/lib/python3.9/smtplib.py", line 341, in connect
    self.sock = self._get_socket(host, port, self.timeout)
  File "/opt/anaconda3/lib/python3.9/smtplib.py", line 312, in _get_socket
    return socket.create_connection((host, port), timeout,
  File "/opt/anaconda3/lib/python3.9/socket.py", line 844, in create_connection
    raise err
  File "/opt/anaconda3/lib/python3.9/socket.py", line 832, in create_connection
    sock.connect(sa)
ConnectionRefusedError: [Errno 61] Connection refused

During handling of the above exception, another exception occurred:

Traceback (most recent call last):
  File "/opt/anaconda3/lib/python3.9/site-packages/airflow/models/taskinstance.py", line 1749, in handle_failure
    self.email_alert(error)
  File "/opt/anaconda3/lib/python3.9/site-packages/airflow/models/taskinstance.py", line 2095, in email_alert
    send_email(self.task.email, subject, html_content_err)
  File "/opt/anaconda3/lib/python3.9/site-packages/airflow/utils/email.py", line 55, in send_email
    return backend(
  File "/opt/anaconda3/lib/python3.9/site-packages/airflow/utils/email.py", line 102, in send_email_smtp
    send_mime_email(e_from=smtp_mail_from, e_to=recipients, mime_msg=msg, conn_id=conn_id, dryrun=dryrun)
  File "/opt/anaconda3/lib/python3.9/site-packages/airflow/utils/email.py", line 210, in send_mime_email
    conn = _get_smtp_connection(smtp_host, smtp_port, smtp_timeout, smtp_ssl)
  File "/opt/anaconda3/lib/python3.9/site-packages/airflow/utils/email.py", line 244, in _get_smtp_connection
    else smtplib.SMTP(host=host, port=port, timeout=timeout)
  File "/opt/anaconda3/lib/python3.9/smtplib.py", line 255, in __init__
    (code, msg) = self.connect(host, port)
  File "/opt/anaconda3/lib/python3.9/smtplib.py", line 341, in connect
    self.sock = self._get_socket(host, port, self.timeout)
  File "/opt/anaconda3/lib/python3.9/smtplib.py", line 312, in _get_socket
    return socket.create_connection((host, port), timeout,
  File "/opt/anaconda3/lib/python3.9/socket.py", line 844, in create_connection
    raise err
  File "/opt/anaconda3/lib/python3.9/socket.py", line 832, in create_connection
    sock.connect(sa)
ConnectionRefusedError: [Errno 61] Connection refused
[2022-08-28 15:25:22,533] {standard_task_runner.py:89} ERROR - Failed to execute job 359 for task Transform
Traceback (most recent call last):
  File "/opt/anaconda3/lib/python3.9/site-packages/airflow/task/task_runner/standard_task_runner.py", line 85, in _start_by_fork
    args.func(args, dag=self.dag)
  File "/opt/anaconda3/lib/python3.9/site-packages/airflow/cli/cli_parser.py", line 48, in command
    return func(*args, **kwargs)
  File "/opt/anaconda3/lib/python3.9/site-packages/airflow/utils/cli.py", line 92, in wrapper
    return f(*args, **kwargs)
  File "/opt/anaconda3/lib/python3.9/site-packages/airflow/cli/commands/task_command.py", line 298, in task_run
    _run_task_by_selected_method(args, dag, ti)
  File "/opt/anaconda3/lib/python3.9/site-packages/airflow/cli/commands/task_command.py", line 107, in _run_task_by_selected_method
    _run_raw_task(args, ti)
  File "/opt/anaconda3/lib/python3.9/site-packages/airflow/cli/commands/task_command.py", line 180, in _run_raw_task
    ti._run_raw_task(
  File "/opt/anaconda3/lib/python3.9/site-packages/airflow/utils/session.py", line 70, in wrapper
    return func(*args, session=session, **kwargs)
  File "/opt/anaconda3/lib/python3.9/site-packages/airflow/models/taskinstance.py", line 1329, in _run_raw_task
    self._execute_task_with_callbacks(context)
  File "/opt/anaconda3/lib/python3.9/site-packages/airflow/models/taskinstance.py", line 1455, in _execute_task_with_callbacks
    result = self._execute_task(context, self.task)
  File "/opt/anaconda3/lib/python3.9/site-packages/airflow/models/taskinstance.py", line 1511, in _execute_task
    result = execute_callable(context=context)
  File "/opt/anaconda3/lib/python3.9/site-packages/airflow/operators/python.py", line 174, in execute
    return_value = self.execute_callable()
  File "/opt/anaconda3/lib/python3.9/site-packages/airflow/operators/python.py", line 185, in execute_callable
    return self.python_callable(*self.op_args, **self.op_kwargs)
TypeError: crime_stats_transformation() missing 1 required positional argument: 'filter_df'
[2022-08-28 15:25:22,561] {local_task_job.py:154} INFO - Task exited with return code 1
[2022-08-28 15:25:22,572] {local_task_job.py:264} INFO - 0 downstream tasks scheduled from follow-on schedule check
[2022-08-28 15:48:53,426] {taskinstance.py:1032} INFO - Dependencies all met for <TaskInstance: ETL_Examples.Transform scheduled__2022-08-28T01:20:00+00:00 [queued]>
[2022-08-28 15:48:53,429] {taskinstance.py:1032} INFO - Dependencies all met for <TaskInstance: ETL_Examples.Transform scheduled__2022-08-28T01:20:00+00:00 [queued]>
[2022-08-28 15:48:53,429] {taskinstance.py:1238} INFO - 
--------------------------------------------------------------------------------
[2022-08-28 15:48:53,429] {taskinstance.py:1239} INFO - Starting attempt 1 of 2
[2022-08-28 15:48:53,429] {taskinstance.py:1240} INFO - 
--------------------------------------------------------------------------------
[2022-08-28 15:48:53,433] {taskinstance.py:1259} INFO - Executing <Task(PythonOperator): Transform> on 2022-08-28 01:20:00+00:00
[2022-08-28 15:48:53,441] {standard_task_runner.py:52} INFO - Started process 31078 to run task
[2022-08-28 15:48:53,445] {standard_task_runner.py:76} INFO - Running: ['airflow', 'tasks', 'run', 'ETL_Examples', 'Transform', 'scheduled__2022-08-28T01:20:00+00:00', '--job-id', '433', '--raw', '--subdir', 'DAGS_FOLDER/Pushtobigquery2.py', '--cfg-path', '/var/folders/35/pzst1sv14yld_nkt23lk_vmr0000gn/T/tmpm0kjkjfk', '--error-file', '/var/folders/35/pzst1sv14yld_nkt23lk_vmr0000gn/T/tmp15jiutgl']
[2022-08-28 15:48:53,446] {standard_task_runner.py:77} INFO - Job 433: Subtask Transform
[2022-08-28 15:48:53,468] {logging_mixin.py:109} INFO - Running <TaskInstance: ETL_Examples.Transform scheduled__2022-08-28T01:20:00+00:00 [running]> on host 1.0.0.127.in-addr.arpa
[2022-08-28 15:48:53,489] {taskinstance.py:1424} INFO - Exporting the following env vars:
AIRFLOW_CTX_DAG_EMAIL=jonathan.dejesus.azor@gmail.com
AIRFLOW_CTX_DAG_OWNER=admin
AIRFLOW_CTX_DAG_ID=ETL_Examples
AIRFLOW_CTX_TASK_ID=Transform
AIRFLOW_CTX_EXECUTION_DATE=2022-08-28T01:20:00+00:00
AIRFLOW_CTX_DAG_RUN_ID=scheduled__2022-08-28T01:20:00+00:00
[2022-08-28 15:48:53,493] {logging_mixin.py:109} WARNING - /opt/anaconda3/lib/python3.9/site-packages/airflow/utils/context.py:152 AirflowContextDeprecationWarning: Accessing 'execution_date' from the template is deprecated and will be removed in a future version. Please use 'data_interval_start' or 'logical_date' instead.
[2022-08-28 15:48:53,494] {logging_mixin.py:109} WARNING - /opt/anaconda3/lib/python3.9/site-packages/airflow/utils/context.py:152 AirflowContextDeprecationWarning: Accessing 'next_ds' from the template is deprecated and will be removed in a future version. Please use '{{ data_interval_end | ds }}' instead.
[2022-08-28 15:48:53,494] {logging_mixin.py:109} WARNING - /opt/anaconda3/lib/python3.9/site-packages/airflow/utils/context.py:152 AirflowContextDeprecationWarning: Accessing 'next_ds_nodash' from the template is deprecated and will be removed in a future version. Please use '{{ data_interval_end | ds_nodash }}' instead.
[2022-08-28 15:48:53,495] {logging_mixin.py:109} WARNING - /opt/anaconda3/lib/python3.9/site-packages/airflow/utils/context.py:152 AirflowContextDeprecationWarning: Accessing 'next_execution_date' from the template is deprecated and will be removed in a future version. Please use 'data_interval_end' instead.
[2022-08-28 15:48:53,495] {logging_mixin.py:109} WARNING - /opt/anaconda3/lib/python3.9/site-packages/airflow/utils/context.py:152 AirflowContextDeprecationWarning: Accessing 'prev_ds' from the template is deprecated and will be removed in a future version.
[2022-08-28 15:48:53,496] {logging_mixin.py:109} WARNING - /opt/anaconda3/lib/python3.9/site-packages/airflow/utils/context.py:152 AirflowContextDeprecationWarning: Accessing 'prev_ds_nodash' from the template is deprecated and will be removed in a future version.
[2022-08-28 15:48:53,496] {logging_mixin.py:109} WARNING - /opt/anaconda3/lib/python3.9/site-packages/airflow/utils/context.py:152 AirflowContextDeprecationWarning: Accessing 'prev_execution_date' from the template is deprecated and will be removed in a future version.
[2022-08-28 15:48:53,497] {logging_mixin.py:109} WARNING - /opt/anaconda3/lib/python3.9/site-packages/airflow/utils/context.py:152 AirflowContextDeprecationWarning: Accessing 'prev_execution_date_success' from the template is deprecated and will be removed in a future version. Please use 'prev_data_interval_start_success' instead.
[2022-08-28 15:48:53,497] {logging_mixin.py:109} WARNING - /opt/anaconda3/lib/python3.9/site-packages/airflow/utils/context.py:152 AirflowContextDeprecationWarning: Accessing 'tomorrow_ds' from the template is deprecated and will be removed in a future version.
[2022-08-28 15:48:53,498] {logging_mixin.py:109} WARNING - /opt/anaconda3/lib/python3.9/site-packages/airflow/utils/context.py:152 AirflowContextDeprecationWarning: Accessing 'tomorrow_ds_nodash' from the template is deprecated and will be removed in a future version.
[2022-08-28 15:48:53,498] {logging_mixin.py:109} WARNING - /opt/anaconda3/lib/python3.9/site-packages/airflow/utils/context.py:152 AirflowContextDeprecationWarning: Accessing 'yesterday_ds' from the template is deprecated and will be removed in a future version.
[2022-08-28 15:48:53,499] {logging_mixin.py:109} WARNING - /opt/anaconda3/lib/python3.9/site-packages/airflow/utils/context.py:152 AirflowContextDeprecationWarning: Accessing 'yesterday_ds_nodash' from the template is deprecated and will be removed in a future version.
[2022-08-28 15:48:53,499] {taskinstance.py:1700} ERROR - Task failed with exception
Traceback (most recent call last):
  File "/opt/anaconda3/lib/python3.9/site-packages/airflow/models/taskinstance.py", line 1329, in _run_raw_task
    self._execute_task_with_callbacks(context)
  File "/opt/anaconda3/lib/python3.9/site-packages/airflow/models/taskinstance.py", line 1455, in _execute_task_with_callbacks
    result = self._execute_task(context, self.task)
  File "/opt/anaconda3/lib/python3.9/site-packages/airflow/models/taskinstance.py", line 1511, in _execute_task
    result = execute_callable(context=context)
  File "/opt/anaconda3/lib/python3.9/site-packages/airflow/operators/python.py", line 174, in execute
    return_value = self.execute_callable()
  File "/opt/anaconda3/lib/python3.9/site-packages/airflow/operators/python.py", line 185, in execute_callable
    return self.python_callable(*self.op_args, **self.op_kwargs)
  File "/Users/theonewiththelion/airflow/dags/Pushtobigquery2.py", line 73, in crime_stats_transformation
    filter_df.rename(columns = {'occ_date' : 'occurred_date',
NameError: name 'filter_df' is not defined
[2022-08-28 15:48:53,503] {taskinstance.py:1267} INFO - Marking task as UP_FOR_RETRY. dag_id=ETL_Examples, task_id=Transform, execution_date=20220828T012000, start_date=20220828T204853, end_date=20220828T204853
[2022-08-28 15:48:53,507] {logging_mixin.py:109} WARNING - /opt/anaconda3/lib/python3.9/site-packages/airflow/utils/context.py:152 AirflowContextDeprecationWarning: Accessing 'execution_date' from the template is deprecated and will be removed in a future version. Please use 'data_interval_start' or 'logical_date' instead.
[2022-08-28 15:48:53,508] {logging_mixin.py:109} WARNING - /opt/anaconda3/lib/python3.9/site-packages/airflow/utils/context.py:152 AirflowContextDeprecationWarning: Accessing 'next_ds' from the template is deprecated and will be removed in a future version. Please use '{{ data_interval_end | ds }}' instead.
[2022-08-28 15:48:53,508] {logging_mixin.py:109} WARNING - /opt/anaconda3/lib/python3.9/site-packages/airflow/utils/context.py:152 AirflowContextDeprecationWarning: Accessing 'next_ds_nodash' from the template is deprecated and will be removed in a future version. Please use '{{ data_interval_end | ds_nodash }}' instead.
[2022-08-28 15:48:53,509] {logging_mixin.py:109} WARNING - /opt/anaconda3/lib/python3.9/site-packages/airflow/utils/context.py:152 AirflowContextDeprecationWarning: Accessing 'next_execution_date' from the template is deprecated and will be removed in a future version. Please use 'data_interval_end' instead.
[2022-08-28 15:48:53,509] {logging_mixin.py:109} WARNING - /opt/anaconda3/lib/python3.9/site-packages/airflow/utils/context.py:152 AirflowContextDeprecationWarning: Accessing 'prev_ds' from the template is deprecated and will be removed in a future version.
[2022-08-28 15:48:53,510] {logging_mixin.py:109} WARNING - /opt/anaconda3/lib/python3.9/site-packages/airflow/utils/context.py:152 AirflowContextDeprecationWarning: Accessing 'prev_ds_nodash' from the template is deprecated and will be removed in a future version.
[2022-08-28 15:48:53,511] {logging_mixin.py:109} WARNING - /opt/anaconda3/lib/python3.9/site-packages/airflow/utils/context.py:152 AirflowContextDeprecationWarning: Accessing 'prev_execution_date' from the template is deprecated and will be removed in a future version.
[2022-08-28 15:48:53,511] {logging_mixin.py:109} WARNING - /opt/anaconda3/lib/python3.9/site-packages/airflow/utils/context.py:152 AirflowContextDeprecationWarning: Accessing 'prev_execution_date_success' from the template is deprecated and will be removed in a future version. Please use 'prev_data_interval_start_success' instead.
[2022-08-28 15:48:53,512] {logging_mixin.py:109} WARNING - /opt/anaconda3/lib/python3.9/site-packages/airflow/utils/context.py:152 AirflowContextDeprecationWarning: Accessing 'tomorrow_ds' from the template is deprecated and will be removed in a future version.
[2022-08-28 15:48:53,512] {logging_mixin.py:109} WARNING - /opt/anaconda3/lib/python3.9/site-packages/airflow/utils/context.py:152 AirflowContextDeprecationWarning: Accessing 'tomorrow_ds_nodash' from the template is deprecated and will be removed in a future version.
[2022-08-28 15:48:53,513] {logging_mixin.py:109} WARNING - /opt/anaconda3/lib/python3.9/site-packages/airflow/utils/context.py:152 AirflowContextDeprecationWarning: Accessing 'yesterday_ds' from the template is deprecated and will be removed in a future version.
[2022-08-28 15:48:53,513] {logging_mixin.py:109} WARNING - /opt/anaconda3/lib/python3.9/site-packages/airflow/utils/context.py:152 AirflowContextDeprecationWarning: Accessing 'yesterday_ds_nodash' from the template is deprecated and will be removed in a future version.
[2022-08-28 15:48:53,519] {logging_mixin.py:109} WARNING - /opt/anaconda3/lib/python3.9/site-packages/airflow/utils/email.py:102 PendingDeprecationWarning: Fetching SMTP credentials from configuration variables will be deprecated in a future release. Please set credentials using a connection instead.
[2022-08-28 15:48:53,519] {configuration.py:381} WARNING - section/key [smtp/smtp_user] not found in config
[2022-08-28 15:48:53,519] {email.py:208} INFO - Email alerting: attempt 1
[2022-08-28 15:48:53,524] {configuration.py:381} WARNING - section/key [smtp/smtp_user] not found in config
[2022-08-28 15:48:53,524] {email.py:208} INFO - Email alerting: attempt 1
[2022-08-28 15:48:53,525] {taskinstance.py:1751} ERROR - Failed to send email to: jonathan.dejesus.azor@gmail.com
Traceback (most recent call last):
  File "/opt/anaconda3/lib/python3.9/site-packages/airflow/models/taskinstance.py", line 1329, in _run_raw_task
    self._execute_task_with_callbacks(context)
  File "/opt/anaconda3/lib/python3.9/site-packages/airflow/models/taskinstance.py", line 1455, in _execute_task_with_callbacks
    result = self._execute_task(context, self.task)
  File "/opt/anaconda3/lib/python3.9/site-packages/airflow/models/taskinstance.py", line 1511, in _execute_task
    result = execute_callable(context=context)
  File "/opt/anaconda3/lib/python3.9/site-packages/airflow/operators/python.py", line 174, in execute
    return_value = self.execute_callable()
  File "/opt/anaconda3/lib/python3.9/site-packages/airflow/operators/python.py", line 185, in execute_callable
    return self.python_callable(*self.op_args, **self.op_kwargs)
  File "/Users/theonewiththelion/airflow/dags/Pushtobigquery2.py", line 73, in crime_stats_transformation
    filter_df.rename(columns = {'occ_date' : 'occurred_date',
NameError: name 'filter_df' is not defined

During handling of the above exception, another exception occurred:

Traceback (most recent call last):
  File "/opt/anaconda3/lib/python3.9/site-packages/airflow/models/taskinstance.py", line 2093, in email_alert
    send_email(self.task.email, subject, html_content)
  File "/opt/anaconda3/lib/python3.9/site-packages/airflow/utils/email.py", line 55, in send_email
    return backend(
  File "/opt/anaconda3/lib/python3.9/site-packages/airflow/utils/email.py", line 102, in send_email_smtp
    send_mime_email(e_from=smtp_mail_from, e_to=recipients, mime_msg=msg, conn_id=conn_id, dryrun=dryrun)
  File "/opt/anaconda3/lib/python3.9/site-packages/airflow/utils/email.py", line 210, in send_mime_email
    conn = _get_smtp_connection(smtp_host, smtp_port, smtp_timeout, smtp_ssl)
  File "/opt/anaconda3/lib/python3.9/site-packages/airflow/utils/email.py", line 244, in _get_smtp_connection
    else smtplib.SMTP(host=host, port=port, timeout=timeout)
  File "/opt/anaconda3/lib/python3.9/smtplib.py", line 255, in __init__
    (code, msg) = self.connect(host, port)
  File "/opt/anaconda3/lib/python3.9/smtplib.py", line 341, in connect
    self.sock = self._get_socket(host, port, self.timeout)
  File "/opt/anaconda3/lib/python3.9/smtplib.py", line 312, in _get_socket
    return socket.create_connection((host, port), timeout,
  File "/opt/anaconda3/lib/python3.9/socket.py", line 844, in create_connection
    raise err
  File "/opt/anaconda3/lib/python3.9/socket.py", line 832, in create_connection
    sock.connect(sa)
ConnectionRefusedError: [Errno 61] Connection refused

During handling of the above exception, another exception occurred:

Traceback (most recent call last):
  File "/opt/anaconda3/lib/python3.9/site-packages/airflow/models/taskinstance.py", line 1749, in handle_failure
    self.email_alert(error)
  File "/opt/anaconda3/lib/python3.9/site-packages/airflow/models/taskinstance.py", line 2095, in email_alert
    send_email(self.task.email, subject, html_content_err)
  File "/opt/anaconda3/lib/python3.9/site-packages/airflow/utils/email.py", line 55, in send_email
    return backend(
  File "/opt/anaconda3/lib/python3.9/site-packages/airflow/utils/email.py", line 102, in send_email_smtp
    send_mime_email(e_from=smtp_mail_from, e_to=recipients, mime_msg=msg, conn_id=conn_id, dryrun=dryrun)
  File "/opt/anaconda3/lib/python3.9/site-packages/airflow/utils/email.py", line 210, in send_mime_email
    conn = _get_smtp_connection(smtp_host, smtp_port, smtp_timeout, smtp_ssl)
  File "/opt/anaconda3/lib/python3.9/site-packages/airflow/utils/email.py", line 244, in _get_smtp_connection
    else smtplib.SMTP(host=host, port=port, timeout=timeout)
  File "/opt/anaconda3/lib/python3.9/smtplib.py", line 255, in __init__
    (code, msg) = self.connect(host, port)
  File "/opt/anaconda3/lib/python3.9/smtplib.py", line 341, in connect
    self.sock = self._get_socket(host, port, self.timeout)
  File "/opt/anaconda3/lib/python3.9/smtplib.py", line 312, in _get_socket
    return socket.create_connection((host, port), timeout,
  File "/opt/anaconda3/lib/python3.9/socket.py", line 844, in create_connection
    raise err
  File "/opt/anaconda3/lib/python3.9/socket.py", line 832, in create_connection
    sock.connect(sa)
ConnectionRefusedError: [Errno 61] Connection refused
[2022-08-28 15:48:53,529] {standard_task_runner.py:89} ERROR - Failed to execute job 433 for task Transform
Traceback (most recent call last):
  File "/opt/anaconda3/lib/python3.9/site-packages/airflow/task/task_runner/standard_task_runner.py", line 85, in _start_by_fork
    args.func(args, dag=self.dag)
  File "/opt/anaconda3/lib/python3.9/site-packages/airflow/cli/cli_parser.py", line 48, in command
    return func(*args, **kwargs)
  File "/opt/anaconda3/lib/python3.9/site-packages/airflow/utils/cli.py", line 92, in wrapper
    return f(*args, **kwargs)
  File "/opt/anaconda3/lib/python3.9/site-packages/airflow/cli/commands/task_command.py", line 298, in task_run
    _run_task_by_selected_method(args, dag, ti)
  File "/opt/anaconda3/lib/python3.9/site-packages/airflow/cli/commands/task_command.py", line 107, in _run_task_by_selected_method
    _run_raw_task(args, ti)
  File "/opt/anaconda3/lib/python3.9/site-packages/airflow/cli/commands/task_command.py", line 180, in _run_raw_task
    ti._run_raw_task(
  File "/opt/anaconda3/lib/python3.9/site-packages/airflow/utils/session.py", line 70, in wrapper
    return func(*args, session=session, **kwargs)
  File "/opt/anaconda3/lib/python3.9/site-packages/airflow/models/taskinstance.py", line 1329, in _run_raw_task
    self._execute_task_with_callbacks(context)
  File "/opt/anaconda3/lib/python3.9/site-packages/airflow/models/taskinstance.py", line 1455, in _execute_task_with_callbacks
    result = self._execute_task(context, self.task)
  File "/opt/anaconda3/lib/python3.9/site-packages/airflow/models/taskinstance.py", line 1511, in _execute_task
    result = execute_callable(context=context)
  File "/opt/anaconda3/lib/python3.9/site-packages/airflow/operators/python.py", line 174, in execute
    return_value = self.execute_callable()
  File "/opt/anaconda3/lib/python3.9/site-packages/airflow/operators/python.py", line 185, in execute_callable
    return self.python_callable(*self.op_args, **self.op_kwargs)
  File "/Users/theonewiththelion/airflow/dags/Pushtobigquery2.py", line 73, in crime_stats_transformation
    filter_df.rename(columns = {'occ_date' : 'occurred_date',
NameError: name 'filter_df' is not defined
[2022-08-28 15:48:53,552] {local_task_job.py:154} INFO - Task exited with return code 1
[2022-08-28 15:48:53,564] {local_task_job.py:264} INFO - 0 downstream tasks scheduled from follow-on schedule check
[2022-08-28 15:50:34,115] {taskinstance.py:1032} INFO - Dependencies all met for <TaskInstance: ETL_Examples.Transform scheduled__2022-08-28T01:20:00+00:00 [queued]>
[2022-08-28 15:50:34,118] {taskinstance.py:1032} INFO - Dependencies all met for <TaskInstance: ETL_Examples.Transform scheduled__2022-08-28T01:20:00+00:00 [queued]>
[2022-08-28 15:50:34,118] {taskinstance.py:1238} INFO - 
--------------------------------------------------------------------------------
[2022-08-28 15:50:34,118] {taskinstance.py:1239} INFO - Starting attempt 1 of 2
[2022-08-28 15:50:34,118] {taskinstance.py:1240} INFO - 
--------------------------------------------------------------------------------
[2022-08-28 15:50:34,123] {taskinstance.py:1259} INFO - Executing <Task(PythonOperator): Transform> on 2022-08-28 01:20:00+00:00
[2022-08-28 15:50:34,129] {standard_task_runner.py:52} INFO - Started process 31168 to run task
[2022-08-28 15:50:34,133] {standard_task_runner.py:76} INFO - Running: ['airflow', 'tasks', 'run', 'ETL_Examples', 'Transform', 'scheduled__2022-08-28T01:20:00+00:00', '--job-id', '457', '--raw', '--subdir', 'DAGS_FOLDER/Pushtobigquery2.py', '--cfg-path', '/var/folders/35/pzst1sv14yld_nkt23lk_vmr0000gn/T/tmp9h5opn5u', '--error-file', '/var/folders/35/pzst1sv14yld_nkt23lk_vmr0000gn/T/tmp7q6k7pfg']
[2022-08-28 15:50:34,134] {standard_task_runner.py:77} INFO - Job 457: Subtask Transform
[2022-08-28 15:50:34,156] {logging_mixin.py:109} INFO - Running <TaskInstance: ETL_Examples.Transform scheduled__2022-08-28T01:20:00+00:00 [running]> on host 1.0.0.127.in-addr.arpa
[2022-08-28 15:50:34,176] {taskinstance.py:1424} INFO - Exporting the following env vars:
AIRFLOW_CTX_DAG_EMAIL=jonathan.dejesus.azor@gmail.com
AIRFLOW_CTX_DAG_OWNER=admin
AIRFLOW_CTX_DAG_ID=ETL_Examples
AIRFLOW_CTX_TASK_ID=Transform
AIRFLOW_CTX_EXECUTION_DATE=2022-08-28T01:20:00+00:00
AIRFLOW_CTX_DAG_RUN_ID=scheduled__2022-08-28T01:20:00+00:00
[2022-08-28 15:50:34,176] {taskinstance.py:1700} ERROR - Task failed with exception
Traceback (most recent call last):
  File "/opt/anaconda3/lib/python3.9/site-packages/airflow/models/taskinstance.py", line 1329, in _run_raw_task
    self._execute_task_with_callbacks(context)
  File "/opt/anaconda3/lib/python3.9/site-packages/airflow/models/taskinstance.py", line 1455, in _execute_task_with_callbacks
    result = self._execute_task(context, self.task)
  File "/opt/anaconda3/lib/python3.9/site-packages/airflow/models/taskinstance.py", line 1511, in _execute_task
    result = execute_callable(context=context)
  File "/opt/anaconda3/lib/python3.9/site-packages/airflow/operators/python.py", line 174, in execute
    return_value = self.execute_callable()
  File "/opt/anaconda3/lib/python3.9/site-packages/airflow/operators/python.py", line 185, in execute_callable
    return self.python_callable(*self.op_args, **self.op_kwargs)
TypeError: crime_stats_transformation() missing 1 required positional argument: 'filter_df'
[2022-08-28 15:50:34,181] {taskinstance.py:1267} INFO - Marking task as UP_FOR_RETRY. dag_id=ETL_Examples, task_id=Transform, execution_date=20220828T012000, start_date=20220828T205034, end_date=20220828T205034
[2022-08-28 15:50:34,186] {logging_mixin.py:109} WARNING - /opt/anaconda3/lib/python3.9/site-packages/airflow/utils/context.py:152 AirflowContextDeprecationWarning: Accessing 'execution_date' from the template is deprecated and will be removed in a future version. Please use 'data_interval_start' or 'logical_date' instead.
[2022-08-28 15:50:34,187] {logging_mixin.py:109} WARNING - /opt/anaconda3/lib/python3.9/site-packages/airflow/utils/context.py:152 AirflowContextDeprecationWarning: Accessing 'next_ds' from the template is deprecated and will be removed in a future version. Please use '{{ data_interval_end | ds }}' instead.
[2022-08-28 15:50:34,188] {logging_mixin.py:109} WARNING - /opt/anaconda3/lib/python3.9/site-packages/airflow/utils/context.py:152 AirflowContextDeprecationWarning: Accessing 'next_ds_nodash' from the template is deprecated and will be removed in a future version. Please use '{{ data_interval_end | ds_nodash }}' instead.
[2022-08-28 15:50:34,188] {logging_mixin.py:109} WARNING - /opt/anaconda3/lib/python3.9/site-packages/airflow/utils/context.py:152 AirflowContextDeprecationWarning: Accessing 'next_execution_date' from the template is deprecated and will be removed in a future version. Please use 'data_interval_end' instead.
[2022-08-28 15:50:34,188] {logging_mixin.py:109} WARNING - /opt/anaconda3/lib/python3.9/site-packages/airflow/utils/context.py:152 AirflowContextDeprecationWarning: Accessing 'prev_ds' from the template is deprecated and will be removed in a future version.
[2022-08-28 15:50:34,189] {logging_mixin.py:109} WARNING - /opt/anaconda3/lib/python3.9/site-packages/airflow/utils/context.py:152 AirflowContextDeprecationWarning: Accessing 'prev_ds_nodash' from the template is deprecated and will be removed in a future version.
[2022-08-28 15:50:34,189] {logging_mixin.py:109} WARNING - /opt/anaconda3/lib/python3.9/site-packages/airflow/utils/context.py:152 AirflowContextDeprecationWarning: Accessing 'prev_execution_date' from the template is deprecated and will be removed in a future version.
[2022-08-28 15:50:34,190] {logging_mixin.py:109} WARNING - /opt/anaconda3/lib/python3.9/site-packages/airflow/utils/context.py:152 AirflowContextDeprecationWarning: Accessing 'prev_execution_date_success' from the template is deprecated and will be removed in a future version. Please use 'prev_data_interval_start_success' instead.
[2022-08-28 15:50:34,190] {logging_mixin.py:109} WARNING - /opt/anaconda3/lib/python3.9/site-packages/airflow/utils/context.py:152 AirflowContextDeprecationWarning: Accessing 'tomorrow_ds' from the template is deprecated and will be removed in a future version.
[2022-08-28 15:50:34,191] {logging_mixin.py:109} WARNING - /opt/anaconda3/lib/python3.9/site-packages/airflow/utils/context.py:152 AirflowContextDeprecationWarning: Accessing 'tomorrow_ds_nodash' from the template is deprecated and will be removed in a future version.
[2022-08-28 15:50:34,191] {logging_mixin.py:109} WARNING - /opt/anaconda3/lib/python3.9/site-packages/airflow/utils/context.py:152 AirflowContextDeprecationWarning: Accessing 'yesterday_ds' from the template is deprecated and will be removed in a future version.
[2022-08-28 15:50:34,192] {logging_mixin.py:109} WARNING - /opt/anaconda3/lib/python3.9/site-packages/airflow/utils/context.py:152 AirflowContextDeprecationWarning: Accessing 'yesterday_ds_nodash' from the template is deprecated and will be removed in a future version.
[2022-08-28 15:50:34,197] {logging_mixin.py:109} WARNING - /opt/anaconda3/lib/python3.9/site-packages/airflow/utils/email.py:102 PendingDeprecationWarning: Fetching SMTP credentials from configuration variables will be deprecated in a future release. Please set credentials using a connection instead.
[2022-08-28 15:50:34,197] {configuration.py:381} WARNING - section/key [smtp/smtp_user] not found in config
[2022-08-28 15:50:34,198] {email.py:208} INFO - Email alerting: attempt 1
[2022-08-28 15:50:34,200] {configuration.py:381} WARNING - section/key [smtp/smtp_user] not found in config
[2022-08-28 15:50:34,201] {email.py:208} INFO - Email alerting: attempt 1
[2022-08-28 15:50:34,201] {taskinstance.py:1751} ERROR - Failed to send email to: jonathan.dejesus.azor@gmail.com
Traceback (most recent call last):
  File "/opt/anaconda3/lib/python3.9/site-packages/airflow/models/taskinstance.py", line 1329, in _run_raw_task
    self._execute_task_with_callbacks(context)
  File "/opt/anaconda3/lib/python3.9/site-packages/airflow/models/taskinstance.py", line 1455, in _execute_task_with_callbacks
    result = self._execute_task(context, self.task)
  File "/opt/anaconda3/lib/python3.9/site-packages/airflow/models/taskinstance.py", line 1511, in _execute_task
    result = execute_callable(context=context)
  File "/opt/anaconda3/lib/python3.9/site-packages/airflow/operators/python.py", line 174, in execute
    return_value = self.execute_callable()
  File "/opt/anaconda3/lib/python3.9/site-packages/airflow/operators/python.py", line 185, in execute_callable
    return self.python_callable(*self.op_args, **self.op_kwargs)
TypeError: crime_stats_transformation() missing 1 required positional argument: 'filter_df'

During handling of the above exception, another exception occurred:

Traceback (most recent call last):
  File "/opt/anaconda3/lib/python3.9/site-packages/airflow/models/taskinstance.py", line 2093, in email_alert
    send_email(self.task.email, subject, html_content)
  File "/opt/anaconda3/lib/python3.9/site-packages/airflow/utils/email.py", line 55, in send_email
    return backend(
  File "/opt/anaconda3/lib/python3.9/site-packages/airflow/utils/email.py", line 102, in send_email_smtp
    send_mime_email(e_from=smtp_mail_from, e_to=recipients, mime_msg=msg, conn_id=conn_id, dryrun=dryrun)
  File "/opt/anaconda3/lib/python3.9/site-packages/airflow/utils/email.py", line 210, in send_mime_email
    conn = _get_smtp_connection(smtp_host, smtp_port, smtp_timeout, smtp_ssl)
  File "/opt/anaconda3/lib/python3.9/site-packages/airflow/utils/email.py", line 244, in _get_smtp_connection
    else smtplib.SMTP(host=host, port=port, timeout=timeout)
  File "/opt/anaconda3/lib/python3.9/smtplib.py", line 255, in __init__
    (code, msg) = self.connect(host, port)
  File "/opt/anaconda3/lib/python3.9/smtplib.py", line 341, in connect
    self.sock = self._get_socket(host, port, self.timeout)
  File "/opt/anaconda3/lib/python3.9/smtplib.py", line 312, in _get_socket
    return socket.create_connection((host, port), timeout,
  File "/opt/anaconda3/lib/python3.9/socket.py", line 844, in create_connection
    raise err
  File "/opt/anaconda3/lib/python3.9/socket.py", line 832, in create_connection
    sock.connect(sa)
ConnectionRefusedError: [Errno 61] Connection refused

During handling of the above exception, another exception occurred:

Traceback (most recent call last):
  File "/opt/anaconda3/lib/python3.9/site-packages/airflow/models/taskinstance.py", line 1749, in handle_failure
    self.email_alert(error)
  File "/opt/anaconda3/lib/python3.9/site-packages/airflow/models/taskinstance.py", line 2095, in email_alert
    send_email(self.task.email, subject, html_content_err)
  File "/opt/anaconda3/lib/python3.9/site-packages/airflow/utils/email.py", line 55, in send_email
    return backend(
  File "/opt/anaconda3/lib/python3.9/site-packages/airflow/utils/email.py", line 102, in send_email_smtp
    send_mime_email(e_from=smtp_mail_from, e_to=recipients, mime_msg=msg, conn_id=conn_id, dryrun=dryrun)
  File "/opt/anaconda3/lib/python3.9/site-packages/airflow/utils/email.py", line 210, in send_mime_email
    conn = _get_smtp_connection(smtp_host, smtp_port, smtp_timeout, smtp_ssl)
  File "/opt/anaconda3/lib/python3.9/site-packages/airflow/utils/email.py", line 244, in _get_smtp_connection
    else smtplib.SMTP(host=host, port=port, timeout=timeout)
  File "/opt/anaconda3/lib/python3.9/smtplib.py", line 255, in __init__
    (code, msg) = self.connect(host, port)
  File "/opt/anaconda3/lib/python3.9/smtplib.py", line 341, in connect
    self.sock = self._get_socket(host, port, self.timeout)
  File "/opt/anaconda3/lib/python3.9/smtplib.py", line 312, in _get_socket
    return socket.create_connection((host, port), timeout,
  File "/opt/anaconda3/lib/python3.9/socket.py", line 844, in create_connection
    raise err
  File "/opt/anaconda3/lib/python3.9/socket.py", line 832, in create_connection
    sock.connect(sa)
ConnectionRefusedError: [Errno 61] Connection refused
[2022-08-28 15:50:34,206] {standard_task_runner.py:89} ERROR - Failed to execute job 457 for task Transform
Traceback (most recent call last):
  File "/opt/anaconda3/lib/python3.9/site-packages/airflow/task/task_runner/standard_task_runner.py", line 85, in _start_by_fork
    args.func(args, dag=self.dag)
  File "/opt/anaconda3/lib/python3.9/site-packages/airflow/cli/cli_parser.py", line 48, in command
    return func(*args, **kwargs)
  File "/opt/anaconda3/lib/python3.9/site-packages/airflow/utils/cli.py", line 92, in wrapper
    return f(*args, **kwargs)
  File "/opt/anaconda3/lib/python3.9/site-packages/airflow/cli/commands/task_command.py", line 298, in task_run
    _run_task_by_selected_method(args, dag, ti)
  File "/opt/anaconda3/lib/python3.9/site-packages/airflow/cli/commands/task_command.py", line 107, in _run_task_by_selected_method
    _run_raw_task(args, ti)
  File "/opt/anaconda3/lib/python3.9/site-packages/airflow/cli/commands/task_command.py", line 180, in _run_raw_task
    ti._run_raw_task(
  File "/opt/anaconda3/lib/python3.9/site-packages/airflow/utils/session.py", line 70, in wrapper
    return func(*args, session=session, **kwargs)
  File "/opt/anaconda3/lib/python3.9/site-packages/airflow/models/taskinstance.py", line 1329, in _run_raw_task
    self._execute_task_with_callbacks(context)
  File "/opt/anaconda3/lib/python3.9/site-packages/airflow/models/taskinstance.py", line 1455, in _execute_task_with_callbacks
    result = self._execute_task(context, self.task)
  File "/opt/anaconda3/lib/python3.9/site-packages/airflow/models/taskinstance.py", line 1511, in _execute_task
    result = execute_callable(context=context)
  File "/opt/anaconda3/lib/python3.9/site-packages/airflow/operators/python.py", line 174, in execute
    return_value = self.execute_callable()
  File "/opt/anaconda3/lib/python3.9/site-packages/airflow/operators/python.py", line 185, in execute_callable
    return self.python_callable(*self.op_args, **self.op_kwargs)
TypeError: crime_stats_transformation() missing 1 required positional argument: 'filter_df'
[2022-08-28 15:50:34,240] {local_task_job.py:154} INFO - Task exited with return code 1
[2022-08-28 15:50:34,251] {local_task_job.py:264} INFO - 0 downstream tasks scheduled from follow-on schedule check
