[2022-08-28 15:19:10,067] {taskinstance.py:1032} INFO - Dependencies all met for <TaskInstance: ETL_Examples.Transform scheduled__2022-08-28T01:40:00+00:00 [queued]>
[2022-08-28 15:19:10,070] {taskinstance.py:1032} INFO - Dependencies all met for <TaskInstance: ETL_Examples.Transform scheduled__2022-08-28T01:40:00+00:00 [queued]>
[2022-08-28 15:19:10,070] {taskinstance.py:1238} INFO - 
--------------------------------------------------------------------------------
[2022-08-28 15:19:10,070] {taskinstance.py:1239} INFO - Starting attempt 1 of 1
[2022-08-28 15:19:10,070] {taskinstance.py:1240} INFO - 
--------------------------------------------------------------------------------
[2022-08-28 15:19:10,074] {taskinstance.py:1259} INFO - Executing <Task(PythonOperator): Transform> on 2022-08-28 01:40:00+00:00
[2022-08-28 15:19:10,080] {standard_task_runner.py:52} INFO - Started process 30149 to run task
[2022-08-28 15:19:10,085] {standard_task_runner.py:76} INFO - Running: ['airflow', 'tasks', 'run', 'ETL_Examples', 'Transform', 'scheduled__2022-08-28T01:40:00+00:00', '--job-id', '306', '--raw', '--subdir', 'DAGS_FOLDER/Pushtobigquery2.py', '--cfg-path', '/var/folders/35/pzst1sv14yld_nkt23lk_vmr0000gn/T/tmpvhydy656', '--error-file', '/var/folders/35/pzst1sv14yld_nkt23lk_vmr0000gn/T/tmp2tx6xh08']
[2022-08-28 15:19:10,086] {standard_task_runner.py:77} INFO - Job 306: Subtask Transform
[2022-08-28 15:19:10,108] {logging_mixin.py:109} INFO - Running <TaskInstance: ETL_Examples.Transform scheduled__2022-08-28T01:40:00+00:00 [running]> on host 1.0.0.127.in-addr.arpa
[2022-08-28 15:19:10,128] {taskinstance.py:1424} INFO - Exporting the following env vars:
AIRFLOW_CTX_DAG_EMAIL=jonathan.dejesus.azor@gmail.com
AIRFLOW_CTX_DAG_OWNER=admin
AIRFLOW_CTX_DAG_ID=ETL_Examples
AIRFLOW_CTX_TASK_ID=Transform
AIRFLOW_CTX_EXECUTION_DATE=2022-08-28T01:40:00+00:00
AIRFLOW_CTX_DAG_RUN_ID=scheduled__2022-08-28T01:40:00+00:00
[2022-08-28 15:19:10,129] {taskinstance.py:1700} ERROR - Task failed with exception
Traceback (most recent call last):
  File "/opt/anaconda3/lib/python3.9/site-packages/airflow/models/taskinstance.py", line 1329, in _run_raw_task
    self._execute_task_with_callbacks(context)
  File "/opt/anaconda3/lib/python3.9/site-packages/airflow/models/taskinstance.py", line 1455, in _execute_task_with_callbacks
    result = self._execute_task(context, self.task)
  File "/opt/anaconda3/lib/python3.9/site-packages/airflow/models/taskinstance.py", line 1511, in _execute_task
    result = execute_callable(context=context)
  File "/opt/anaconda3/lib/python3.9/site-packages/airflow/operators/python.py", line 174, in execute
    return_value = self.execute_callable()
  File "/opt/anaconda3/lib/python3.9/site-packages/airflow/operators/python.py", line 185, in execute_callable
    return self.python_callable(*self.op_args, **self.op_kwargs)
TypeError: crime_stats_transformation() missing 1 required positional argument: 'filter_df'
[2022-08-28 15:19:10,134] {taskinstance.py:1267} INFO - Marking task as FAILED. dag_id=ETL_Examples, task_id=Transform, execution_date=20220828T014000, start_date=20220828T201910, end_date=20220828T201910
[2022-08-28 15:19:10,140] {logging_mixin.py:109} WARNING - /opt/anaconda3/lib/python3.9/site-packages/airflow/utils/context.py:152 AirflowContextDeprecationWarning: Accessing 'execution_date' from the template is deprecated and will be removed in a future version. Please use 'data_interval_start' or 'logical_date' instead.
[2022-08-28 15:19:10,141] {logging_mixin.py:109} WARNING - /opt/anaconda3/lib/python3.9/site-packages/airflow/utils/context.py:152 AirflowContextDeprecationWarning: Accessing 'next_ds' from the template is deprecated and will be removed in a future version. Please use '{{ data_interval_end | ds }}' instead.
[2022-08-28 15:19:10,141] {logging_mixin.py:109} WARNING - /opt/anaconda3/lib/python3.9/site-packages/airflow/utils/context.py:152 AirflowContextDeprecationWarning: Accessing 'next_ds_nodash' from the template is deprecated and will be removed in a future version. Please use '{{ data_interval_end | ds_nodash }}' instead.
[2022-08-28 15:19:10,142] {logging_mixin.py:109} WARNING - /opt/anaconda3/lib/python3.9/site-packages/airflow/utils/context.py:152 AirflowContextDeprecationWarning: Accessing 'next_execution_date' from the template is deprecated and will be removed in a future version. Please use 'data_interval_end' instead.
[2022-08-28 15:19:10,142] {logging_mixin.py:109} WARNING - /opt/anaconda3/lib/python3.9/site-packages/airflow/utils/context.py:152 AirflowContextDeprecationWarning: Accessing 'prev_ds' from the template is deprecated and will be removed in a future version.
[2022-08-28 15:19:10,143] {logging_mixin.py:109} WARNING - /opt/anaconda3/lib/python3.9/site-packages/airflow/utils/context.py:152 AirflowContextDeprecationWarning: Accessing 'prev_ds_nodash' from the template is deprecated and will be removed in a future version.
[2022-08-28 15:19:10,143] {logging_mixin.py:109} WARNING - /opt/anaconda3/lib/python3.9/site-packages/airflow/utils/context.py:152 AirflowContextDeprecationWarning: Accessing 'prev_execution_date' from the template is deprecated and will be removed in a future version.
[2022-08-28 15:19:10,144] {logging_mixin.py:109} WARNING - /opt/anaconda3/lib/python3.9/site-packages/airflow/utils/context.py:152 AirflowContextDeprecationWarning: Accessing 'prev_execution_date_success' from the template is deprecated and will be removed in a future version. Please use 'prev_data_interval_start_success' instead.
[2022-08-28 15:19:10,144] {logging_mixin.py:109} WARNING - /opt/anaconda3/lib/python3.9/site-packages/airflow/utils/context.py:152 AirflowContextDeprecationWarning: Accessing 'tomorrow_ds' from the template is deprecated and will be removed in a future version.
[2022-08-28 15:19:10,145] {logging_mixin.py:109} WARNING - /opt/anaconda3/lib/python3.9/site-packages/airflow/utils/context.py:152 AirflowContextDeprecationWarning: Accessing 'tomorrow_ds_nodash' from the template is deprecated and will be removed in a future version.
[2022-08-28 15:19:10,145] {logging_mixin.py:109} WARNING - /opt/anaconda3/lib/python3.9/site-packages/airflow/utils/context.py:152 AirflowContextDeprecationWarning: Accessing 'yesterday_ds' from the template is deprecated and will be removed in a future version.
[2022-08-28 15:19:10,146] {logging_mixin.py:109} WARNING - /opt/anaconda3/lib/python3.9/site-packages/airflow/utils/context.py:152 AirflowContextDeprecationWarning: Accessing 'yesterday_ds_nodash' from the template is deprecated and will be removed in a future version.
[2022-08-28 15:19:10,152] {logging_mixin.py:109} WARNING - /opt/anaconda3/lib/python3.9/site-packages/airflow/utils/email.py:102 PendingDeprecationWarning: Fetching SMTP credentials from configuration variables will be deprecated in a future release. Please set credentials using a connection instead.
[2022-08-28 15:19:10,152] {configuration.py:381} WARNING - section/key [smtp/smtp_user] not found in config
[2022-08-28 15:19:10,152] {email.py:208} INFO - Email alerting: attempt 1
[2022-08-28 15:19:10,156] {configuration.py:381} WARNING - section/key [smtp/smtp_user] not found in config
[2022-08-28 15:19:10,156] {email.py:208} INFO - Email alerting: attempt 1
[2022-08-28 15:19:10,157] {taskinstance.py:1751} ERROR - Failed to send email to: jonathan.dejesus.azor@gmail.com
Traceback (most recent call last):
  File "/opt/anaconda3/lib/python3.9/site-packages/airflow/models/taskinstance.py", line 1329, in _run_raw_task
    self._execute_task_with_callbacks(context)
  File "/opt/anaconda3/lib/python3.9/site-packages/airflow/models/taskinstance.py", line 1455, in _execute_task_with_callbacks
    result = self._execute_task(context, self.task)
  File "/opt/anaconda3/lib/python3.9/site-packages/airflow/models/taskinstance.py", line 1511, in _execute_task
    result = execute_callable(context=context)
  File "/opt/anaconda3/lib/python3.9/site-packages/airflow/operators/python.py", line 174, in execute
    return_value = self.execute_callable()
  File "/opt/anaconda3/lib/python3.9/site-packages/airflow/operators/python.py", line 185, in execute_callable
    return self.python_callable(*self.op_args, **self.op_kwargs)
TypeError: crime_stats_transformation() missing 1 required positional argument: 'filter_df'

During handling of the above exception, another exception occurred:

Traceback (most recent call last):
  File "/opt/anaconda3/lib/python3.9/site-packages/airflow/models/taskinstance.py", line 2093, in email_alert
    send_email(self.task.email, subject, html_content)
  File "/opt/anaconda3/lib/python3.9/site-packages/airflow/utils/email.py", line 55, in send_email
    return backend(
  File "/opt/anaconda3/lib/python3.9/site-packages/airflow/utils/email.py", line 102, in send_email_smtp
    send_mime_email(e_from=smtp_mail_from, e_to=recipients, mime_msg=msg, conn_id=conn_id, dryrun=dryrun)
  File "/opt/anaconda3/lib/python3.9/site-packages/airflow/utils/email.py", line 210, in send_mime_email
    conn = _get_smtp_connection(smtp_host, smtp_port, smtp_timeout, smtp_ssl)
  File "/opt/anaconda3/lib/python3.9/site-packages/airflow/utils/email.py", line 244, in _get_smtp_connection
    else smtplib.SMTP(host=host, port=port, timeout=timeout)
  File "/opt/anaconda3/lib/python3.9/smtplib.py", line 255, in __init__
    (code, msg) = self.connect(host, port)
  File "/opt/anaconda3/lib/python3.9/smtplib.py", line 341, in connect
    self.sock = self._get_socket(host, port, self.timeout)
  File "/opt/anaconda3/lib/python3.9/smtplib.py", line 312, in _get_socket
    return socket.create_connection((host, port), timeout,
  File "/opt/anaconda3/lib/python3.9/socket.py", line 844, in create_connection
    raise err
  File "/opt/anaconda3/lib/python3.9/socket.py", line 832, in create_connection
    sock.connect(sa)
ConnectionRefusedError: [Errno 61] Connection refused

During handling of the above exception, another exception occurred:

Traceback (most recent call last):
  File "/opt/anaconda3/lib/python3.9/site-packages/airflow/models/taskinstance.py", line 1749, in handle_failure
    self.email_alert(error)
  File "/opt/anaconda3/lib/python3.9/site-packages/airflow/models/taskinstance.py", line 2095, in email_alert
    send_email(self.task.email, subject, html_content_err)
  File "/opt/anaconda3/lib/python3.9/site-packages/airflow/utils/email.py", line 55, in send_email
    return backend(
  File "/opt/anaconda3/lib/python3.9/site-packages/airflow/utils/email.py", line 102, in send_email_smtp
    send_mime_email(e_from=smtp_mail_from, e_to=recipients, mime_msg=msg, conn_id=conn_id, dryrun=dryrun)
  File "/opt/anaconda3/lib/python3.9/site-packages/airflow/utils/email.py", line 210, in send_mime_email
    conn = _get_smtp_connection(smtp_host, smtp_port, smtp_timeout, smtp_ssl)
  File "/opt/anaconda3/lib/python3.9/site-packages/airflow/utils/email.py", line 244, in _get_smtp_connection
    else smtplib.SMTP(host=host, port=port, timeout=timeout)
  File "/opt/anaconda3/lib/python3.9/smtplib.py", line 255, in __init__
    (code, msg) = self.connect(host, port)
  File "/opt/anaconda3/lib/python3.9/smtplib.py", line 341, in connect
    self.sock = self._get_socket(host, port, self.timeout)
  File "/opt/anaconda3/lib/python3.9/smtplib.py", line 312, in _get_socket
    return socket.create_connection((host, port), timeout,
  File "/opt/anaconda3/lib/python3.9/socket.py", line 844, in create_connection
    raise err
  File "/opt/anaconda3/lib/python3.9/socket.py", line 832, in create_connection
    sock.connect(sa)
ConnectionRefusedError: [Errno 61] Connection refused
[2022-08-28 15:19:10,162] {standard_task_runner.py:89} ERROR - Failed to execute job 306 for task Transform
Traceback (most recent call last):
  File "/opt/anaconda3/lib/python3.9/site-packages/airflow/task/task_runner/standard_task_runner.py", line 85, in _start_by_fork
    args.func(args, dag=self.dag)
  File "/opt/anaconda3/lib/python3.9/site-packages/airflow/cli/cli_parser.py", line 48, in command
    return func(*args, **kwargs)
  File "/opt/anaconda3/lib/python3.9/site-packages/airflow/utils/cli.py", line 92, in wrapper
    return f(*args, **kwargs)
  File "/opt/anaconda3/lib/python3.9/site-packages/airflow/cli/commands/task_command.py", line 298, in task_run
    _run_task_by_selected_method(args, dag, ti)
  File "/opt/anaconda3/lib/python3.9/site-packages/airflow/cli/commands/task_command.py", line 107, in _run_task_by_selected_method
    _run_raw_task(args, ti)
  File "/opt/anaconda3/lib/python3.9/site-packages/airflow/cli/commands/task_command.py", line 180, in _run_raw_task
    ti._run_raw_task(
  File "/opt/anaconda3/lib/python3.9/site-packages/airflow/utils/session.py", line 70, in wrapper
    return func(*args, session=session, **kwargs)
  File "/opt/anaconda3/lib/python3.9/site-packages/airflow/models/taskinstance.py", line 1329, in _run_raw_task
    self._execute_task_with_callbacks(context)
  File "/opt/anaconda3/lib/python3.9/site-packages/airflow/models/taskinstance.py", line 1455, in _execute_task_with_callbacks
    result = self._execute_task(context, self.task)
  File "/opt/anaconda3/lib/python3.9/site-packages/airflow/models/taskinstance.py", line 1511, in _execute_task
    result = execute_callable(context=context)
  File "/opt/anaconda3/lib/python3.9/site-packages/airflow/operators/python.py", line 174, in execute
    return_value = self.execute_callable()
  File "/opt/anaconda3/lib/python3.9/site-packages/airflow/operators/python.py", line 185, in execute_callable
    return self.python_callable(*self.op_args, **self.op_kwargs)
TypeError: crime_stats_transformation() missing 1 required positional argument: 'filter_df'
[2022-08-28 15:19:10,185] {local_task_job.py:154} INFO - Task exited with return code 1
[2022-08-28 15:19:10,199] {local_task_job.py:264} INFO - 0 downstream tasks scheduled from follow-on schedule check
[2022-08-28 15:25:27,663] {taskinstance.py:1032} INFO - Dependencies all met for <TaskInstance: ETL_Examples.Transform scheduled__2022-08-28T01:40:00+00:00 [queued]>
[2022-08-28 15:25:27,667] {taskinstance.py:1032} INFO - Dependencies all met for <TaskInstance: ETL_Examples.Transform scheduled__2022-08-28T01:40:00+00:00 [queued]>
[2022-08-28 15:25:27,667] {taskinstance.py:1238} INFO - 
--------------------------------------------------------------------------------
[2022-08-28 15:25:27,667] {taskinstance.py:1239} INFO - Starting attempt 1 of 2
[2022-08-28 15:25:27,667] {taskinstance.py:1240} INFO - 
--------------------------------------------------------------------------------
[2022-08-28 15:25:27,671] {taskinstance.py:1259} INFO - Executing <Task(PythonOperator): Transform> on 2022-08-28 01:40:00+00:00
[2022-08-28 15:25:27,678] {standard_task_runner.py:52} INFO - Started process 30375 to run task
[2022-08-28 15:25:27,683] {standard_task_runner.py:76} INFO - Running: ['airflow', 'tasks', 'run', 'ETL_Examples', 'Transform', 'scheduled__2022-08-28T01:40:00+00:00', '--job-id', '361', '--raw', '--subdir', 'DAGS_FOLDER/Pushtobigquery2.py', '--cfg-path', '/var/folders/35/pzst1sv14yld_nkt23lk_vmr0000gn/T/tmpo700szhh', '--error-file', '/var/folders/35/pzst1sv14yld_nkt23lk_vmr0000gn/T/tmp8j8jj6zi']
[2022-08-28 15:25:27,684] {standard_task_runner.py:77} INFO - Job 361: Subtask Transform
[2022-08-28 15:25:27,708] {logging_mixin.py:109} INFO - Running <TaskInstance: ETL_Examples.Transform scheduled__2022-08-28T01:40:00+00:00 [running]> on host 1.0.0.127.in-addr.arpa
[2022-08-28 15:25:27,730] {taskinstance.py:1424} INFO - Exporting the following env vars:
AIRFLOW_CTX_DAG_EMAIL=jonathan.dejesus.azor@gmail.com
AIRFLOW_CTX_DAG_OWNER=admin
AIRFLOW_CTX_DAG_ID=ETL_Examples
AIRFLOW_CTX_TASK_ID=Transform
AIRFLOW_CTX_EXECUTION_DATE=2022-08-28T01:40:00+00:00
AIRFLOW_CTX_DAG_RUN_ID=scheduled__2022-08-28T01:40:00+00:00
[2022-08-28 15:25:27,730] {taskinstance.py:1700} ERROR - Task failed with exception
Traceback (most recent call last):
  File "/opt/anaconda3/lib/python3.9/site-packages/airflow/models/taskinstance.py", line 1329, in _run_raw_task
    self._execute_task_with_callbacks(context)
  File "/opt/anaconda3/lib/python3.9/site-packages/airflow/models/taskinstance.py", line 1455, in _execute_task_with_callbacks
    result = self._execute_task(context, self.task)
  File "/opt/anaconda3/lib/python3.9/site-packages/airflow/models/taskinstance.py", line 1511, in _execute_task
    result = execute_callable(context=context)
  File "/opt/anaconda3/lib/python3.9/site-packages/airflow/operators/python.py", line 174, in execute
    return_value = self.execute_callable()
  File "/opt/anaconda3/lib/python3.9/site-packages/airflow/operators/python.py", line 185, in execute_callable
    return self.python_callable(*self.op_args, **self.op_kwargs)
TypeError: crime_stats_transformation() missing 1 required positional argument: 'filter_df'
[2022-08-28 15:25:27,736] {taskinstance.py:1267} INFO - Marking task as UP_FOR_RETRY. dag_id=ETL_Examples, task_id=Transform, execution_date=20220828T014000, start_date=20220828T202527, end_date=20220828T202527
[2022-08-28 15:25:27,742] {logging_mixin.py:109} WARNING - /opt/anaconda3/lib/python3.9/site-packages/airflow/utils/context.py:152 AirflowContextDeprecationWarning: Accessing 'execution_date' from the template is deprecated and will be removed in a future version. Please use 'data_interval_start' or 'logical_date' instead.
[2022-08-28 15:25:27,743] {logging_mixin.py:109} WARNING - /opt/anaconda3/lib/python3.9/site-packages/airflow/utils/context.py:152 AirflowContextDeprecationWarning: Accessing 'next_ds' from the template is deprecated and will be removed in a future version. Please use '{{ data_interval_end | ds }}' instead.
[2022-08-28 15:25:27,744] {logging_mixin.py:109} WARNING - /opt/anaconda3/lib/python3.9/site-packages/airflow/utils/context.py:152 AirflowContextDeprecationWarning: Accessing 'next_ds_nodash' from the template is deprecated and will be removed in a future version. Please use '{{ data_interval_end | ds_nodash }}' instead.
[2022-08-28 15:25:27,744] {logging_mixin.py:109} WARNING - /opt/anaconda3/lib/python3.9/site-packages/airflow/utils/context.py:152 AirflowContextDeprecationWarning: Accessing 'next_execution_date' from the template is deprecated and will be removed in a future version. Please use 'data_interval_end' instead.
[2022-08-28 15:25:27,745] {logging_mixin.py:109} WARNING - /opt/anaconda3/lib/python3.9/site-packages/airflow/utils/context.py:152 AirflowContextDeprecationWarning: Accessing 'prev_ds' from the template is deprecated and will be removed in a future version.
[2022-08-28 15:25:27,745] {logging_mixin.py:109} WARNING - /opt/anaconda3/lib/python3.9/site-packages/airflow/utils/context.py:152 AirflowContextDeprecationWarning: Accessing 'prev_ds_nodash' from the template is deprecated and will be removed in a future version.
[2022-08-28 15:25:27,746] {logging_mixin.py:109} WARNING - /opt/anaconda3/lib/python3.9/site-packages/airflow/utils/context.py:152 AirflowContextDeprecationWarning: Accessing 'prev_execution_date' from the template is deprecated and will be removed in a future version.
[2022-08-28 15:25:27,746] {logging_mixin.py:109} WARNING - /opt/anaconda3/lib/python3.9/site-packages/airflow/utils/context.py:152 AirflowContextDeprecationWarning: Accessing 'prev_execution_date_success' from the template is deprecated and will be removed in a future version. Please use 'prev_data_interval_start_success' instead.
[2022-08-28 15:25:27,747] {logging_mixin.py:109} WARNING - /opt/anaconda3/lib/python3.9/site-packages/airflow/utils/context.py:152 AirflowContextDeprecationWarning: Accessing 'tomorrow_ds' from the template is deprecated and will be removed in a future version.
[2022-08-28 15:25:27,747] {logging_mixin.py:109} WARNING - /opt/anaconda3/lib/python3.9/site-packages/airflow/utils/context.py:152 AirflowContextDeprecationWarning: Accessing 'tomorrow_ds_nodash' from the template is deprecated and will be removed in a future version.
[2022-08-28 15:25:27,748] {logging_mixin.py:109} WARNING - /opt/anaconda3/lib/python3.9/site-packages/airflow/utils/context.py:152 AirflowContextDeprecationWarning: Accessing 'yesterday_ds' from the template is deprecated and will be removed in a future version.
[2022-08-28 15:25:27,748] {logging_mixin.py:109} WARNING - /opt/anaconda3/lib/python3.9/site-packages/airflow/utils/context.py:152 AirflowContextDeprecationWarning: Accessing 'yesterday_ds_nodash' from the template is deprecated and will be removed in a future version.
[2022-08-28 15:25:27,755] {logging_mixin.py:109} WARNING - /opt/anaconda3/lib/python3.9/site-packages/airflow/utils/email.py:102 PendingDeprecationWarning: Fetching SMTP credentials from configuration variables will be deprecated in a future release. Please set credentials using a connection instead.
[2022-08-28 15:25:27,755] {configuration.py:381} WARNING - section/key [smtp/smtp_user] not found in config
[2022-08-28 15:25:27,755] {email.py:208} INFO - Email alerting: attempt 1
[2022-08-28 15:25:27,758] {configuration.py:381} WARNING - section/key [smtp/smtp_user] not found in config
[2022-08-28 15:25:27,759] {email.py:208} INFO - Email alerting: attempt 1
[2022-08-28 15:25:27,759] {taskinstance.py:1751} ERROR - Failed to send email to: jonathan.dejesus.azor@gmail.com
Traceback (most recent call last):
  File "/opt/anaconda3/lib/python3.9/site-packages/airflow/models/taskinstance.py", line 1329, in _run_raw_task
    self._execute_task_with_callbacks(context)
  File "/opt/anaconda3/lib/python3.9/site-packages/airflow/models/taskinstance.py", line 1455, in _execute_task_with_callbacks
    result = self._execute_task(context, self.task)
  File "/opt/anaconda3/lib/python3.9/site-packages/airflow/models/taskinstance.py", line 1511, in _execute_task
    result = execute_callable(context=context)
  File "/opt/anaconda3/lib/python3.9/site-packages/airflow/operators/python.py", line 174, in execute
    return_value = self.execute_callable()
  File "/opt/anaconda3/lib/python3.9/site-packages/airflow/operators/python.py", line 185, in execute_callable
    return self.python_callable(*self.op_args, **self.op_kwargs)
TypeError: crime_stats_transformation() missing 1 required positional argument: 'filter_df'

During handling of the above exception, another exception occurred:

Traceback (most recent call last):
  File "/opt/anaconda3/lib/python3.9/site-packages/airflow/models/taskinstance.py", line 2093, in email_alert
    send_email(self.task.email, subject, html_content)
  File "/opt/anaconda3/lib/python3.9/site-packages/airflow/utils/email.py", line 55, in send_email
    return backend(
  File "/opt/anaconda3/lib/python3.9/site-packages/airflow/utils/email.py", line 102, in send_email_smtp
    send_mime_email(e_from=smtp_mail_from, e_to=recipients, mime_msg=msg, conn_id=conn_id, dryrun=dryrun)
  File "/opt/anaconda3/lib/python3.9/site-packages/airflow/utils/email.py", line 210, in send_mime_email
    conn = _get_smtp_connection(smtp_host, smtp_port, smtp_timeout, smtp_ssl)
  File "/opt/anaconda3/lib/python3.9/site-packages/airflow/utils/email.py", line 244, in _get_smtp_connection
    else smtplib.SMTP(host=host, port=port, timeout=timeout)
  File "/opt/anaconda3/lib/python3.9/smtplib.py", line 255, in __init__
    (code, msg) = self.connect(host, port)
  File "/opt/anaconda3/lib/python3.9/smtplib.py", line 341, in connect
    self.sock = self._get_socket(host, port, self.timeout)
  File "/opt/anaconda3/lib/python3.9/smtplib.py", line 312, in _get_socket
    return socket.create_connection((host, port), timeout,
  File "/opt/anaconda3/lib/python3.9/socket.py", line 844, in create_connection
    raise err
  File "/opt/anaconda3/lib/python3.9/socket.py", line 832, in create_connection
    sock.connect(sa)
ConnectionRefusedError: [Errno 61] Connection refused

During handling of the above exception, another exception occurred:

Traceback (most recent call last):
  File "/opt/anaconda3/lib/python3.9/site-packages/airflow/models/taskinstance.py", line 1749, in handle_failure
    self.email_alert(error)
  File "/opt/anaconda3/lib/python3.9/site-packages/airflow/models/taskinstance.py", line 2095, in email_alert
    send_email(self.task.email, subject, html_content_err)
  File "/opt/anaconda3/lib/python3.9/site-packages/airflow/utils/email.py", line 55, in send_email
    return backend(
  File "/opt/anaconda3/lib/python3.9/site-packages/airflow/utils/email.py", line 102, in send_email_smtp
    send_mime_email(e_from=smtp_mail_from, e_to=recipients, mime_msg=msg, conn_id=conn_id, dryrun=dryrun)
  File "/opt/anaconda3/lib/python3.9/site-packages/airflow/utils/email.py", line 210, in send_mime_email
    conn = _get_smtp_connection(smtp_host, smtp_port, smtp_timeout, smtp_ssl)
  File "/opt/anaconda3/lib/python3.9/site-packages/airflow/utils/email.py", line 244, in _get_smtp_connection
    else smtplib.SMTP(host=host, port=port, timeout=timeout)
  File "/opt/anaconda3/lib/python3.9/smtplib.py", line 255, in __init__
    (code, msg) = self.connect(host, port)
  File "/opt/anaconda3/lib/python3.9/smtplib.py", line 341, in connect
    self.sock = self._get_socket(host, port, self.timeout)
  File "/opt/anaconda3/lib/python3.9/smtplib.py", line 312, in _get_socket
    return socket.create_connection((host, port), timeout,
  File "/opt/anaconda3/lib/python3.9/socket.py", line 844, in create_connection
    raise err
  File "/opt/anaconda3/lib/python3.9/socket.py", line 832, in create_connection
    sock.connect(sa)
ConnectionRefusedError: [Errno 61] Connection refused
[2022-08-28 15:25:27,765] {standard_task_runner.py:89} ERROR - Failed to execute job 361 for task Transform
Traceback (most recent call last):
  File "/opt/anaconda3/lib/python3.9/site-packages/airflow/task/task_runner/standard_task_runner.py", line 85, in _start_by_fork
    args.func(args, dag=self.dag)
  File "/opt/anaconda3/lib/python3.9/site-packages/airflow/cli/cli_parser.py", line 48, in command
    return func(*args, **kwargs)
  File "/opt/anaconda3/lib/python3.9/site-packages/airflow/utils/cli.py", line 92, in wrapper
    return f(*args, **kwargs)
  File "/opt/anaconda3/lib/python3.9/site-packages/airflow/cli/commands/task_command.py", line 298, in task_run
    _run_task_by_selected_method(args, dag, ti)
  File "/opt/anaconda3/lib/python3.9/site-packages/airflow/cli/commands/task_command.py", line 107, in _run_task_by_selected_method
    _run_raw_task(args, ti)
  File "/opt/anaconda3/lib/python3.9/site-packages/airflow/cli/commands/task_command.py", line 180, in _run_raw_task
    ti._run_raw_task(
  File "/opt/anaconda3/lib/python3.9/site-packages/airflow/utils/session.py", line 70, in wrapper
    return func(*args, session=session, **kwargs)
  File "/opt/anaconda3/lib/python3.9/site-packages/airflow/models/taskinstance.py", line 1329, in _run_raw_task
    self._execute_task_with_callbacks(context)
  File "/opt/anaconda3/lib/python3.9/site-packages/airflow/models/taskinstance.py", line 1455, in _execute_task_with_callbacks
    result = self._execute_task(context, self.task)
  File "/opt/anaconda3/lib/python3.9/site-packages/airflow/models/taskinstance.py", line 1511, in _execute_task
    result = execute_callable(context=context)
  File "/opt/anaconda3/lib/python3.9/site-packages/airflow/operators/python.py", line 174, in execute
    return_value = self.execute_callable()
  File "/opt/anaconda3/lib/python3.9/site-packages/airflow/operators/python.py", line 185, in execute_callable
    return self.python_callable(*self.op_args, **self.op_kwargs)
TypeError: crime_stats_transformation() missing 1 required positional argument: 'filter_df'
[2022-08-28 15:25:27,790] {local_task_job.py:154} INFO - Task exited with return code 1
[2022-08-28 15:25:27,802] {local_task_job.py:264} INFO - 0 downstream tasks scheduled from follow-on schedule check
[2022-08-28 15:49:00,575] {taskinstance.py:1032} INFO - Dependencies all met for <TaskInstance: ETL_Examples.Transform scheduled__2022-08-28T01:40:00+00:00 [queued]>
[2022-08-28 15:49:00,578] {taskinstance.py:1032} INFO - Dependencies all met for <TaskInstance: ETL_Examples.Transform scheduled__2022-08-28T01:40:00+00:00 [queued]>
[2022-08-28 15:49:00,578] {taskinstance.py:1238} INFO - 
--------------------------------------------------------------------------------
[2022-08-28 15:49:00,578] {taskinstance.py:1239} INFO - Starting attempt 1 of 2
[2022-08-28 15:49:00,578] {taskinstance.py:1240} INFO - 
--------------------------------------------------------------------------------
[2022-08-28 15:49:00,582] {taskinstance.py:1259} INFO - Executing <Task(PythonOperator): Transform> on 2022-08-28 01:40:00+00:00
[2022-08-28 15:49:00,589] {standard_task_runner.py:52} INFO - Started process 31083 to run task
[2022-08-28 15:49:00,593] {standard_task_runner.py:76} INFO - Running: ['airflow', 'tasks', 'run', 'ETL_Examples', 'Transform', 'scheduled__2022-08-28T01:40:00+00:00', '--job-id', '435', '--raw', '--subdir', 'DAGS_FOLDER/Pushtobigquery2.py', '--cfg-path', '/var/folders/35/pzst1sv14yld_nkt23lk_vmr0000gn/T/tmpwfom183x', '--error-file', '/var/folders/35/pzst1sv14yld_nkt23lk_vmr0000gn/T/tmp6c15598o']
[2022-08-28 15:49:00,594] {standard_task_runner.py:77} INFO - Job 435: Subtask Transform
[2022-08-28 15:49:00,617] {logging_mixin.py:109} INFO - Running <TaskInstance: ETL_Examples.Transform scheduled__2022-08-28T01:40:00+00:00 [running]> on host 1.0.0.127.in-addr.arpa
[2022-08-28 15:49:00,638] {taskinstance.py:1424} INFO - Exporting the following env vars:
AIRFLOW_CTX_DAG_EMAIL=jonathan.dejesus.azor@gmail.com
AIRFLOW_CTX_DAG_OWNER=admin
AIRFLOW_CTX_DAG_ID=ETL_Examples
AIRFLOW_CTX_TASK_ID=Transform
AIRFLOW_CTX_EXECUTION_DATE=2022-08-28T01:40:00+00:00
AIRFLOW_CTX_DAG_RUN_ID=scheduled__2022-08-28T01:40:00+00:00
[2022-08-28 15:49:00,643] {logging_mixin.py:109} WARNING - /opt/anaconda3/lib/python3.9/site-packages/airflow/utils/context.py:152 AirflowContextDeprecationWarning: Accessing 'execution_date' from the template is deprecated and will be removed in a future version. Please use 'data_interval_start' or 'logical_date' instead.
[2022-08-28 15:49:00,643] {logging_mixin.py:109} WARNING - /opt/anaconda3/lib/python3.9/site-packages/airflow/utils/context.py:152 AirflowContextDeprecationWarning: Accessing 'next_ds' from the template is deprecated and will be removed in a future version. Please use '{{ data_interval_end | ds }}' instead.
[2022-08-28 15:49:00,644] {logging_mixin.py:109} WARNING - /opt/anaconda3/lib/python3.9/site-packages/airflow/utils/context.py:152 AirflowContextDeprecationWarning: Accessing 'next_ds_nodash' from the template is deprecated and will be removed in a future version. Please use '{{ data_interval_end | ds_nodash }}' instead.
[2022-08-28 15:49:00,644] {logging_mixin.py:109} WARNING - /opt/anaconda3/lib/python3.9/site-packages/airflow/utils/context.py:152 AirflowContextDeprecationWarning: Accessing 'next_execution_date' from the template is deprecated and will be removed in a future version. Please use 'data_interval_end' instead.
[2022-08-28 15:49:00,645] {logging_mixin.py:109} WARNING - /opt/anaconda3/lib/python3.9/site-packages/airflow/utils/context.py:152 AirflowContextDeprecationWarning: Accessing 'prev_ds' from the template is deprecated and will be removed in a future version.
[2022-08-28 15:49:00,646] {logging_mixin.py:109} WARNING - /opt/anaconda3/lib/python3.9/site-packages/airflow/utils/context.py:152 AirflowContextDeprecationWarning: Accessing 'prev_ds_nodash' from the template is deprecated and will be removed in a future version.
[2022-08-28 15:49:00,646] {logging_mixin.py:109} WARNING - /opt/anaconda3/lib/python3.9/site-packages/airflow/utils/context.py:152 AirflowContextDeprecationWarning: Accessing 'prev_execution_date' from the template is deprecated and will be removed in a future version.
[2022-08-28 15:49:00,647] {logging_mixin.py:109} WARNING - /opt/anaconda3/lib/python3.9/site-packages/airflow/utils/context.py:152 AirflowContextDeprecationWarning: Accessing 'prev_execution_date_success' from the template is deprecated and will be removed in a future version. Please use 'prev_data_interval_start_success' instead.
[2022-08-28 15:49:00,647] {logging_mixin.py:109} WARNING - /opt/anaconda3/lib/python3.9/site-packages/airflow/utils/context.py:152 AirflowContextDeprecationWarning: Accessing 'tomorrow_ds' from the template is deprecated and will be removed in a future version.
[2022-08-28 15:49:00,648] {logging_mixin.py:109} WARNING - /opt/anaconda3/lib/python3.9/site-packages/airflow/utils/context.py:152 AirflowContextDeprecationWarning: Accessing 'tomorrow_ds_nodash' from the template is deprecated and will be removed in a future version.
[2022-08-28 15:49:00,648] {logging_mixin.py:109} WARNING - /opt/anaconda3/lib/python3.9/site-packages/airflow/utils/context.py:152 AirflowContextDeprecationWarning: Accessing 'yesterday_ds' from the template is deprecated and will be removed in a future version.
[2022-08-28 15:49:00,649] {logging_mixin.py:109} WARNING - /opt/anaconda3/lib/python3.9/site-packages/airflow/utils/context.py:152 AirflowContextDeprecationWarning: Accessing 'yesterday_ds_nodash' from the template is deprecated and will be removed in a future version.
[2022-08-28 15:49:00,649] {taskinstance.py:1700} ERROR - Task failed with exception
Traceback (most recent call last):
  File "/opt/anaconda3/lib/python3.9/site-packages/airflow/models/taskinstance.py", line 1329, in _run_raw_task
    self._execute_task_with_callbacks(context)
  File "/opt/anaconda3/lib/python3.9/site-packages/airflow/models/taskinstance.py", line 1455, in _execute_task_with_callbacks
    result = self._execute_task(context, self.task)
  File "/opt/anaconda3/lib/python3.9/site-packages/airflow/models/taskinstance.py", line 1511, in _execute_task
    result = execute_callable(context=context)
  File "/opt/anaconda3/lib/python3.9/site-packages/airflow/operators/python.py", line 174, in execute
    return_value = self.execute_callable()
  File "/opt/anaconda3/lib/python3.9/site-packages/airflow/operators/python.py", line 185, in execute_callable
    return self.python_callable(*self.op_args, **self.op_kwargs)
  File "/Users/theonewiththelion/airflow/dags/Pushtobigquery2.py", line 73, in crime_stats_transformation
    filter_df.rename(columns = {'occ_date' : 'occurred_date',
NameError: name 'filter_df' is not defined
[2022-08-28 15:49:00,653] {taskinstance.py:1267} INFO - Marking task as UP_FOR_RETRY. dag_id=ETL_Examples, task_id=Transform, execution_date=20220828T014000, start_date=20220828T204900, end_date=20220828T204900
[2022-08-28 15:49:00,657] {logging_mixin.py:109} WARNING - /opt/anaconda3/lib/python3.9/site-packages/airflow/utils/context.py:152 AirflowContextDeprecationWarning: Accessing 'execution_date' from the template is deprecated and will be removed in a future version. Please use 'data_interval_start' or 'logical_date' instead.
[2022-08-28 15:49:00,657] {logging_mixin.py:109} WARNING - /opt/anaconda3/lib/python3.9/site-packages/airflow/utils/context.py:152 AirflowContextDeprecationWarning: Accessing 'next_ds' from the template is deprecated and will be removed in a future version. Please use '{{ data_interval_end | ds }}' instead.
[2022-08-28 15:49:00,658] {logging_mixin.py:109} WARNING - /opt/anaconda3/lib/python3.9/site-packages/airflow/utils/context.py:152 AirflowContextDeprecationWarning: Accessing 'next_ds_nodash' from the template is deprecated and will be removed in a future version. Please use '{{ data_interval_end | ds_nodash }}' instead.
[2022-08-28 15:49:00,658] {logging_mixin.py:109} WARNING - /opt/anaconda3/lib/python3.9/site-packages/airflow/utils/context.py:152 AirflowContextDeprecationWarning: Accessing 'next_execution_date' from the template is deprecated and will be removed in a future version. Please use 'data_interval_end' instead.
[2022-08-28 15:49:00,659] {logging_mixin.py:109} WARNING - /opt/anaconda3/lib/python3.9/site-packages/airflow/utils/context.py:152 AirflowContextDeprecationWarning: Accessing 'prev_ds' from the template is deprecated and will be removed in a future version.
[2022-08-28 15:49:00,659] {logging_mixin.py:109} WARNING - /opt/anaconda3/lib/python3.9/site-packages/airflow/utils/context.py:152 AirflowContextDeprecationWarning: Accessing 'prev_ds_nodash' from the template is deprecated and will be removed in a future version.
[2022-08-28 15:49:00,660] {logging_mixin.py:109} WARNING - /opt/anaconda3/lib/python3.9/site-packages/airflow/utils/context.py:152 AirflowContextDeprecationWarning: Accessing 'prev_execution_date' from the template is deprecated and will be removed in a future version.
[2022-08-28 15:49:00,660] {logging_mixin.py:109} WARNING - /opt/anaconda3/lib/python3.9/site-packages/airflow/utils/context.py:152 AirflowContextDeprecationWarning: Accessing 'prev_execution_date_success' from the template is deprecated and will be removed in a future version. Please use 'prev_data_interval_start_success' instead.
[2022-08-28 15:49:00,661] {logging_mixin.py:109} WARNING - /opt/anaconda3/lib/python3.9/site-packages/airflow/utils/context.py:152 AirflowContextDeprecationWarning: Accessing 'tomorrow_ds' from the template is deprecated and will be removed in a future version.
[2022-08-28 15:49:00,661] {logging_mixin.py:109} WARNING - /opt/anaconda3/lib/python3.9/site-packages/airflow/utils/context.py:152 AirflowContextDeprecationWarning: Accessing 'tomorrow_ds_nodash' from the template is deprecated and will be removed in a future version.
[2022-08-28 15:49:00,662] {logging_mixin.py:109} WARNING - /opt/anaconda3/lib/python3.9/site-packages/airflow/utils/context.py:152 AirflowContextDeprecationWarning: Accessing 'yesterday_ds' from the template is deprecated and will be removed in a future version.
[2022-08-28 15:49:00,662] {logging_mixin.py:109} WARNING - /opt/anaconda3/lib/python3.9/site-packages/airflow/utils/context.py:152 AirflowContextDeprecationWarning: Accessing 'yesterday_ds_nodash' from the template is deprecated and will be removed in a future version.
[2022-08-28 15:49:00,668] {logging_mixin.py:109} WARNING - /opt/anaconda3/lib/python3.9/site-packages/airflow/utils/email.py:102 PendingDeprecationWarning: Fetching SMTP credentials from configuration variables will be deprecated in a future release. Please set credentials using a connection instead.
[2022-08-28 15:49:00,668] {configuration.py:381} WARNING - section/key [smtp/smtp_user] not found in config
[2022-08-28 15:49:00,668] {email.py:208} INFO - Email alerting: attempt 1
[2022-08-28 15:49:00,672] {configuration.py:381} WARNING - section/key [smtp/smtp_user] not found in config
[2022-08-28 15:49:00,672] {email.py:208} INFO - Email alerting: attempt 1
[2022-08-28 15:49:00,673] {taskinstance.py:1751} ERROR - Failed to send email to: jonathan.dejesus.azor@gmail.com
Traceback (most recent call last):
  File "/opt/anaconda3/lib/python3.9/site-packages/airflow/models/taskinstance.py", line 1329, in _run_raw_task
    self._execute_task_with_callbacks(context)
  File "/opt/anaconda3/lib/python3.9/site-packages/airflow/models/taskinstance.py", line 1455, in _execute_task_with_callbacks
    result = self._execute_task(context, self.task)
  File "/opt/anaconda3/lib/python3.9/site-packages/airflow/models/taskinstance.py", line 1511, in _execute_task
    result = execute_callable(context=context)
  File "/opt/anaconda3/lib/python3.9/site-packages/airflow/operators/python.py", line 174, in execute
    return_value = self.execute_callable()
  File "/opt/anaconda3/lib/python3.9/site-packages/airflow/operators/python.py", line 185, in execute_callable
    return self.python_callable(*self.op_args, **self.op_kwargs)
  File "/Users/theonewiththelion/airflow/dags/Pushtobigquery2.py", line 73, in crime_stats_transformation
    filter_df.rename(columns = {'occ_date' : 'occurred_date',
NameError: name 'filter_df' is not defined

During handling of the above exception, another exception occurred:

Traceback (most recent call last):
  File "/opt/anaconda3/lib/python3.9/site-packages/airflow/models/taskinstance.py", line 2093, in email_alert
    send_email(self.task.email, subject, html_content)
  File "/opt/anaconda3/lib/python3.9/site-packages/airflow/utils/email.py", line 55, in send_email
    return backend(
  File "/opt/anaconda3/lib/python3.9/site-packages/airflow/utils/email.py", line 102, in send_email_smtp
    send_mime_email(e_from=smtp_mail_from, e_to=recipients, mime_msg=msg, conn_id=conn_id, dryrun=dryrun)
  File "/opt/anaconda3/lib/python3.9/site-packages/airflow/utils/email.py", line 210, in send_mime_email
    conn = _get_smtp_connection(smtp_host, smtp_port, smtp_timeout, smtp_ssl)
  File "/opt/anaconda3/lib/python3.9/site-packages/airflow/utils/email.py", line 244, in _get_smtp_connection
    else smtplib.SMTP(host=host, port=port, timeout=timeout)
  File "/opt/anaconda3/lib/python3.9/smtplib.py", line 255, in __init__
    (code, msg) = self.connect(host, port)
  File "/opt/anaconda3/lib/python3.9/smtplib.py", line 341, in connect
    self.sock = self._get_socket(host, port, self.timeout)
  File "/opt/anaconda3/lib/python3.9/smtplib.py", line 312, in _get_socket
    return socket.create_connection((host, port), timeout,
  File "/opt/anaconda3/lib/python3.9/socket.py", line 844, in create_connection
    raise err
  File "/opt/anaconda3/lib/python3.9/socket.py", line 832, in create_connection
    sock.connect(sa)
ConnectionRefusedError: [Errno 61] Connection refused

During handling of the above exception, another exception occurred:

Traceback (most recent call last):
  File "/opt/anaconda3/lib/python3.9/site-packages/airflow/models/taskinstance.py", line 1749, in handle_failure
    self.email_alert(error)
  File "/opt/anaconda3/lib/python3.9/site-packages/airflow/models/taskinstance.py", line 2095, in email_alert
    send_email(self.task.email, subject, html_content_err)
  File "/opt/anaconda3/lib/python3.9/site-packages/airflow/utils/email.py", line 55, in send_email
    return backend(
  File "/opt/anaconda3/lib/python3.9/site-packages/airflow/utils/email.py", line 102, in send_email_smtp
    send_mime_email(e_from=smtp_mail_from, e_to=recipients, mime_msg=msg, conn_id=conn_id, dryrun=dryrun)
  File "/opt/anaconda3/lib/python3.9/site-packages/airflow/utils/email.py", line 210, in send_mime_email
    conn = _get_smtp_connection(smtp_host, smtp_port, smtp_timeout, smtp_ssl)
  File "/opt/anaconda3/lib/python3.9/site-packages/airflow/utils/email.py", line 244, in _get_smtp_connection
    else smtplib.SMTP(host=host, port=port, timeout=timeout)
  File "/opt/anaconda3/lib/python3.9/smtplib.py", line 255, in __init__
    (code, msg) = self.connect(host, port)
  File "/opt/anaconda3/lib/python3.9/smtplib.py", line 341, in connect
    self.sock = self._get_socket(host, port, self.timeout)
  File "/opt/anaconda3/lib/python3.9/smtplib.py", line 312, in _get_socket
    return socket.create_connection((host, port), timeout,
  File "/opt/anaconda3/lib/python3.9/socket.py", line 844, in create_connection
    raise err
  File "/opt/anaconda3/lib/python3.9/socket.py", line 832, in create_connection
    sock.connect(sa)
ConnectionRefusedError: [Errno 61] Connection refused
[2022-08-28 15:49:00,678] {standard_task_runner.py:89} ERROR - Failed to execute job 435 for task Transform
Traceback (most recent call last):
  File "/opt/anaconda3/lib/python3.9/site-packages/airflow/task/task_runner/standard_task_runner.py", line 85, in _start_by_fork
    args.func(args, dag=self.dag)
  File "/opt/anaconda3/lib/python3.9/site-packages/airflow/cli/cli_parser.py", line 48, in command
    return func(*args, **kwargs)
  File "/opt/anaconda3/lib/python3.9/site-packages/airflow/utils/cli.py", line 92, in wrapper
    return f(*args, **kwargs)
  File "/opt/anaconda3/lib/python3.9/site-packages/airflow/cli/commands/task_command.py", line 298, in task_run
    _run_task_by_selected_method(args, dag, ti)
  File "/opt/anaconda3/lib/python3.9/site-packages/airflow/cli/commands/task_command.py", line 107, in _run_task_by_selected_method
    _run_raw_task(args, ti)
  File "/opt/anaconda3/lib/python3.9/site-packages/airflow/cli/commands/task_command.py", line 180, in _run_raw_task
    ti._run_raw_task(
  File "/opt/anaconda3/lib/python3.9/site-packages/airflow/utils/session.py", line 70, in wrapper
    return func(*args, session=session, **kwargs)
  File "/opt/anaconda3/lib/python3.9/site-packages/airflow/models/taskinstance.py", line 1329, in _run_raw_task
    self._execute_task_with_callbacks(context)
  File "/opt/anaconda3/lib/python3.9/site-packages/airflow/models/taskinstance.py", line 1455, in _execute_task_with_callbacks
    result = self._execute_task(context, self.task)
  File "/opt/anaconda3/lib/python3.9/site-packages/airflow/models/taskinstance.py", line 1511, in _execute_task
    result = execute_callable(context=context)
  File "/opt/anaconda3/lib/python3.9/site-packages/airflow/operators/python.py", line 174, in execute
    return_value = self.execute_callable()
  File "/opt/anaconda3/lib/python3.9/site-packages/airflow/operators/python.py", line 185, in execute_callable
    return self.python_callable(*self.op_args, **self.op_kwargs)
  File "/Users/theonewiththelion/airflow/dags/Pushtobigquery2.py", line 73, in crime_stats_transformation
    filter_df.rename(columns = {'occ_date' : 'occurred_date',
NameError: name 'filter_df' is not defined
[2022-08-28 15:49:00,698] {local_task_job.py:154} INFO - Task exited with return code 1
[2022-08-28 15:49:00,710] {local_task_job.py:264} INFO - 0 downstream tasks scheduled from follow-on schedule check
[2022-08-28 15:50:41,663] {taskinstance.py:1032} INFO - Dependencies all met for <TaskInstance: ETL_Examples.Transform scheduled__2022-08-28T01:40:00+00:00 [queued]>
[2022-08-28 15:50:41,667] {taskinstance.py:1032} INFO - Dependencies all met for <TaskInstance: ETL_Examples.Transform scheduled__2022-08-28T01:40:00+00:00 [queued]>
[2022-08-28 15:50:41,667] {taskinstance.py:1238} INFO - 
--------------------------------------------------------------------------------
[2022-08-28 15:50:41,667] {taskinstance.py:1239} INFO - Starting attempt 1 of 2
[2022-08-28 15:50:41,667] {taskinstance.py:1240} INFO - 
--------------------------------------------------------------------------------
[2022-08-28 15:50:41,672] {taskinstance.py:1259} INFO - Executing <Task(PythonOperator): Transform> on 2022-08-28 01:40:00+00:00
[2022-08-28 15:50:41,681] {standard_task_runner.py:52} INFO - Started process 31174 to run task
[2022-08-28 15:50:41,685] {standard_task_runner.py:76} INFO - Running: ['airflow', 'tasks', 'run', 'ETL_Examples', 'Transform', 'scheduled__2022-08-28T01:40:00+00:00', '--job-id', '459', '--raw', '--subdir', 'DAGS_FOLDER/Pushtobigquery2.py', '--cfg-path', '/var/folders/35/pzst1sv14yld_nkt23lk_vmr0000gn/T/tmpao0j0ufc', '--error-file', '/var/folders/35/pzst1sv14yld_nkt23lk_vmr0000gn/T/tmpx6gue14r']
[2022-08-28 15:50:41,687] {standard_task_runner.py:77} INFO - Job 459: Subtask Transform
[2022-08-28 15:50:41,714] {logging_mixin.py:109} INFO - Running <TaskInstance: ETL_Examples.Transform scheduled__2022-08-28T01:40:00+00:00 [running]> on host 1.0.0.127.in-addr.arpa
[2022-08-28 15:50:41,737] {taskinstance.py:1424} INFO - Exporting the following env vars:
AIRFLOW_CTX_DAG_EMAIL=jonathan.dejesus.azor@gmail.com
AIRFLOW_CTX_DAG_OWNER=admin
AIRFLOW_CTX_DAG_ID=ETL_Examples
AIRFLOW_CTX_TASK_ID=Transform
AIRFLOW_CTX_EXECUTION_DATE=2022-08-28T01:40:00+00:00
AIRFLOW_CTX_DAG_RUN_ID=scheduled__2022-08-28T01:40:00+00:00
[2022-08-28 15:50:41,738] {taskinstance.py:1700} ERROR - Task failed with exception
Traceback (most recent call last):
  File "/opt/anaconda3/lib/python3.9/site-packages/airflow/models/taskinstance.py", line 1329, in _run_raw_task
    self._execute_task_with_callbacks(context)
  File "/opt/anaconda3/lib/python3.9/site-packages/airflow/models/taskinstance.py", line 1455, in _execute_task_with_callbacks
    result = self._execute_task(context, self.task)
  File "/opt/anaconda3/lib/python3.9/site-packages/airflow/models/taskinstance.py", line 1511, in _execute_task
    result = execute_callable(context=context)
  File "/opt/anaconda3/lib/python3.9/site-packages/airflow/operators/python.py", line 174, in execute
    return_value = self.execute_callable()
  File "/opt/anaconda3/lib/python3.9/site-packages/airflow/operators/python.py", line 185, in execute_callable
    return self.python_callable(*self.op_args, **self.op_kwargs)
TypeError: crime_stats_transformation() missing 1 required positional argument: 'filter_df'
[2022-08-28 15:50:41,744] {taskinstance.py:1267} INFO - Marking task as UP_FOR_RETRY. dag_id=ETL_Examples, task_id=Transform, execution_date=20220828T014000, start_date=20220828T205041, end_date=20220828T205041
[2022-08-28 15:50:41,751] {logging_mixin.py:109} WARNING - /opt/anaconda3/lib/python3.9/site-packages/airflow/utils/context.py:152 AirflowContextDeprecationWarning: Accessing 'execution_date' from the template is deprecated and will be removed in a future version. Please use 'data_interval_start' or 'logical_date' instead.
[2022-08-28 15:50:41,752] {logging_mixin.py:109} WARNING - /opt/anaconda3/lib/python3.9/site-packages/airflow/utils/context.py:152 AirflowContextDeprecationWarning: Accessing 'next_ds' from the template is deprecated and will be removed in a future version. Please use '{{ data_interval_end | ds }}' instead.
[2022-08-28 15:50:41,752] {logging_mixin.py:109} WARNING - /opt/anaconda3/lib/python3.9/site-packages/airflow/utils/context.py:152 AirflowContextDeprecationWarning: Accessing 'next_ds_nodash' from the template is deprecated and will be removed in a future version. Please use '{{ data_interval_end | ds_nodash }}' instead.
[2022-08-28 15:50:41,753] {logging_mixin.py:109} WARNING - /opt/anaconda3/lib/python3.9/site-packages/airflow/utils/context.py:152 AirflowContextDeprecationWarning: Accessing 'next_execution_date' from the template is deprecated and will be removed in a future version. Please use 'data_interval_end' instead.
[2022-08-28 15:50:41,753] {logging_mixin.py:109} WARNING - /opt/anaconda3/lib/python3.9/site-packages/airflow/utils/context.py:152 AirflowContextDeprecationWarning: Accessing 'prev_ds' from the template is deprecated and will be removed in a future version.
[2022-08-28 15:50:41,754] {logging_mixin.py:109} WARNING - /opt/anaconda3/lib/python3.9/site-packages/airflow/utils/context.py:152 AirflowContextDeprecationWarning: Accessing 'prev_ds_nodash' from the template is deprecated and will be removed in a future version.
[2022-08-28 15:50:41,755] {logging_mixin.py:109} WARNING - /opt/anaconda3/lib/python3.9/site-packages/airflow/utils/context.py:152 AirflowContextDeprecationWarning: Accessing 'prev_execution_date' from the template is deprecated and will be removed in a future version.
[2022-08-28 15:50:41,755] {logging_mixin.py:109} WARNING - /opt/anaconda3/lib/python3.9/site-packages/airflow/utils/context.py:152 AirflowContextDeprecationWarning: Accessing 'prev_execution_date_success' from the template is deprecated and will be removed in a future version. Please use 'prev_data_interval_start_success' instead.
[2022-08-28 15:50:41,756] {logging_mixin.py:109} WARNING - /opt/anaconda3/lib/python3.9/site-packages/airflow/utils/context.py:152 AirflowContextDeprecationWarning: Accessing 'tomorrow_ds' from the template is deprecated and will be removed in a future version.
[2022-08-28 15:50:41,756] {logging_mixin.py:109} WARNING - /opt/anaconda3/lib/python3.9/site-packages/airflow/utils/context.py:152 AirflowContextDeprecationWarning: Accessing 'tomorrow_ds_nodash' from the template is deprecated and will be removed in a future version.
[2022-08-28 15:50:41,757] {logging_mixin.py:109} WARNING - /opt/anaconda3/lib/python3.9/site-packages/airflow/utils/context.py:152 AirflowContextDeprecationWarning: Accessing 'yesterday_ds' from the template is deprecated and will be removed in a future version.
[2022-08-28 15:50:41,757] {logging_mixin.py:109} WARNING - /opt/anaconda3/lib/python3.9/site-packages/airflow/utils/context.py:152 AirflowContextDeprecationWarning: Accessing 'yesterday_ds_nodash' from the template is deprecated and will be removed in a future version.
[2022-08-28 15:50:41,764] {logging_mixin.py:109} WARNING - /opt/anaconda3/lib/python3.9/site-packages/airflow/utils/email.py:102 PendingDeprecationWarning: Fetching SMTP credentials from configuration variables will be deprecated in a future release. Please set credentials using a connection instead.
[2022-08-28 15:50:41,764] {configuration.py:381} WARNING - section/key [smtp/smtp_user] not found in config
[2022-08-28 15:50:41,764] {email.py:208} INFO - Email alerting: attempt 1
[2022-08-28 15:50:41,768] {configuration.py:381} WARNING - section/key [smtp/smtp_user] not found in config
[2022-08-28 15:50:41,768] {email.py:208} INFO - Email alerting: attempt 1
[2022-08-28 15:50:41,768] {taskinstance.py:1751} ERROR - Failed to send email to: jonathan.dejesus.azor@gmail.com
Traceback (most recent call last):
  File "/opt/anaconda3/lib/python3.9/site-packages/airflow/models/taskinstance.py", line 1329, in _run_raw_task
    self._execute_task_with_callbacks(context)
  File "/opt/anaconda3/lib/python3.9/site-packages/airflow/models/taskinstance.py", line 1455, in _execute_task_with_callbacks
    result = self._execute_task(context, self.task)
  File "/opt/anaconda3/lib/python3.9/site-packages/airflow/models/taskinstance.py", line 1511, in _execute_task
    result = execute_callable(context=context)
  File "/opt/anaconda3/lib/python3.9/site-packages/airflow/operators/python.py", line 174, in execute
    return_value = self.execute_callable()
  File "/opt/anaconda3/lib/python3.9/site-packages/airflow/operators/python.py", line 185, in execute_callable
    return self.python_callable(*self.op_args, **self.op_kwargs)
TypeError: crime_stats_transformation() missing 1 required positional argument: 'filter_df'

During handling of the above exception, another exception occurred:

Traceback (most recent call last):
  File "/opt/anaconda3/lib/python3.9/site-packages/airflow/models/taskinstance.py", line 2093, in email_alert
    send_email(self.task.email, subject, html_content)
  File "/opt/anaconda3/lib/python3.9/site-packages/airflow/utils/email.py", line 55, in send_email
    return backend(
  File "/opt/anaconda3/lib/python3.9/site-packages/airflow/utils/email.py", line 102, in send_email_smtp
    send_mime_email(e_from=smtp_mail_from, e_to=recipients, mime_msg=msg, conn_id=conn_id, dryrun=dryrun)
  File "/opt/anaconda3/lib/python3.9/site-packages/airflow/utils/email.py", line 210, in send_mime_email
    conn = _get_smtp_connection(smtp_host, smtp_port, smtp_timeout, smtp_ssl)
  File "/opt/anaconda3/lib/python3.9/site-packages/airflow/utils/email.py", line 244, in _get_smtp_connection
    else smtplib.SMTP(host=host, port=port, timeout=timeout)
  File "/opt/anaconda3/lib/python3.9/smtplib.py", line 255, in __init__
    (code, msg) = self.connect(host, port)
  File "/opt/anaconda3/lib/python3.9/smtplib.py", line 341, in connect
    self.sock = self._get_socket(host, port, self.timeout)
  File "/opt/anaconda3/lib/python3.9/smtplib.py", line 312, in _get_socket
    return socket.create_connection((host, port), timeout,
  File "/opt/anaconda3/lib/python3.9/socket.py", line 844, in create_connection
    raise err
  File "/opt/anaconda3/lib/python3.9/socket.py", line 832, in create_connection
    sock.connect(sa)
ConnectionRefusedError: [Errno 61] Connection refused

During handling of the above exception, another exception occurred:

Traceback (most recent call last):
  File "/opt/anaconda3/lib/python3.9/site-packages/airflow/models/taskinstance.py", line 1749, in handle_failure
    self.email_alert(error)
  File "/opt/anaconda3/lib/python3.9/site-packages/airflow/models/taskinstance.py", line 2095, in email_alert
    send_email(self.task.email, subject, html_content_err)
  File "/opt/anaconda3/lib/python3.9/site-packages/airflow/utils/email.py", line 55, in send_email
    return backend(
  File "/opt/anaconda3/lib/python3.9/site-packages/airflow/utils/email.py", line 102, in send_email_smtp
    send_mime_email(e_from=smtp_mail_from, e_to=recipients, mime_msg=msg, conn_id=conn_id, dryrun=dryrun)
  File "/opt/anaconda3/lib/python3.9/site-packages/airflow/utils/email.py", line 210, in send_mime_email
    conn = _get_smtp_connection(smtp_host, smtp_port, smtp_timeout, smtp_ssl)
  File "/opt/anaconda3/lib/python3.9/site-packages/airflow/utils/email.py", line 244, in _get_smtp_connection
    else smtplib.SMTP(host=host, port=port, timeout=timeout)
  File "/opt/anaconda3/lib/python3.9/smtplib.py", line 255, in __init__
    (code, msg) = self.connect(host, port)
  File "/opt/anaconda3/lib/python3.9/smtplib.py", line 341, in connect
    self.sock = self._get_socket(host, port, self.timeout)
  File "/opt/anaconda3/lib/python3.9/smtplib.py", line 312, in _get_socket
    return socket.create_connection((host, port), timeout,
  File "/opt/anaconda3/lib/python3.9/socket.py", line 844, in create_connection
    raise err
  File "/opt/anaconda3/lib/python3.9/socket.py", line 832, in create_connection
    sock.connect(sa)
ConnectionRefusedError: [Errno 61] Connection refused
[2022-08-28 15:50:41,774] {standard_task_runner.py:89} ERROR - Failed to execute job 459 for task Transform
Traceback (most recent call last):
  File "/opt/anaconda3/lib/python3.9/site-packages/airflow/task/task_runner/standard_task_runner.py", line 85, in _start_by_fork
    args.func(args, dag=self.dag)
  File "/opt/anaconda3/lib/python3.9/site-packages/airflow/cli/cli_parser.py", line 48, in command
    return func(*args, **kwargs)
  File "/opt/anaconda3/lib/python3.9/site-packages/airflow/utils/cli.py", line 92, in wrapper
    return f(*args, **kwargs)
  File "/opt/anaconda3/lib/python3.9/site-packages/airflow/cli/commands/task_command.py", line 298, in task_run
    _run_task_by_selected_method(args, dag, ti)
  File "/opt/anaconda3/lib/python3.9/site-packages/airflow/cli/commands/task_command.py", line 107, in _run_task_by_selected_method
    _run_raw_task(args, ti)
  File "/opt/anaconda3/lib/python3.9/site-packages/airflow/cli/commands/task_command.py", line 180, in _run_raw_task
    ti._run_raw_task(
  File "/opt/anaconda3/lib/python3.9/site-packages/airflow/utils/session.py", line 70, in wrapper
    return func(*args, session=session, **kwargs)
  File "/opt/anaconda3/lib/python3.9/site-packages/airflow/models/taskinstance.py", line 1329, in _run_raw_task
    self._execute_task_with_callbacks(context)
  File "/opt/anaconda3/lib/python3.9/site-packages/airflow/models/taskinstance.py", line 1455, in _execute_task_with_callbacks
    result = self._execute_task(context, self.task)
  File "/opt/anaconda3/lib/python3.9/site-packages/airflow/models/taskinstance.py", line 1511, in _execute_task
    result = execute_callable(context=context)
  File "/opt/anaconda3/lib/python3.9/site-packages/airflow/operators/python.py", line 174, in execute
    return_value = self.execute_callable()
  File "/opt/anaconda3/lib/python3.9/site-packages/airflow/operators/python.py", line 185, in execute_callable
    return self.python_callable(*self.op_args, **self.op_kwargs)
TypeError: crime_stats_transformation() missing 1 required positional argument: 'filter_df'
[2022-08-28 15:50:41,788] {local_task_job.py:154} INFO - Task exited with return code 1
[2022-08-28 15:50:41,800] {local_task_job.py:264} INFO - 0 downstream tasks scheduled from follow-on schedule check
