[2022-08-28 15:25:45,664] {taskinstance.py:1032} INFO - Dependencies all met for <TaskInstance: ETL_Examples.Transform scheduled__2022-08-28T02:40:00+00:00 [queued]>
[2022-08-28 15:25:45,667] {taskinstance.py:1032} INFO - Dependencies all met for <TaskInstance: ETL_Examples.Transform scheduled__2022-08-28T02:40:00+00:00 [queued]>
[2022-08-28 15:25:45,667] {taskinstance.py:1238} INFO - 
--------------------------------------------------------------------------------
[2022-08-28 15:25:45,667] {taskinstance.py:1239} INFO - Starting attempt 1 of 2
[2022-08-28 15:25:45,667] {taskinstance.py:1240} INFO - 
--------------------------------------------------------------------------------
[2022-08-28 15:25:45,671] {taskinstance.py:1259} INFO - Executing <Task(PythonOperator): Transform> on 2022-08-28 02:40:00+00:00
[2022-08-28 15:25:45,678] {standard_task_runner.py:52} INFO - Started process 30390 to run task
[2022-08-28 15:25:45,682] {standard_task_runner.py:76} INFO - Running: ['airflow', 'tasks', 'run', 'ETL_Examples', 'Transform', 'scheduled__2022-08-28T02:40:00+00:00', '--job-id', '367', '--raw', '--subdir', 'DAGS_FOLDER/Pushtobigquery2.py', '--cfg-path', '/var/folders/35/pzst1sv14yld_nkt23lk_vmr0000gn/T/tmptud7qvq7', '--error-file', '/var/folders/35/pzst1sv14yld_nkt23lk_vmr0000gn/T/tmpko6savtv']
[2022-08-28 15:25:45,684] {standard_task_runner.py:77} INFO - Job 367: Subtask Transform
[2022-08-28 15:25:45,705] {logging_mixin.py:109} INFO - Running <TaskInstance: ETL_Examples.Transform scheduled__2022-08-28T02:40:00+00:00 [running]> on host 1.0.0.127.in-addr.arpa
[2022-08-28 15:25:45,727] {taskinstance.py:1424} INFO - Exporting the following env vars:
AIRFLOW_CTX_DAG_EMAIL=jonathan.dejesus.azor@gmail.com
AIRFLOW_CTX_DAG_OWNER=admin
AIRFLOW_CTX_DAG_ID=ETL_Examples
AIRFLOW_CTX_TASK_ID=Transform
AIRFLOW_CTX_EXECUTION_DATE=2022-08-28T02:40:00+00:00
AIRFLOW_CTX_DAG_RUN_ID=scheduled__2022-08-28T02:40:00+00:00
[2022-08-28 15:25:45,727] {taskinstance.py:1700} ERROR - Task failed with exception
Traceback (most recent call last):
  File "/opt/anaconda3/lib/python3.9/site-packages/airflow/models/taskinstance.py", line 1329, in _run_raw_task
    self._execute_task_with_callbacks(context)
  File "/opt/anaconda3/lib/python3.9/site-packages/airflow/models/taskinstance.py", line 1455, in _execute_task_with_callbacks
    result = self._execute_task(context, self.task)
  File "/opt/anaconda3/lib/python3.9/site-packages/airflow/models/taskinstance.py", line 1511, in _execute_task
    result = execute_callable(context=context)
  File "/opt/anaconda3/lib/python3.9/site-packages/airflow/operators/python.py", line 174, in execute
    return_value = self.execute_callable()
  File "/opt/anaconda3/lib/python3.9/site-packages/airflow/operators/python.py", line 185, in execute_callable
    return self.python_callable(*self.op_args, **self.op_kwargs)
TypeError: crime_stats_transformation() missing 1 required positional argument: 'filter_df'
[2022-08-28 15:25:45,732] {taskinstance.py:1267} INFO - Marking task as UP_FOR_RETRY. dag_id=ETL_Examples, task_id=Transform, execution_date=20220828T024000, start_date=20220828T202545, end_date=20220828T202545
[2022-08-28 15:25:45,738] {logging_mixin.py:109} WARNING - /opt/anaconda3/lib/python3.9/site-packages/airflow/utils/context.py:152 AirflowContextDeprecationWarning: Accessing 'execution_date' from the template is deprecated and will be removed in a future version. Please use 'data_interval_start' or 'logical_date' instead.
[2022-08-28 15:25:45,739] {logging_mixin.py:109} WARNING - /opt/anaconda3/lib/python3.9/site-packages/airflow/utils/context.py:152 AirflowContextDeprecationWarning: Accessing 'next_ds' from the template is deprecated and will be removed in a future version. Please use '{{ data_interval_end | ds }}' instead.
[2022-08-28 15:25:45,739] {logging_mixin.py:109} WARNING - /opt/anaconda3/lib/python3.9/site-packages/airflow/utils/context.py:152 AirflowContextDeprecationWarning: Accessing 'next_ds_nodash' from the template is deprecated and will be removed in a future version. Please use '{{ data_interval_end | ds_nodash }}' instead.
[2022-08-28 15:25:45,740] {logging_mixin.py:109} WARNING - /opt/anaconda3/lib/python3.9/site-packages/airflow/utils/context.py:152 AirflowContextDeprecationWarning: Accessing 'next_execution_date' from the template is deprecated and will be removed in a future version. Please use 'data_interval_end' instead.
[2022-08-28 15:25:45,740] {logging_mixin.py:109} WARNING - /opt/anaconda3/lib/python3.9/site-packages/airflow/utils/context.py:152 AirflowContextDeprecationWarning: Accessing 'prev_ds' from the template is deprecated and will be removed in a future version.
[2022-08-28 15:25:45,741] {logging_mixin.py:109} WARNING - /opt/anaconda3/lib/python3.9/site-packages/airflow/utils/context.py:152 AirflowContextDeprecationWarning: Accessing 'prev_ds_nodash' from the template is deprecated and will be removed in a future version.
[2022-08-28 15:25:45,741] {logging_mixin.py:109} WARNING - /opt/anaconda3/lib/python3.9/site-packages/airflow/utils/context.py:152 AirflowContextDeprecationWarning: Accessing 'prev_execution_date' from the template is deprecated and will be removed in a future version.
[2022-08-28 15:25:45,742] {logging_mixin.py:109} WARNING - /opt/anaconda3/lib/python3.9/site-packages/airflow/utils/context.py:152 AirflowContextDeprecationWarning: Accessing 'prev_execution_date_success' from the template is deprecated and will be removed in a future version. Please use 'prev_data_interval_start_success' instead.
[2022-08-28 15:25:45,743] {logging_mixin.py:109} WARNING - /opt/anaconda3/lib/python3.9/site-packages/airflow/utils/context.py:152 AirflowContextDeprecationWarning: Accessing 'tomorrow_ds' from the template is deprecated and will be removed in a future version.
[2022-08-28 15:25:45,743] {logging_mixin.py:109} WARNING - /opt/anaconda3/lib/python3.9/site-packages/airflow/utils/context.py:152 AirflowContextDeprecationWarning: Accessing 'tomorrow_ds_nodash' from the template is deprecated and will be removed in a future version.
[2022-08-28 15:25:45,744] {logging_mixin.py:109} WARNING - /opt/anaconda3/lib/python3.9/site-packages/airflow/utils/context.py:152 AirflowContextDeprecationWarning: Accessing 'yesterday_ds' from the template is deprecated and will be removed in a future version.
[2022-08-28 15:25:45,744] {logging_mixin.py:109} WARNING - /opt/anaconda3/lib/python3.9/site-packages/airflow/utils/context.py:152 AirflowContextDeprecationWarning: Accessing 'yesterday_ds_nodash' from the template is deprecated and will be removed in a future version.
[2022-08-28 15:25:45,750] {logging_mixin.py:109} WARNING - /opt/anaconda3/lib/python3.9/site-packages/airflow/utils/email.py:102 PendingDeprecationWarning: Fetching SMTP credentials from configuration variables will be deprecated in a future release. Please set credentials using a connection instead.
[2022-08-28 15:25:45,750] {configuration.py:381} WARNING - section/key [smtp/smtp_user] not found in config
[2022-08-28 15:25:45,750] {email.py:208} INFO - Email alerting: attempt 1
[2022-08-28 15:25:45,753] {configuration.py:381} WARNING - section/key [smtp/smtp_user] not found in config
[2022-08-28 15:25:45,753] {email.py:208} INFO - Email alerting: attempt 1
[2022-08-28 15:25:45,755] {taskinstance.py:1751} ERROR - Failed to send email to: jonathan.dejesus.azor@gmail.com
Traceback (most recent call last):
  File "/opt/anaconda3/lib/python3.9/site-packages/airflow/models/taskinstance.py", line 1329, in _run_raw_task
    self._execute_task_with_callbacks(context)
  File "/opt/anaconda3/lib/python3.9/site-packages/airflow/models/taskinstance.py", line 1455, in _execute_task_with_callbacks
    result = self._execute_task(context, self.task)
  File "/opt/anaconda3/lib/python3.9/site-packages/airflow/models/taskinstance.py", line 1511, in _execute_task
    result = execute_callable(context=context)
  File "/opt/anaconda3/lib/python3.9/site-packages/airflow/operators/python.py", line 174, in execute
    return_value = self.execute_callable()
  File "/opt/anaconda3/lib/python3.9/site-packages/airflow/operators/python.py", line 185, in execute_callable
    return self.python_callable(*self.op_args, **self.op_kwargs)
TypeError: crime_stats_transformation() missing 1 required positional argument: 'filter_df'

During handling of the above exception, another exception occurred:

Traceback (most recent call last):
  File "/opt/anaconda3/lib/python3.9/site-packages/airflow/models/taskinstance.py", line 2093, in email_alert
    send_email(self.task.email, subject, html_content)
  File "/opt/anaconda3/lib/python3.9/site-packages/airflow/utils/email.py", line 55, in send_email
    return backend(
  File "/opt/anaconda3/lib/python3.9/site-packages/airflow/utils/email.py", line 102, in send_email_smtp
    send_mime_email(e_from=smtp_mail_from, e_to=recipients, mime_msg=msg, conn_id=conn_id, dryrun=dryrun)
  File "/opt/anaconda3/lib/python3.9/site-packages/airflow/utils/email.py", line 210, in send_mime_email
    conn = _get_smtp_connection(smtp_host, smtp_port, smtp_timeout, smtp_ssl)
  File "/opt/anaconda3/lib/python3.9/site-packages/airflow/utils/email.py", line 244, in _get_smtp_connection
    else smtplib.SMTP(host=host, port=port, timeout=timeout)
  File "/opt/anaconda3/lib/python3.9/smtplib.py", line 255, in __init__
    (code, msg) = self.connect(host, port)
  File "/opt/anaconda3/lib/python3.9/smtplib.py", line 341, in connect
    self.sock = self._get_socket(host, port, self.timeout)
  File "/opt/anaconda3/lib/python3.9/smtplib.py", line 312, in _get_socket
    return socket.create_connection((host, port), timeout,
  File "/opt/anaconda3/lib/python3.9/socket.py", line 844, in create_connection
    raise err
  File "/opt/anaconda3/lib/python3.9/socket.py", line 832, in create_connection
    sock.connect(sa)
ConnectionRefusedError: [Errno 61] Connection refused

During handling of the above exception, another exception occurred:

Traceback (most recent call last):
  File "/opt/anaconda3/lib/python3.9/site-packages/airflow/models/taskinstance.py", line 1749, in handle_failure
    self.email_alert(error)
  File "/opt/anaconda3/lib/python3.9/site-packages/airflow/models/taskinstance.py", line 2095, in email_alert
    send_email(self.task.email, subject, html_content_err)
  File "/opt/anaconda3/lib/python3.9/site-packages/airflow/utils/email.py", line 55, in send_email
    return backend(
  File "/opt/anaconda3/lib/python3.9/site-packages/airflow/utils/email.py", line 102, in send_email_smtp
    send_mime_email(e_from=smtp_mail_from, e_to=recipients, mime_msg=msg, conn_id=conn_id, dryrun=dryrun)
  File "/opt/anaconda3/lib/python3.9/site-packages/airflow/utils/email.py", line 210, in send_mime_email
    conn = _get_smtp_connection(smtp_host, smtp_port, smtp_timeout, smtp_ssl)
  File "/opt/anaconda3/lib/python3.9/site-packages/airflow/utils/email.py", line 244, in _get_smtp_connection
    else smtplib.SMTP(host=host, port=port, timeout=timeout)
  File "/opt/anaconda3/lib/python3.9/smtplib.py", line 255, in __init__
    (code, msg) = self.connect(host, port)
  File "/opt/anaconda3/lib/python3.9/smtplib.py", line 341, in connect
    self.sock = self._get_socket(host, port, self.timeout)
  File "/opt/anaconda3/lib/python3.9/smtplib.py", line 312, in _get_socket
    return socket.create_connection((host, port), timeout,
  File "/opt/anaconda3/lib/python3.9/socket.py", line 844, in create_connection
    raise err
  File "/opt/anaconda3/lib/python3.9/socket.py", line 832, in create_connection
    sock.connect(sa)
ConnectionRefusedError: [Errno 61] Connection refused
[2022-08-28 15:25:45,760] {standard_task_runner.py:89} ERROR - Failed to execute job 367 for task Transform
Traceback (most recent call last):
  File "/opt/anaconda3/lib/python3.9/site-packages/airflow/task/task_runner/standard_task_runner.py", line 85, in _start_by_fork
    args.func(args, dag=self.dag)
  File "/opt/anaconda3/lib/python3.9/site-packages/airflow/cli/cli_parser.py", line 48, in command
    return func(*args, **kwargs)
  File "/opt/anaconda3/lib/python3.9/site-packages/airflow/utils/cli.py", line 92, in wrapper
    return f(*args, **kwargs)
  File "/opt/anaconda3/lib/python3.9/site-packages/airflow/cli/commands/task_command.py", line 298, in task_run
    _run_task_by_selected_method(args, dag, ti)
  File "/opt/anaconda3/lib/python3.9/site-packages/airflow/cli/commands/task_command.py", line 107, in _run_task_by_selected_method
    _run_raw_task(args, ti)
  File "/opt/anaconda3/lib/python3.9/site-packages/airflow/cli/commands/task_command.py", line 180, in _run_raw_task
    ti._run_raw_task(
  File "/opt/anaconda3/lib/python3.9/site-packages/airflow/utils/session.py", line 70, in wrapper
    return func(*args, session=session, **kwargs)
  File "/opt/anaconda3/lib/python3.9/site-packages/airflow/models/taskinstance.py", line 1329, in _run_raw_task
    self._execute_task_with_callbacks(context)
  File "/opt/anaconda3/lib/python3.9/site-packages/airflow/models/taskinstance.py", line 1455, in _execute_task_with_callbacks
    result = self._execute_task(context, self.task)
  File "/opt/anaconda3/lib/python3.9/site-packages/airflow/models/taskinstance.py", line 1511, in _execute_task
    result = execute_callable(context=context)
  File "/opt/anaconda3/lib/python3.9/site-packages/airflow/operators/python.py", line 174, in execute
    return_value = self.execute_callable()
  File "/opt/anaconda3/lib/python3.9/site-packages/airflow/operators/python.py", line 185, in execute_callable
    return self.python_callable(*self.op_args, **self.op_kwargs)
TypeError: crime_stats_transformation() missing 1 required positional argument: 'filter_df'
[2022-08-28 15:25:45,789] {local_task_job.py:154} INFO - Task exited with return code 1
[2022-08-28 15:25:45,801] {local_task_job.py:264} INFO - 0 downstream tasks scheduled from follow-on schedule check
[2022-08-28 15:49:16,743] {taskinstance.py:1032} INFO - Dependencies all met for <TaskInstance: ETL_Examples.Transform scheduled__2022-08-28T02:40:00+00:00 [queued]>
[2022-08-28 15:49:16,746] {taskinstance.py:1032} INFO - Dependencies all met for <TaskInstance: ETL_Examples.Transform scheduled__2022-08-28T02:40:00+00:00 [queued]>
[2022-08-28 15:49:16,746] {taskinstance.py:1238} INFO - 
--------------------------------------------------------------------------------
[2022-08-28 15:49:16,746] {taskinstance.py:1239} INFO - Starting attempt 1 of 2
[2022-08-28 15:49:16,746] {taskinstance.py:1240} INFO - 
--------------------------------------------------------------------------------
[2022-08-28 15:49:16,751] {taskinstance.py:1259} INFO - Executing <Task(PythonOperator): Transform> on 2022-08-28 02:40:00+00:00
[2022-08-28 15:49:16,757] {standard_task_runner.py:52} INFO - Started process 31107 to run task
[2022-08-28 15:49:16,761] {standard_task_runner.py:76} INFO - Running: ['airflow', 'tasks', 'run', 'ETL_Examples', 'Transform', 'scheduled__2022-08-28T02:40:00+00:00', '--job-id', '441', '--raw', '--subdir', 'DAGS_FOLDER/Pushtobigquery2.py', '--cfg-path', '/var/folders/35/pzst1sv14yld_nkt23lk_vmr0000gn/T/tmpdk738cx_', '--error-file', '/var/folders/35/pzst1sv14yld_nkt23lk_vmr0000gn/T/tmpgk1rwi14']
[2022-08-28 15:49:16,762] {standard_task_runner.py:77} INFO - Job 441: Subtask Transform
[2022-08-28 15:49:16,784] {logging_mixin.py:109} INFO - Running <TaskInstance: ETL_Examples.Transform scheduled__2022-08-28T02:40:00+00:00 [running]> on host 1.0.0.127.in-addr.arpa
[2022-08-28 15:49:16,804] {taskinstance.py:1424} INFO - Exporting the following env vars:
AIRFLOW_CTX_DAG_EMAIL=jonathan.dejesus.azor@gmail.com
AIRFLOW_CTX_DAG_OWNER=admin
AIRFLOW_CTX_DAG_ID=ETL_Examples
AIRFLOW_CTX_TASK_ID=Transform
AIRFLOW_CTX_EXECUTION_DATE=2022-08-28T02:40:00+00:00
AIRFLOW_CTX_DAG_RUN_ID=scheduled__2022-08-28T02:40:00+00:00
[2022-08-28 15:49:16,804] {taskinstance.py:1700} ERROR - Task failed with exception
Traceback (most recent call last):
  File "/opt/anaconda3/lib/python3.9/site-packages/airflow/models/taskinstance.py", line 1329, in _run_raw_task
    self._execute_task_with_callbacks(context)
  File "/opt/anaconda3/lib/python3.9/site-packages/airflow/models/taskinstance.py", line 1455, in _execute_task_with_callbacks
    result = self._execute_task(context, self.task)
  File "/opt/anaconda3/lib/python3.9/site-packages/airflow/models/taskinstance.py", line 1511, in _execute_task
    result = execute_callable(context=context)
  File "/opt/anaconda3/lib/python3.9/site-packages/airflow/operators/python.py", line 174, in execute
    return_value = self.execute_callable()
  File "/opt/anaconda3/lib/python3.9/site-packages/airflow/operators/python.py", line 185, in execute_callable
    return self.python_callable(*self.op_args, **self.op_kwargs)
TypeError: crime_stats_transformation() missing 1 required positional argument: 'filter_df'
[2022-08-28 15:49:16,809] {taskinstance.py:1267} INFO - Marking task as UP_FOR_RETRY. dag_id=ETL_Examples, task_id=Transform, execution_date=20220828T024000, start_date=20220828T204916, end_date=20220828T204916
[2022-08-28 15:49:16,815] {logging_mixin.py:109} WARNING - /opt/anaconda3/lib/python3.9/site-packages/airflow/utils/context.py:152 AirflowContextDeprecationWarning: Accessing 'execution_date' from the template is deprecated and will be removed in a future version. Please use 'data_interval_start' or 'logical_date' instead.
[2022-08-28 15:49:16,815] {logging_mixin.py:109} WARNING - /opt/anaconda3/lib/python3.9/site-packages/airflow/utils/context.py:152 AirflowContextDeprecationWarning: Accessing 'next_ds' from the template is deprecated and will be removed in a future version. Please use '{{ data_interval_end | ds }}' instead.
[2022-08-28 15:49:16,816] {logging_mixin.py:109} WARNING - /opt/anaconda3/lib/python3.9/site-packages/airflow/utils/context.py:152 AirflowContextDeprecationWarning: Accessing 'next_ds_nodash' from the template is deprecated and will be removed in a future version. Please use '{{ data_interval_end | ds_nodash }}' instead.
[2022-08-28 15:49:16,816] {logging_mixin.py:109} WARNING - /opt/anaconda3/lib/python3.9/site-packages/airflow/utils/context.py:152 AirflowContextDeprecationWarning: Accessing 'next_execution_date' from the template is deprecated and will be removed in a future version. Please use 'data_interval_end' instead.
[2022-08-28 15:49:16,817] {logging_mixin.py:109} WARNING - /opt/anaconda3/lib/python3.9/site-packages/airflow/utils/context.py:152 AirflowContextDeprecationWarning: Accessing 'prev_ds' from the template is deprecated and will be removed in a future version.
[2022-08-28 15:49:16,817] {logging_mixin.py:109} WARNING - /opt/anaconda3/lib/python3.9/site-packages/airflow/utils/context.py:152 AirflowContextDeprecationWarning: Accessing 'prev_ds_nodash' from the template is deprecated and will be removed in a future version.
[2022-08-28 15:49:16,818] {logging_mixin.py:109} WARNING - /opt/anaconda3/lib/python3.9/site-packages/airflow/utils/context.py:152 AirflowContextDeprecationWarning: Accessing 'prev_execution_date' from the template is deprecated and will be removed in a future version.
[2022-08-28 15:49:16,818] {logging_mixin.py:109} WARNING - /opt/anaconda3/lib/python3.9/site-packages/airflow/utils/context.py:152 AirflowContextDeprecationWarning: Accessing 'prev_execution_date_success' from the template is deprecated and will be removed in a future version. Please use 'prev_data_interval_start_success' instead.
[2022-08-28 15:49:16,819] {logging_mixin.py:109} WARNING - /opt/anaconda3/lib/python3.9/site-packages/airflow/utils/context.py:152 AirflowContextDeprecationWarning: Accessing 'tomorrow_ds' from the template is deprecated and will be removed in a future version.
[2022-08-28 15:49:16,819] {logging_mixin.py:109} WARNING - /opt/anaconda3/lib/python3.9/site-packages/airflow/utils/context.py:152 AirflowContextDeprecationWarning: Accessing 'tomorrow_ds_nodash' from the template is deprecated and will be removed in a future version.
[2022-08-28 15:49:16,820] {logging_mixin.py:109} WARNING - /opt/anaconda3/lib/python3.9/site-packages/airflow/utils/context.py:152 AirflowContextDeprecationWarning: Accessing 'yesterday_ds' from the template is deprecated and will be removed in a future version.
[2022-08-28 15:49:16,820] {logging_mixin.py:109} WARNING - /opt/anaconda3/lib/python3.9/site-packages/airflow/utils/context.py:152 AirflowContextDeprecationWarning: Accessing 'yesterday_ds_nodash' from the template is deprecated and will be removed in a future version.
[2022-08-28 15:49:16,826] {logging_mixin.py:109} WARNING - /opt/anaconda3/lib/python3.9/site-packages/airflow/utils/email.py:102 PendingDeprecationWarning: Fetching SMTP credentials from configuration variables will be deprecated in a future release. Please set credentials using a connection instead.
[2022-08-28 15:49:16,826] {configuration.py:381} WARNING - section/key [smtp/smtp_user] not found in config
[2022-08-28 15:49:16,827] {email.py:208} INFO - Email alerting: attempt 1
[2022-08-28 15:49:16,829] {configuration.py:381} WARNING - section/key [smtp/smtp_user] not found in config
[2022-08-28 15:49:16,829] {email.py:208} INFO - Email alerting: attempt 1
[2022-08-28 15:49:16,830] {taskinstance.py:1751} ERROR - Failed to send email to: jonathan.dejesus.azor@gmail.com
Traceback (most recent call last):
  File "/opt/anaconda3/lib/python3.9/site-packages/airflow/models/taskinstance.py", line 1329, in _run_raw_task
    self._execute_task_with_callbacks(context)
  File "/opt/anaconda3/lib/python3.9/site-packages/airflow/models/taskinstance.py", line 1455, in _execute_task_with_callbacks
    result = self._execute_task(context, self.task)
  File "/opt/anaconda3/lib/python3.9/site-packages/airflow/models/taskinstance.py", line 1511, in _execute_task
    result = execute_callable(context=context)
  File "/opt/anaconda3/lib/python3.9/site-packages/airflow/operators/python.py", line 174, in execute
    return_value = self.execute_callable()
  File "/opt/anaconda3/lib/python3.9/site-packages/airflow/operators/python.py", line 185, in execute_callable
    return self.python_callable(*self.op_args, **self.op_kwargs)
TypeError: crime_stats_transformation() missing 1 required positional argument: 'filter_df'

During handling of the above exception, another exception occurred:

Traceback (most recent call last):
  File "/opt/anaconda3/lib/python3.9/site-packages/airflow/models/taskinstance.py", line 2093, in email_alert
    send_email(self.task.email, subject, html_content)
  File "/opt/anaconda3/lib/python3.9/site-packages/airflow/utils/email.py", line 55, in send_email
    return backend(
  File "/opt/anaconda3/lib/python3.9/site-packages/airflow/utils/email.py", line 102, in send_email_smtp
    send_mime_email(e_from=smtp_mail_from, e_to=recipients, mime_msg=msg, conn_id=conn_id, dryrun=dryrun)
  File "/opt/anaconda3/lib/python3.9/site-packages/airflow/utils/email.py", line 210, in send_mime_email
    conn = _get_smtp_connection(smtp_host, smtp_port, smtp_timeout, smtp_ssl)
  File "/opt/anaconda3/lib/python3.9/site-packages/airflow/utils/email.py", line 244, in _get_smtp_connection
    else smtplib.SMTP(host=host, port=port, timeout=timeout)
  File "/opt/anaconda3/lib/python3.9/smtplib.py", line 255, in __init__
    (code, msg) = self.connect(host, port)
  File "/opt/anaconda3/lib/python3.9/smtplib.py", line 341, in connect
    self.sock = self._get_socket(host, port, self.timeout)
  File "/opt/anaconda3/lib/python3.9/smtplib.py", line 312, in _get_socket
    return socket.create_connection((host, port), timeout,
  File "/opt/anaconda3/lib/python3.9/socket.py", line 844, in create_connection
    raise err
  File "/opt/anaconda3/lib/python3.9/socket.py", line 832, in create_connection
    sock.connect(sa)
ConnectionRefusedError: [Errno 61] Connection refused

During handling of the above exception, another exception occurred:

Traceback (most recent call last):
  File "/opt/anaconda3/lib/python3.9/site-packages/airflow/models/taskinstance.py", line 1749, in handle_failure
    self.email_alert(error)
  File "/opt/anaconda3/lib/python3.9/site-packages/airflow/models/taskinstance.py", line 2095, in email_alert
    send_email(self.task.email, subject, html_content_err)
  File "/opt/anaconda3/lib/python3.9/site-packages/airflow/utils/email.py", line 55, in send_email
    return backend(
  File "/opt/anaconda3/lib/python3.9/site-packages/airflow/utils/email.py", line 102, in send_email_smtp
    send_mime_email(e_from=smtp_mail_from, e_to=recipients, mime_msg=msg, conn_id=conn_id, dryrun=dryrun)
  File "/opt/anaconda3/lib/python3.9/site-packages/airflow/utils/email.py", line 210, in send_mime_email
    conn = _get_smtp_connection(smtp_host, smtp_port, smtp_timeout, smtp_ssl)
  File "/opt/anaconda3/lib/python3.9/site-packages/airflow/utils/email.py", line 244, in _get_smtp_connection
    else smtplib.SMTP(host=host, port=port, timeout=timeout)
  File "/opt/anaconda3/lib/python3.9/smtplib.py", line 255, in __init__
    (code, msg) = self.connect(host, port)
  File "/opt/anaconda3/lib/python3.9/smtplib.py", line 341, in connect
    self.sock = self._get_socket(host, port, self.timeout)
  File "/opt/anaconda3/lib/python3.9/smtplib.py", line 312, in _get_socket
    return socket.create_connection((host, port), timeout,
  File "/opt/anaconda3/lib/python3.9/socket.py", line 844, in create_connection
    raise err
  File "/opt/anaconda3/lib/python3.9/socket.py", line 832, in create_connection
    sock.connect(sa)
ConnectionRefusedError: [Errno 61] Connection refused
[2022-08-28 15:49:16,835] {standard_task_runner.py:89} ERROR - Failed to execute job 441 for task Transform
Traceback (most recent call last):
  File "/opt/anaconda3/lib/python3.9/site-packages/airflow/task/task_runner/standard_task_runner.py", line 85, in _start_by_fork
    args.func(args, dag=self.dag)
  File "/opt/anaconda3/lib/python3.9/site-packages/airflow/cli/cli_parser.py", line 48, in command
    return func(*args, **kwargs)
  File "/opt/anaconda3/lib/python3.9/site-packages/airflow/utils/cli.py", line 92, in wrapper
    return f(*args, **kwargs)
  File "/opt/anaconda3/lib/python3.9/site-packages/airflow/cli/commands/task_command.py", line 298, in task_run
    _run_task_by_selected_method(args, dag, ti)
  File "/opt/anaconda3/lib/python3.9/site-packages/airflow/cli/commands/task_command.py", line 107, in _run_task_by_selected_method
    _run_raw_task(args, ti)
  File "/opt/anaconda3/lib/python3.9/site-packages/airflow/cli/commands/task_command.py", line 180, in _run_raw_task
    ti._run_raw_task(
  File "/opt/anaconda3/lib/python3.9/site-packages/airflow/utils/session.py", line 70, in wrapper
    return func(*args, session=session, **kwargs)
  File "/opt/anaconda3/lib/python3.9/site-packages/airflow/models/taskinstance.py", line 1329, in _run_raw_task
    self._execute_task_with_callbacks(context)
  File "/opt/anaconda3/lib/python3.9/site-packages/airflow/models/taskinstance.py", line 1455, in _execute_task_with_callbacks
    result = self._execute_task(context, self.task)
  File "/opt/anaconda3/lib/python3.9/site-packages/airflow/models/taskinstance.py", line 1511, in _execute_task
    result = execute_callable(context=context)
  File "/opt/anaconda3/lib/python3.9/site-packages/airflow/operators/python.py", line 174, in execute
    return_value = self.execute_callable()
  File "/opt/anaconda3/lib/python3.9/site-packages/airflow/operators/python.py", line 185, in execute_callable
    return self.python_callable(*self.op_args, **self.op_kwargs)
TypeError: crime_stats_transformation() missing 1 required positional argument: 'filter_df'
[2022-08-28 15:49:16,863] {local_task_job.py:154} INFO - Task exited with return code 1
[2022-08-28 15:49:16,874] {local_task_job.py:264} INFO - 0 downstream tasks scheduled from follow-on schedule check
[2022-08-28 15:50:57,576] {taskinstance.py:1032} INFO - Dependencies all met for <TaskInstance: ETL_Examples.Transform scheduled__2022-08-28T02:40:00+00:00 [queued]>
[2022-08-28 15:50:57,580] {taskinstance.py:1032} INFO - Dependencies all met for <TaskInstance: ETL_Examples.Transform scheduled__2022-08-28T02:40:00+00:00 [queued]>
[2022-08-28 15:50:57,580] {taskinstance.py:1238} INFO - 
--------------------------------------------------------------------------------
[2022-08-28 15:50:57,580] {taskinstance.py:1239} INFO - Starting attempt 1 of 2
[2022-08-28 15:50:57,580] {taskinstance.py:1240} INFO - 
--------------------------------------------------------------------------------
[2022-08-28 15:50:57,584] {taskinstance.py:1259} INFO - Executing <Task(PythonOperator): Transform> on 2022-08-28 02:40:00+00:00
[2022-08-28 15:50:57,591] {standard_task_runner.py:52} INFO - Started process 31187 to run task
[2022-08-28 15:50:57,595] {standard_task_runner.py:76} INFO - Running: ['airflow', 'tasks', 'run', 'ETL_Examples', 'Transform', 'scheduled__2022-08-28T02:40:00+00:00', '--job-id', '465', '--raw', '--subdir', 'DAGS_FOLDER/Pushtobigquery2.py', '--cfg-path', '/var/folders/35/pzst1sv14yld_nkt23lk_vmr0000gn/T/tmp_8x3ymz6', '--error-file', '/var/folders/35/pzst1sv14yld_nkt23lk_vmr0000gn/T/tmp76y_o8z0']
[2022-08-28 15:50:57,596] {standard_task_runner.py:77} INFO - Job 465: Subtask Transform
[2022-08-28 15:50:57,619] {logging_mixin.py:109} INFO - Running <TaskInstance: ETL_Examples.Transform scheduled__2022-08-28T02:40:00+00:00 [running]> on host 1.0.0.127.in-addr.arpa
[2022-08-28 15:50:57,639] {taskinstance.py:1424} INFO - Exporting the following env vars:
AIRFLOW_CTX_DAG_EMAIL=jonathan.dejesus.azor@gmail.com
AIRFLOW_CTX_DAG_OWNER=admin
AIRFLOW_CTX_DAG_ID=ETL_Examples
AIRFLOW_CTX_TASK_ID=Transform
AIRFLOW_CTX_EXECUTION_DATE=2022-08-28T02:40:00+00:00
AIRFLOW_CTX_DAG_RUN_ID=scheduled__2022-08-28T02:40:00+00:00
[2022-08-28 15:50:57,640] {taskinstance.py:1700} ERROR - Task failed with exception
Traceback (most recent call last):
  File "/opt/anaconda3/lib/python3.9/site-packages/airflow/models/taskinstance.py", line 1329, in _run_raw_task
    self._execute_task_with_callbacks(context)
  File "/opt/anaconda3/lib/python3.9/site-packages/airflow/models/taskinstance.py", line 1455, in _execute_task_with_callbacks
    result = self._execute_task(context, self.task)
  File "/opt/anaconda3/lib/python3.9/site-packages/airflow/models/taskinstance.py", line 1511, in _execute_task
    result = execute_callable(context=context)
  File "/opt/anaconda3/lib/python3.9/site-packages/airflow/operators/python.py", line 174, in execute
    return_value = self.execute_callable()
  File "/opt/anaconda3/lib/python3.9/site-packages/airflow/operators/python.py", line 185, in execute_callable
    return self.python_callable(*self.op_args, **self.op_kwargs)
TypeError: crime_stats_transformation() missing 1 required positional argument: 'filter_df'
[2022-08-28 15:50:57,645] {taskinstance.py:1267} INFO - Marking task as UP_FOR_RETRY. dag_id=ETL_Examples, task_id=Transform, execution_date=20220828T024000, start_date=20220828T205057, end_date=20220828T205057
[2022-08-28 15:50:57,651] {logging_mixin.py:109} WARNING - /opt/anaconda3/lib/python3.9/site-packages/airflow/utils/context.py:152 AirflowContextDeprecationWarning: Accessing 'execution_date' from the template is deprecated and will be removed in a future version. Please use 'data_interval_start' or 'logical_date' instead.
[2022-08-28 15:50:57,652] {logging_mixin.py:109} WARNING - /opt/anaconda3/lib/python3.9/site-packages/airflow/utils/context.py:152 AirflowContextDeprecationWarning: Accessing 'next_ds' from the template is deprecated and will be removed in a future version. Please use '{{ data_interval_end | ds }}' instead.
[2022-08-28 15:50:57,653] {logging_mixin.py:109} WARNING - /opt/anaconda3/lib/python3.9/site-packages/airflow/utils/context.py:152 AirflowContextDeprecationWarning: Accessing 'next_ds_nodash' from the template is deprecated and will be removed in a future version. Please use '{{ data_interval_end | ds_nodash }}' instead.
[2022-08-28 15:50:57,653] {logging_mixin.py:109} WARNING - /opt/anaconda3/lib/python3.9/site-packages/airflow/utils/context.py:152 AirflowContextDeprecationWarning: Accessing 'next_execution_date' from the template is deprecated and will be removed in a future version. Please use 'data_interval_end' instead.
[2022-08-28 15:50:57,654] {logging_mixin.py:109} WARNING - /opt/anaconda3/lib/python3.9/site-packages/airflow/utils/context.py:152 AirflowContextDeprecationWarning: Accessing 'prev_ds' from the template is deprecated and will be removed in a future version.
[2022-08-28 15:50:57,654] {logging_mixin.py:109} WARNING - /opt/anaconda3/lib/python3.9/site-packages/airflow/utils/context.py:152 AirflowContextDeprecationWarning: Accessing 'prev_ds_nodash' from the template is deprecated and will be removed in a future version.
[2022-08-28 15:50:57,655] {logging_mixin.py:109} WARNING - /opt/anaconda3/lib/python3.9/site-packages/airflow/utils/context.py:152 AirflowContextDeprecationWarning: Accessing 'prev_execution_date' from the template is deprecated and will be removed in a future version.
[2022-08-28 15:50:57,655] {logging_mixin.py:109} WARNING - /opt/anaconda3/lib/python3.9/site-packages/airflow/utils/context.py:152 AirflowContextDeprecationWarning: Accessing 'prev_execution_date_success' from the template is deprecated and will be removed in a future version. Please use 'prev_data_interval_start_success' instead.
[2022-08-28 15:50:57,656] {logging_mixin.py:109} WARNING - /opt/anaconda3/lib/python3.9/site-packages/airflow/utils/context.py:152 AirflowContextDeprecationWarning: Accessing 'tomorrow_ds' from the template is deprecated and will be removed in a future version.
[2022-08-28 15:50:57,656] {logging_mixin.py:109} WARNING - /opt/anaconda3/lib/python3.9/site-packages/airflow/utils/context.py:152 AirflowContextDeprecationWarning: Accessing 'tomorrow_ds_nodash' from the template is deprecated and will be removed in a future version.
[2022-08-28 15:50:57,657] {logging_mixin.py:109} WARNING - /opt/anaconda3/lib/python3.9/site-packages/airflow/utils/context.py:152 AirflowContextDeprecationWarning: Accessing 'yesterday_ds' from the template is deprecated and will be removed in a future version.
[2022-08-28 15:50:57,657] {logging_mixin.py:109} WARNING - /opt/anaconda3/lib/python3.9/site-packages/airflow/utils/context.py:152 AirflowContextDeprecationWarning: Accessing 'yesterday_ds_nodash' from the template is deprecated and will be removed in a future version.
[2022-08-28 15:50:57,663] {logging_mixin.py:109} WARNING - /opt/anaconda3/lib/python3.9/site-packages/airflow/utils/email.py:102 PendingDeprecationWarning: Fetching SMTP credentials from configuration variables will be deprecated in a future release. Please set credentials using a connection instead.
[2022-08-28 15:50:57,663] {configuration.py:381} WARNING - section/key [smtp/smtp_user] not found in config
[2022-08-28 15:50:57,664] {email.py:208} INFO - Email alerting: attempt 1
[2022-08-28 15:50:57,666] {configuration.py:381} WARNING - section/key [smtp/smtp_user] not found in config
[2022-08-28 15:50:57,666] {email.py:208} INFO - Email alerting: attempt 1
[2022-08-28 15:50:57,667] {taskinstance.py:1751} ERROR - Failed to send email to: jonathan.dejesus.azor@gmail.com
Traceback (most recent call last):
  File "/opt/anaconda3/lib/python3.9/site-packages/airflow/models/taskinstance.py", line 1329, in _run_raw_task
    self._execute_task_with_callbacks(context)
  File "/opt/anaconda3/lib/python3.9/site-packages/airflow/models/taskinstance.py", line 1455, in _execute_task_with_callbacks
    result = self._execute_task(context, self.task)
  File "/opt/anaconda3/lib/python3.9/site-packages/airflow/models/taskinstance.py", line 1511, in _execute_task
    result = execute_callable(context=context)
  File "/opt/anaconda3/lib/python3.9/site-packages/airflow/operators/python.py", line 174, in execute
    return_value = self.execute_callable()
  File "/opt/anaconda3/lib/python3.9/site-packages/airflow/operators/python.py", line 185, in execute_callable
    return self.python_callable(*self.op_args, **self.op_kwargs)
TypeError: crime_stats_transformation() missing 1 required positional argument: 'filter_df'

During handling of the above exception, another exception occurred:

Traceback (most recent call last):
  File "/opt/anaconda3/lib/python3.9/site-packages/airflow/models/taskinstance.py", line 2093, in email_alert
    send_email(self.task.email, subject, html_content)
  File "/opt/anaconda3/lib/python3.9/site-packages/airflow/utils/email.py", line 55, in send_email
    return backend(
  File "/opt/anaconda3/lib/python3.9/site-packages/airflow/utils/email.py", line 102, in send_email_smtp
    send_mime_email(e_from=smtp_mail_from, e_to=recipients, mime_msg=msg, conn_id=conn_id, dryrun=dryrun)
  File "/opt/anaconda3/lib/python3.9/site-packages/airflow/utils/email.py", line 210, in send_mime_email
    conn = _get_smtp_connection(smtp_host, smtp_port, smtp_timeout, smtp_ssl)
  File "/opt/anaconda3/lib/python3.9/site-packages/airflow/utils/email.py", line 244, in _get_smtp_connection
    else smtplib.SMTP(host=host, port=port, timeout=timeout)
  File "/opt/anaconda3/lib/python3.9/smtplib.py", line 255, in __init__
    (code, msg) = self.connect(host, port)
  File "/opt/anaconda3/lib/python3.9/smtplib.py", line 341, in connect
    self.sock = self._get_socket(host, port, self.timeout)
  File "/opt/anaconda3/lib/python3.9/smtplib.py", line 312, in _get_socket
    return socket.create_connection((host, port), timeout,
  File "/opt/anaconda3/lib/python3.9/socket.py", line 844, in create_connection
    raise err
  File "/opt/anaconda3/lib/python3.9/socket.py", line 832, in create_connection
    sock.connect(sa)
ConnectionRefusedError: [Errno 61] Connection refused

During handling of the above exception, another exception occurred:

Traceback (most recent call last):
  File "/opt/anaconda3/lib/python3.9/site-packages/airflow/models/taskinstance.py", line 1749, in handle_failure
    self.email_alert(error)
  File "/opt/anaconda3/lib/python3.9/site-packages/airflow/models/taskinstance.py", line 2095, in email_alert
    send_email(self.task.email, subject, html_content_err)
  File "/opt/anaconda3/lib/python3.9/site-packages/airflow/utils/email.py", line 55, in send_email
    return backend(
  File "/opt/anaconda3/lib/python3.9/site-packages/airflow/utils/email.py", line 102, in send_email_smtp
    send_mime_email(e_from=smtp_mail_from, e_to=recipients, mime_msg=msg, conn_id=conn_id, dryrun=dryrun)
  File "/opt/anaconda3/lib/python3.9/site-packages/airflow/utils/email.py", line 210, in send_mime_email
    conn = _get_smtp_connection(smtp_host, smtp_port, smtp_timeout, smtp_ssl)
  File "/opt/anaconda3/lib/python3.9/site-packages/airflow/utils/email.py", line 244, in _get_smtp_connection
    else smtplib.SMTP(host=host, port=port, timeout=timeout)
  File "/opt/anaconda3/lib/python3.9/smtplib.py", line 255, in __init__
    (code, msg) = self.connect(host, port)
  File "/opt/anaconda3/lib/python3.9/smtplib.py", line 341, in connect
    self.sock = self._get_socket(host, port, self.timeout)
  File "/opt/anaconda3/lib/python3.9/smtplib.py", line 312, in _get_socket
    return socket.create_connection((host, port), timeout,
  File "/opt/anaconda3/lib/python3.9/socket.py", line 844, in create_connection
    raise err
  File "/opt/anaconda3/lib/python3.9/socket.py", line 832, in create_connection
    sock.connect(sa)
ConnectionRefusedError: [Errno 61] Connection refused
[2022-08-28 15:50:57,672] {standard_task_runner.py:89} ERROR - Failed to execute job 465 for task Transform
Traceback (most recent call last):
  File "/opt/anaconda3/lib/python3.9/site-packages/airflow/task/task_runner/standard_task_runner.py", line 85, in _start_by_fork
    args.func(args, dag=self.dag)
  File "/opt/anaconda3/lib/python3.9/site-packages/airflow/cli/cli_parser.py", line 48, in command
    return func(*args, **kwargs)
  File "/opt/anaconda3/lib/python3.9/site-packages/airflow/utils/cli.py", line 92, in wrapper
    return f(*args, **kwargs)
  File "/opt/anaconda3/lib/python3.9/site-packages/airflow/cli/commands/task_command.py", line 298, in task_run
    _run_task_by_selected_method(args, dag, ti)
  File "/opt/anaconda3/lib/python3.9/site-packages/airflow/cli/commands/task_command.py", line 107, in _run_task_by_selected_method
    _run_raw_task(args, ti)
  File "/opt/anaconda3/lib/python3.9/site-packages/airflow/cli/commands/task_command.py", line 180, in _run_raw_task
    ti._run_raw_task(
  File "/opt/anaconda3/lib/python3.9/site-packages/airflow/utils/session.py", line 70, in wrapper
    return func(*args, session=session, **kwargs)
  File "/opt/anaconda3/lib/python3.9/site-packages/airflow/models/taskinstance.py", line 1329, in _run_raw_task
    self._execute_task_with_callbacks(context)
  File "/opt/anaconda3/lib/python3.9/site-packages/airflow/models/taskinstance.py", line 1455, in _execute_task_with_callbacks
    result = self._execute_task(context, self.task)
  File "/opt/anaconda3/lib/python3.9/site-packages/airflow/models/taskinstance.py", line 1511, in _execute_task
    result = execute_callable(context=context)
  File "/opt/anaconda3/lib/python3.9/site-packages/airflow/operators/python.py", line 174, in execute
    return_value = self.execute_callable()
  File "/opt/anaconda3/lib/python3.9/site-packages/airflow/operators/python.py", line 185, in execute_callable
    return self.python_callable(*self.op_args, **self.op_kwargs)
TypeError: crime_stats_transformation() missing 1 required positional argument: 'filter_df'
[2022-08-28 15:50:57,702] {local_task_job.py:154} INFO - Task exited with return code 1
[2022-08-28 15:50:57,713] {local_task_job.py:264} INFO - 0 downstream tasks scheduled from follow-on schedule check
