[2022-09-03 14:03:26,651] {taskinstance.py:1032} INFO - Dependencies all met for <TaskInstance: etl_airflow.date_formatting scheduled__2022-09-03T04:00:00+00:00 [queued]>
[2022-09-03 14:03:26,655] {taskinstance.py:1032} INFO - Dependencies all met for <TaskInstance: etl_airflow.date_formatting scheduled__2022-09-03T04:00:00+00:00 [queued]>
[2022-09-03 14:03:26,655] {taskinstance.py:1238} INFO - 
--------------------------------------------------------------------------------
[2022-09-03 14:03:26,655] {taskinstance.py:1239} INFO - Starting attempt 1 of 1
[2022-09-03 14:03:26,655] {taskinstance.py:1240} INFO - 
--------------------------------------------------------------------------------
[2022-09-03 14:03:26,659] {taskinstance.py:1259} INFO - Executing <Task(PythonOperator): date_formatting> on 2022-09-03 04:00:00+00:00
[2022-09-03 14:03:26,667] {standard_task_runner.py:52} INFO - Started process 41307 to run task
[2022-09-03 14:03:26,672] {standard_task_runner.py:76} INFO - Running: ['airflow', 'tasks', 'run', 'etl_airflow', 'date_formatting', 'scheduled__2022-09-03T04:00:00+00:00', '--job-id', '649', '--raw', '--subdir', 'DAGS_FOLDER/etl_airflowv2.py', '--cfg-path', '/var/folders/35/pzst1sv14yld_nkt23lk_vmr0000gn/T/tmpcgzraval', '--error-file', '/var/folders/35/pzst1sv14yld_nkt23lk_vmr0000gn/T/tmphfmzhgso']
[2022-09-03 14:03:26,673] {standard_task_runner.py:77} INFO - Job 649: Subtask date_formatting
[2022-09-03 14:03:26,702] {logging_mixin.py:109} INFO - Running <TaskInstance: etl_airflow.date_formatting scheduled__2022-09-03T04:00:00+00:00 [running]> on host 1.0.0.127.in-addr.arpa
[2022-09-03 14:03:26,737] {taskinstance.py:1424} INFO - Exporting the following env vars:
AIRFLOW_CTX_DAG_EMAIL=jonathan.dejesus.azor@gmail.com
AIRFLOW_CTX_DAG_OWNER=admin
AIRFLOW_CTX_DAG_ID=etl_airflow
AIRFLOW_CTX_TASK_ID=date_formatting
AIRFLOW_CTX_EXECUTION_DATE=2022-09-03T04:00:00+00:00
AIRFLOW_CTX_DAG_RUN_ID=scheduled__2022-09-03T04:00:00+00:00
[2022-09-03 14:03:29,953] {_metadata.py:99} WARNING - Compute Engine Metadata server unavailable on attempt 1 of 3. Reason: timed out
[2022-09-03 14:03:32,957] {_metadata.py:99} WARNING - Compute Engine Metadata server unavailable on attempt 2 of 3. Reason: timed out
[2022-09-03 14:03:32,959] {_metadata.py:99} WARNING - Compute Engine Metadata server unavailable on attempt 3 of 3. Reason: [Errno 64] Host is down
[2022-09-03 14:03:32,960] {_default.py:290} WARNING - Authentication failed using Compute Engine authentication due to unavailable metadata server.
[2022-09-03 14:03:33,866] {logging_mixin.py:109} WARNING - Downloading:   0%|          | 0/200 [00:00<?, ?rows/s]
[2022-09-03 14:03:34,106] {logging_mixin.py:109} WARNING - Downloading: 100%|##########| 200/200 [00:00<00:00, 837.70rows/s]
[2022-09-03 14:03:34,108] {logging_mixin.py:109} WARNING - Downloading: 100%|##########| 200/200 [00:00<00:00, 829.00rows/s]
[2022-09-03 14:03:34,109] {logging_mixin.py:109} WARNING - 
[2022-09-03 14:03:34,121] {logging_mixin.py:109} INFO - Staging table extraction successfully completed
[2022-09-03 14:03:34,131] {logging_mixin.py:109} INFO -      incident_report_number  ... rep_time
0               20222381575  ...     2129
1               20222381479  ...     1935
2               20222381858  ...     2337
3               20222381688  ...     2201
4               20222381348  ...     1830
..                      ...  ...      ...
195             20222390765  ...     1208
196             20222391622  ...        7
197             20222391707  ...       27
198             20222391682  ...       37
199             20222391561  ...       10

[200 rows x 9 columns]
[2022-09-03 14:03:34,132] {taskinstance.py:1700} ERROR - Task failed with exception
Traceback (most recent call last):
  File "/opt/anaconda3/lib/python3.9/site-packages/pandas/core/indexes/base.py", line 3621, in get_loc
    return self._engine.get_loc(casted_key)
  File "pandas/_libs/index.pyx", line 136, in pandas._libs.index.IndexEngine.get_loc
  File "pandas/_libs/index.pyx", line 163, in pandas._libs.index.IndexEngine.get_loc
  File "pandas/_libs/hashtable_class_helper.pxi", line 5198, in pandas._libs.hashtable.PyObjectHashTable.get_item
  File "pandas/_libs/hashtable_class_helper.pxi", line 5206, in pandas._libs.hashtable.PyObjectHashTable.get_item
KeyError: 'ocurred_time'

The above exception was the direct cause of the following exception:

Traceback (most recent call last):
  File "/opt/anaconda3/lib/python3.9/site-packages/airflow/models/taskinstance.py", line 1329, in _run_raw_task
    self._execute_task_with_callbacks(context)
  File "/opt/anaconda3/lib/python3.9/site-packages/airflow/models/taskinstance.py", line 1455, in _execute_task_with_callbacks
    result = self._execute_task(context, self.task)
  File "/opt/anaconda3/lib/python3.9/site-packages/airflow/models/taskinstance.py", line 1511, in _execute_task
    result = execute_callable(context=context)
  File "/opt/anaconda3/lib/python3.9/site-packages/airflow/operators/python.py", line 174, in execute
    return_value = self.execute_callable()
  File "/opt/anaconda3/lib/python3.9/site-packages/airflow/operators/python.py", line 185, in execute_callable
    return self.python_callable(*self.op_args, **self.op_kwargs)
  File "/Users/theonewiththelion/airflow/dags/etl_airflowv2.py", line 128, in transformation_date
    time = pd.to_datetime(df_transformed_austin_crime['ocurred_time'].astype(str).str.zfill(4), format='%H%M').dt.time
  File "/opt/anaconda3/lib/python3.9/site-packages/pandas/core/frame.py", line 3505, in __getitem__
    indexer = self.columns.get_loc(key)
  File "/opt/anaconda3/lib/python3.9/site-packages/pandas/core/indexes/base.py", line 3623, in get_loc
    raise KeyError(key) from err
KeyError: 'ocurred_time'
[2022-09-03 14:03:34,142] {taskinstance.py:1267} INFO - Marking task as FAILED. dag_id=etl_airflow, task_id=date_formatting, execution_date=20220903T040000, start_date=20220903T190326, end_date=20220903T190334
[2022-09-03 14:03:34,149] {logging_mixin.py:109} WARNING - /opt/anaconda3/lib/python3.9/site-packages/airflow/utils/context.py:152 AirflowContextDeprecationWarning: Accessing 'execution_date' from the template is deprecated and will be removed in a future version. Please use 'data_interval_start' or 'logical_date' instead.
[2022-09-03 14:03:34,150] {logging_mixin.py:109} WARNING - /opt/anaconda3/lib/python3.9/site-packages/airflow/utils/context.py:152 AirflowContextDeprecationWarning: Accessing 'next_ds' from the template is deprecated and will be removed in a future version. Please use '{{ data_interval_end | ds }}' instead.
[2022-09-03 14:03:34,151] {logging_mixin.py:109} WARNING - /opt/anaconda3/lib/python3.9/site-packages/airflow/utils/context.py:152 AirflowContextDeprecationWarning: Accessing 'next_ds_nodash' from the template is deprecated and will be removed in a future version. Please use '{{ data_interval_end | ds_nodash }}' instead.
[2022-09-03 14:03:34,152] {logging_mixin.py:109} WARNING - /opt/anaconda3/lib/python3.9/site-packages/airflow/utils/context.py:152 AirflowContextDeprecationWarning: Accessing 'next_execution_date' from the template is deprecated and will be removed in a future version. Please use 'data_interval_end' instead.
[2022-09-03 14:03:34,152] {logging_mixin.py:109} WARNING - /opt/anaconda3/lib/python3.9/site-packages/airflow/utils/context.py:152 AirflowContextDeprecationWarning: Accessing 'prev_ds' from the template is deprecated and will be removed in a future version.
[2022-09-03 14:03:34,152] {logging_mixin.py:109} WARNING - /opt/anaconda3/lib/python3.9/site-packages/airflow/utils/context.py:152 AirflowContextDeprecationWarning: Accessing 'prev_ds_nodash' from the template is deprecated and will be removed in a future version.
[2022-09-03 14:03:34,153] {logging_mixin.py:109} WARNING - /opt/anaconda3/lib/python3.9/site-packages/airflow/utils/context.py:152 AirflowContextDeprecationWarning: Accessing 'prev_execution_date' from the template is deprecated and will be removed in a future version.
[2022-09-03 14:03:34,153] {logging_mixin.py:109} WARNING - /opt/anaconda3/lib/python3.9/site-packages/airflow/utils/context.py:152 AirflowContextDeprecationWarning: Accessing 'prev_execution_date_success' from the template is deprecated and will be removed in a future version. Please use 'prev_data_interval_start_success' instead.
[2022-09-03 14:03:34,154] {logging_mixin.py:109} WARNING - /opt/anaconda3/lib/python3.9/site-packages/airflow/utils/context.py:152 AirflowContextDeprecationWarning: Accessing 'tomorrow_ds' from the template is deprecated and will be removed in a future version.
[2022-09-03 14:03:34,154] {logging_mixin.py:109} WARNING - /opt/anaconda3/lib/python3.9/site-packages/airflow/utils/context.py:152 AirflowContextDeprecationWarning: Accessing 'tomorrow_ds_nodash' from the template is deprecated and will be removed in a future version.
[2022-09-03 14:03:34,155] {logging_mixin.py:109} WARNING - /opt/anaconda3/lib/python3.9/site-packages/airflow/utils/context.py:152 AirflowContextDeprecationWarning: Accessing 'yesterday_ds' from the template is deprecated and will be removed in a future version.
[2022-09-03 14:03:34,155] {logging_mixin.py:109} WARNING - /opt/anaconda3/lib/python3.9/site-packages/airflow/utils/context.py:152 AirflowContextDeprecationWarning: Accessing 'yesterday_ds_nodash' from the template is deprecated and will be removed in a future version.
[2022-09-03 14:03:34,162] {logging_mixin.py:109} WARNING - /opt/anaconda3/lib/python3.9/site-packages/airflow/utils/email.py:102 PendingDeprecationWarning: Fetching SMTP credentials from configuration variables will be deprecated in a future release. Please set credentials using a connection instead.
[2022-09-03 14:03:34,162] {configuration.py:381} WARNING - section/key [smtp/smtp_user] not found in config
[2022-09-03 14:03:34,162] {email.py:208} INFO - Email alerting: attempt 1
[2022-09-03 14:03:34,166] {configuration.py:381} WARNING - section/key [smtp/smtp_user] not found in config
[2022-09-03 14:03:34,166] {email.py:208} INFO - Email alerting: attempt 1
[2022-09-03 14:03:34,167] {taskinstance.py:1751} ERROR - Failed to send email to: jonathan.dejesus.azor@gmail.com
Traceback (most recent call last):
  File "/opt/anaconda3/lib/python3.9/site-packages/pandas/core/indexes/base.py", line 3621, in get_loc
    return self._engine.get_loc(casted_key)
  File "pandas/_libs/index.pyx", line 136, in pandas._libs.index.IndexEngine.get_loc
  File "pandas/_libs/index.pyx", line 163, in pandas._libs.index.IndexEngine.get_loc
  File "pandas/_libs/hashtable_class_helper.pxi", line 5198, in pandas._libs.hashtable.PyObjectHashTable.get_item
  File "pandas/_libs/hashtable_class_helper.pxi", line 5206, in pandas._libs.hashtable.PyObjectHashTable.get_item
KeyError: 'ocurred_time'

The above exception was the direct cause of the following exception:

Traceback (most recent call last):
  File "/opt/anaconda3/lib/python3.9/site-packages/airflow/models/taskinstance.py", line 1329, in _run_raw_task
    self._execute_task_with_callbacks(context)
  File "/opt/anaconda3/lib/python3.9/site-packages/airflow/models/taskinstance.py", line 1455, in _execute_task_with_callbacks
    result = self._execute_task(context, self.task)
  File "/opt/anaconda3/lib/python3.9/site-packages/airflow/models/taskinstance.py", line 1511, in _execute_task
    result = execute_callable(context=context)
  File "/opt/anaconda3/lib/python3.9/site-packages/airflow/operators/python.py", line 174, in execute
    return_value = self.execute_callable()
  File "/opt/anaconda3/lib/python3.9/site-packages/airflow/operators/python.py", line 185, in execute_callable
    return self.python_callable(*self.op_args, **self.op_kwargs)
  File "/Users/theonewiththelion/airflow/dags/etl_airflowv2.py", line 128, in transformation_date
    time = pd.to_datetime(df_transformed_austin_crime['ocurred_time'].astype(str).str.zfill(4), format='%H%M').dt.time
  File "/opt/anaconda3/lib/python3.9/site-packages/pandas/core/frame.py", line 3505, in __getitem__
    indexer = self.columns.get_loc(key)
  File "/opt/anaconda3/lib/python3.9/site-packages/pandas/core/indexes/base.py", line 3623, in get_loc
    raise KeyError(key) from err
KeyError: 'ocurred_time'

During handling of the above exception, another exception occurred:

Traceback (most recent call last):
  File "/opt/anaconda3/lib/python3.9/site-packages/airflow/models/taskinstance.py", line 2093, in email_alert
    send_email(self.task.email, subject, html_content)
  File "/opt/anaconda3/lib/python3.9/site-packages/airflow/utils/email.py", line 55, in send_email
    return backend(
  File "/opt/anaconda3/lib/python3.9/site-packages/airflow/utils/email.py", line 102, in send_email_smtp
    send_mime_email(e_from=smtp_mail_from, e_to=recipients, mime_msg=msg, conn_id=conn_id, dryrun=dryrun)
  File "/opt/anaconda3/lib/python3.9/site-packages/airflow/utils/email.py", line 210, in send_mime_email
    conn = _get_smtp_connection(smtp_host, smtp_port, smtp_timeout, smtp_ssl)
  File "/opt/anaconda3/lib/python3.9/site-packages/airflow/utils/email.py", line 244, in _get_smtp_connection
    else smtplib.SMTP(host=host, port=port, timeout=timeout)
  File "/opt/anaconda3/lib/python3.9/smtplib.py", line 255, in __init__
    (code, msg) = self.connect(host, port)
  File "/opt/anaconda3/lib/python3.9/smtplib.py", line 341, in connect
    self.sock = self._get_socket(host, port, self.timeout)
  File "/opt/anaconda3/lib/python3.9/smtplib.py", line 312, in _get_socket
    return socket.create_connection((host, port), timeout,
  File "/opt/anaconda3/lib/python3.9/socket.py", line 844, in create_connection
    raise err
  File "/opt/anaconda3/lib/python3.9/socket.py", line 832, in create_connection
    sock.connect(sa)
ConnectionRefusedError: [Errno 61] Connection refused

During handling of the above exception, another exception occurred:

Traceback (most recent call last):
  File "/opt/anaconda3/lib/python3.9/site-packages/airflow/models/taskinstance.py", line 1749, in handle_failure
    self.email_alert(error)
  File "/opt/anaconda3/lib/python3.9/site-packages/airflow/models/taskinstance.py", line 2095, in email_alert
    send_email(self.task.email, subject, html_content_err)
  File "/opt/anaconda3/lib/python3.9/site-packages/airflow/utils/email.py", line 55, in send_email
    return backend(
  File "/opt/anaconda3/lib/python3.9/site-packages/airflow/utils/email.py", line 102, in send_email_smtp
    send_mime_email(e_from=smtp_mail_from, e_to=recipients, mime_msg=msg, conn_id=conn_id, dryrun=dryrun)
  File "/opt/anaconda3/lib/python3.9/site-packages/airflow/utils/email.py", line 210, in send_mime_email
    conn = _get_smtp_connection(smtp_host, smtp_port, smtp_timeout, smtp_ssl)
  File "/opt/anaconda3/lib/python3.9/site-packages/airflow/utils/email.py", line 244, in _get_smtp_connection
    else smtplib.SMTP(host=host, port=port, timeout=timeout)
  File "/opt/anaconda3/lib/python3.9/smtplib.py", line 255, in __init__
    (code, msg) = self.connect(host, port)
  File "/opt/anaconda3/lib/python3.9/smtplib.py", line 341, in connect
    self.sock = self._get_socket(host, port, self.timeout)
  File "/opt/anaconda3/lib/python3.9/smtplib.py", line 312, in _get_socket
    return socket.create_connection((host, port), timeout,
  File "/opt/anaconda3/lib/python3.9/socket.py", line 844, in create_connection
    raise err
  File "/opt/anaconda3/lib/python3.9/socket.py", line 832, in create_connection
    sock.connect(sa)
ConnectionRefusedError: [Errno 61] Connection refused
[2022-09-03 14:03:34,174] {standard_task_runner.py:89} ERROR - Failed to execute job 649 for task date_formatting
Traceback (most recent call last):
  File "/opt/anaconda3/lib/python3.9/site-packages/pandas/core/indexes/base.py", line 3621, in get_loc
    return self._engine.get_loc(casted_key)
  File "pandas/_libs/index.pyx", line 136, in pandas._libs.index.IndexEngine.get_loc
  File "pandas/_libs/index.pyx", line 163, in pandas._libs.index.IndexEngine.get_loc
  File "pandas/_libs/hashtable_class_helper.pxi", line 5198, in pandas._libs.hashtable.PyObjectHashTable.get_item
  File "pandas/_libs/hashtable_class_helper.pxi", line 5206, in pandas._libs.hashtable.PyObjectHashTable.get_item
KeyError: 'ocurred_time'

The above exception was the direct cause of the following exception:

Traceback (most recent call last):
  File "/opt/anaconda3/lib/python3.9/site-packages/airflow/task/task_runner/standard_task_runner.py", line 85, in _start_by_fork
    args.func(args, dag=self.dag)
  File "/opt/anaconda3/lib/python3.9/site-packages/airflow/cli/cli_parser.py", line 48, in command
    return func(*args, **kwargs)
  File "/opt/anaconda3/lib/python3.9/site-packages/airflow/utils/cli.py", line 92, in wrapper
    return f(*args, **kwargs)
  File "/opt/anaconda3/lib/python3.9/site-packages/airflow/cli/commands/task_command.py", line 298, in task_run
    _run_task_by_selected_method(args, dag, ti)
  File "/opt/anaconda3/lib/python3.9/site-packages/airflow/cli/commands/task_command.py", line 107, in _run_task_by_selected_method
    _run_raw_task(args, ti)
  File "/opt/anaconda3/lib/python3.9/site-packages/airflow/cli/commands/task_command.py", line 180, in _run_raw_task
    ti._run_raw_task(
  File "/opt/anaconda3/lib/python3.9/site-packages/airflow/utils/session.py", line 70, in wrapper
    return func(*args, session=session, **kwargs)
  File "/opt/anaconda3/lib/python3.9/site-packages/airflow/models/taskinstance.py", line 1329, in _run_raw_task
    self._execute_task_with_callbacks(context)
  File "/opt/anaconda3/lib/python3.9/site-packages/airflow/models/taskinstance.py", line 1455, in _execute_task_with_callbacks
    result = self._execute_task(context, self.task)
  File "/opt/anaconda3/lib/python3.9/site-packages/airflow/models/taskinstance.py", line 1511, in _execute_task
    result = execute_callable(context=context)
  File "/opt/anaconda3/lib/python3.9/site-packages/airflow/operators/python.py", line 174, in execute
    return_value = self.execute_callable()
  File "/opt/anaconda3/lib/python3.9/site-packages/airflow/operators/python.py", line 185, in execute_callable
    return self.python_callable(*self.op_args, **self.op_kwargs)
  File "/Users/theonewiththelion/airflow/dags/etl_airflowv2.py", line 128, in transformation_date
    time = pd.to_datetime(df_transformed_austin_crime['ocurred_time'].astype(str).str.zfill(4), format='%H%M').dt.time
  File "/opt/anaconda3/lib/python3.9/site-packages/pandas/core/frame.py", line 3505, in __getitem__
    indexer = self.columns.get_loc(key)
  File "/opt/anaconda3/lib/python3.9/site-packages/pandas/core/indexes/base.py", line 3623, in get_loc
    raise KeyError(key) from err
KeyError: 'ocurred_time'
[2022-09-03 14:03:34,224] {local_task_job.py:154} INFO - Task exited with return code 1
[2022-09-03 14:03:34,237] {local_task_job.py:264} INFO - 0 downstream tasks scheduled from follow-on schedule check
