[2022-09-03 14:03:38,290] {taskinstance.py:1032} INFO - Dependencies all met for <TaskInstance: etl_airflow.field_rename scheduled__2022-09-03T04:20:00+00:00 [queued]>
[2022-09-03 14:03:38,294] {taskinstance.py:1032} INFO - Dependencies all met for <TaskInstance: etl_airflow.field_rename scheduled__2022-09-03T04:20:00+00:00 [queued]>
[2022-09-03 14:03:38,294] {taskinstance.py:1238} INFO - 
--------------------------------------------------------------------------------
[2022-09-03 14:03:38,294] {taskinstance.py:1239} INFO - Starting attempt 1 of 1
[2022-09-03 14:03:38,294] {taskinstance.py:1240} INFO - 
--------------------------------------------------------------------------------
[2022-09-03 14:03:38,298] {taskinstance.py:1259} INFO - Executing <Task(PythonOperator): field_rename> on 2022-09-03 04:20:00+00:00
[2022-09-03 14:03:38,306] {standard_task_runner.py:52} INFO - Started process 41323 to run task
[2022-09-03 14:03:38,310] {standard_task_runner.py:76} INFO - Running: ['airflow', 'tasks', 'run', 'etl_airflow', 'field_rename', 'scheduled__2022-09-03T04:20:00+00:00', '--job-id', '650', '--raw', '--subdir', 'DAGS_FOLDER/etl_airflowv2.py', '--cfg-path', '/var/folders/35/pzst1sv14yld_nkt23lk_vmr0000gn/T/tmpnpn1hwb3', '--error-file', '/var/folders/35/pzst1sv14yld_nkt23lk_vmr0000gn/T/tmph9klb2m2']
[2022-09-03 14:03:38,312] {standard_task_runner.py:77} INFO - Job 650: Subtask field_rename
[2022-09-03 14:03:38,335] {logging_mixin.py:109} INFO - Running <TaskInstance: etl_airflow.field_rename scheduled__2022-09-03T04:20:00+00:00 [running]> on host 1.0.0.127.in-addr.arpa
[2022-09-03 14:03:38,361] {taskinstance.py:1424} INFO - Exporting the following env vars:
AIRFLOW_CTX_DAG_EMAIL=jonathan.dejesus.azor@gmail.com
AIRFLOW_CTX_DAG_OWNER=admin
AIRFLOW_CTX_DAG_ID=etl_airflow
AIRFLOW_CTX_TASK_ID=field_rename
AIRFLOW_CTX_EXECUTION_DATE=2022-09-03T04:20:00+00:00
AIRFLOW_CTX_DAG_RUN_ID=scheduled__2022-09-03T04:20:00+00:00
[2022-09-03 14:03:38,575] {_metadata.py:99} WARNING - Compute Engine Metadata server unavailable on attempt 1 of 3. Reason: [Errno 64] Host is down
[2022-09-03 14:03:38,575] {_metadata.py:99} WARNING - Compute Engine Metadata server unavailable on attempt 2 of 3. Reason: [Errno 64] Host is down
[2022-09-03 14:03:38,575] {_metadata.py:99} WARNING - Compute Engine Metadata server unavailable on attempt 3 of 3. Reason: [Errno 64] Host is down
[2022-09-03 14:03:38,576] {_default.py:290} WARNING - Authentication failed using Compute Engine authentication due to unavailable metadata server.
[2022-09-03 14:03:39,595] {logging_mixin.py:109} WARNING - Downloading:   0%|          | 0/200 [00:00<?, ?rows/s]
[2022-09-03 14:03:39,796] {logging_mixin.py:109} WARNING - Downloading: 100%|##########| 200/200 [00:00<00:00, 1001.10rows/s]
[2022-09-03 14:03:39,796] {logging_mixin.py:109} WARNING - Downloading: 100%|##########| 200/200 [00:00<00:00, 997.66rows/s] 
[2022-09-03 14:03:39,796] {logging_mixin.py:109} WARNING - 
[2022-09-03 14:03:39,802] {logging_mixin.py:109} INFO - Staging table extraction successfully completed
[2022-09-03 14:03:39,811] {logging_mixin.py:109} INFO -      incident_report_number  ... rep_time
0               20222381575  ...     2129
1               20222381479  ...     1935
2               20222381858  ...     2337
3               20222381688  ...     2201
4               20222381348  ...     1830
..                      ...  ...      ...
195             20222390765  ...     1208
196             20222391622  ...        7
197             20222391707  ...       27
198             20222391682  ...       37
199             20222391561  ...       10

[200 rows x 9 columns]
[2022-09-03 14:03:43,380] {local_task_job.py:211} WARNING - State of this instance has been externally set to None. Terminating instance.
[2022-09-03 14:03:43,385] {process_utils.py:120} INFO - Sending Signals.SIGTERM to group 41323. PIDs of all processes in the group: [41324, 41323]
[2022-09-03 14:03:43,386] {process_utils.py:75} INFO - Sending the signal Signals.SIGTERM to group 41323
[2022-09-03 14:03:43,386] {taskinstance.py:1408} ERROR - Received SIGTERM. Terminating subprocesses.
[2022-09-03 14:03:43,392] {taskinstance.py:1700} ERROR - Task failed with exception
Traceback (most recent call last):
  File "/opt/anaconda3/lib/python3.9/site-packages/airflow/models/taskinstance.py", line 1329, in _run_raw_task
    self._execute_task_with_callbacks(context)
  File "/opt/anaconda3/lib/python3.9/site-packages/airflow/models/taskinstance.py", line 1455, in _execute_task_with_callbacks
    result = self._execute_task(context, self.task)
  File "/opt/anaconda3/lib/python3.9/site-packages/airflow/models/taskinstance.py", line 1511, in _execute_task
    result = execute_callable(context=context)
  File "/opt/anaconda3/lib/python3.9/site-packages/airflow/operators/python.py", line 174, in execute
    return_value = self.execute_callable()
  File "/opt/anaconda3/lib/python3.9/site-packages/airflow/operators/python.py", line 185, in execute_callable
    return self.python_callable(*self.op_args, **self.op_kwargs)
  File "/Users/theonewiththelion/airflow/dags/etl_airflowv2.py", line 109, in transformation_rename
    pandas_gbq.to_gbq(df_transformed_austin_crime, table_id, project_id='crafty-shield-359406', if_exists='replace')
  File "/opt/anaconda3/lib/python3.9/site-packages/pandas_gbq/gbq.py", line 1198, in to_gbq
    connector.load_data(
  File "/opt/anaconda3/lib/python3.9/site-packages/pandas_gbq/gbq.py", line 591, in load_data
    chunks = load.load_chunks(
  File "/opt/anaconda3/lib/python3.9/site-packages/pandas_gbq/load.py", line 240, in load_chunks
    load_parquet(
  File "/opt/anaconda3/lib/python3.9/site-packages/pandas_gbq/load.py", line 131, in load_parquet
    client.load_table_from_dataframe(
  File "/opt/anaconda3/lib/python3.9/site-packages/google/cloud/bigquery/job/base.py", line 728, in result
    return super(_AsyncJob, self).result(timeout=timeout, **kwargs)
  File "/opt/anaconda3/lib/python3.9/site-packages/google/api_core/future/polling.py", line 132, in result
    self._blocking_poll(timeout=timeout, **kwargs)
  File "/opt/anaconda3/lib/python3.9/site-packages/google/api_core/future/polling.py", line 110, in _blocking_poll
    retry_(self._done_or_raise)(**kwargs)
  File "/opt/anaconda3/lib/python3.9/site-packages/google/api_core/retry.py", line 283, in retry_wrapped_func
    return retry_target(
  File "/opt/anaconda3/lib/python3.9/site-packages/google/api_core/retry.py", line 218, in retry_target
    time.sleep(sleep)
  File "/opt/anaconda3/lib/python3.9/site-packages/airflow/models/taskinstance.py", line 1410, in signal_handler
    raise AirflowException("Task received SIGTERM signal")
airflow.exceptions.AirflowException: Task received SIGTERM signal
[2022-09-03 14:03:43,396] {taskinstance.py:1267} INFO - Marking task as FAILED. dag_id=etl_airflow, task_id=field_rename, execution_date=20220903T042000, start_date=20220903T190338, end_date=20220903T190343
[2022-09-03 14:03:43,402] {logging_mixin.py:109} WARNING - /opt/anaconda3/lib/python3.9/site-packages/airflow/utils/context.py:152 AirflowContextDeprecationWarning: Accessing 'execution_date' from the template is deprecated and will be removed in a future version. Please use 'data_interval_start' or 'logical_date' instead.
[2022-09-03 14:03:43,403] {logging_mixin.py:109} WARNING - /opt/anaconda3/lib/python3.9/site-packages/airflow/utils/context.py:152 AirflowContextDeprecationWarning: Accessing 'next_ds' from the template is deprecated and will be removed in a future version. Please use '{{ data_interval_end | ds }}' instead.
[2022-09-03 14:03:43,403] {logging_mixin.py:109} WARNING - /opt/anaconda3/lib/python3.9/site-packages/airflow/utils/context.py:152 AirflowContextDeprecationWarning: Accessing 'next_ds_nodash' from the template is deprecated and will be removed in a future version. Please use '{{ data_interval_end | ds_nodash }}' instead.
[2022-09-03 14:03:43,404] {logging_mixin.py:109} WARNING - /opt/anaconda3/lib/python3.9/site-packages/airflow/utils/context.py:152 AirflowContextDeprecationWarning: Accessing 'next_execution_date' from the template is deprecated and will be removed in a future version. Please use 'data_interval_end' instead.
[2022-09-03 14:03:43,404] {logging_mixin.py:109} WARNING - /opt/anaconda3/lib/python3.9/site-packages/airflow/utils/context.py:152 AirflowContextDeprecationWarning: Accessing 'prev_ds' from the template is deprecated and will be removed in a future version.
[2022-09-03 14:03:43,405] {logging_mixin.py:109} WARNING - /opt/anaconda3/lib/python3.9/site-packages/airflow/utils/context.py:152 AirflowContextDeprecationWarning: Accessing 'prev_ds_nodash' from the template is deprecated and will be removed in a future version.
[2022-09-03 14:03:43,405] {logging_mixin.py:109} WARNING - /opt/anaconda3/lib/python3.9/site-packages/airflow/utils/context.py:152 AirflowContextDeprecationWarning: Accessing 'prev_execution_date' from the template is deprecated and will be removed in a future version.
[2022-09-03 14:03:43,406] {logging_mixin.py:109} WARNING - /opt/anaconda3/lib/python3.9/site-packages/airflow/utils/context.py:152 AirflowContextDeprecationWarning: Accessing 'prev_execution_date_success' from the template is deprecated and will be removed in a future version. Please use 'prev_data_interval_start_success' instead.
[2022-09-03 14:03:43,406] {logging_mixin.py:109} WARNING - /opt/anaconda3/lib/python3.9/site-packages/airflow/utils/context.py:152 AirflowContextDeprecationWarning: Accessing 'tomorrow_ds' from the template is deprecated and will be removed in a future version.
[2022-09-03 14:03:43,407] {logging_mixin.py:109} WARNING - /opt/anaconda3/lib/python3.9/site-packages/airflow/utils/context.py:152 AirflowContextDeprecationWarning: Accessing 'tomorrow_ds_nodash' from the template is deprecated and will be removed in a future version.
[2022-09-03 14:03:43,407] {logging_mixin.py:109} WARNING - /opt/anaconda3/lib/python3.9/site-packages/airflow/utils/context.py:152 AirflowContextDeprecationWarning: Accessing 'yesterday_ds' from the template is deprecated and will be removed in a future version.
[2022-09-03 14:03:43,408] {logging_mixin.py:109} WARNING - /opt/anaconda3/lib/python3.9/site-packages/airflow/utils/context.py:152 AirflowContextDeprecationWarning: Accessing 'yesterday_ds_nodash' from the template is deprecated and will be removed in a future version.
[2022-09-03 14:03:43,413] {logging_mixin.py:109} WARNING - /opt/anaconda3/lib/python3.9/site-packages/airflow/utils/email.py:102 PendingDeprecationWarning: Fetching SMTP credentials from configuration variables will be deprecated in a future release. Please set credentials using a connection instead.
[2022-09-03 14:03:43,413] {configuration.py:381} WARNING - section/key [smtp/smtp_user] not found in config
[2022-09-03 14:03:43,413] {email.py:208} INFO - Email alerting: attempt 1
[2022-09-03 14:03:43,417] {configuration.py:381} WARNING - section/key [smtp/smtp_user] not found in config
[2022-09-03 14:03:43,417] {email.py:208} INFO - Email alerting: attempt 1
[2022-09-03 14:03:43,417] {taskinstance.py:1751} ERROR - Failed to send email to: jonathan.dejesus.azor@gmail.com
Traceback (most recent call last):
  File "/opt/anaconda3/lib/python3.9/site-packages/airflow/models/taskinstance.py", line 1329, in _run_raw_task
    self._execute_task_with_callbacks(context)
  File "/opt/anaconda3/lib/python3.9/site-packages/airflow/models/taskinstance.py", line 1455, in _execute_task_with_callbacks
    result = self._execute_task(context, self.task)
  File "/opt/anaconda3/lib/python3.9/site-packages/airflow/models/taskinstance.py", line 1511, in _execute_task
    result = execute_callable(context=context)
  File "/opt/anaconda3/lib/python3.9/site-packages/airflow/operators/python.py", line 174, in execute
    return_value = self.execute_callable()
  File "/opt/anaconda3/lib/python3.9/site-packages/airflow/operators/python.py", line 185, in execute_callable
    return self.python_callable(*self.op_args, **self.op_kwargs)
  File "/Users/theonewiththelion/airflow/dags/etl_airflowv2.py", line 109, in transformation_rename
    pandas_gbq.to_gbq(df_transformed_austin_crime, table_id, project_id='crafty-shield-359406', if_exists='replace')
  File "/opt/anaconda3/lib/python3.9/site-packages/pandas_gbq/gbq.py", line 1198, in to_gbq
    connector.load_data(
  File "/opt/anaconda3/lib/python3.9/site-packages/pandas_gbq/gbq.py", line 591, in load_data
    chunks = load.load_chunks(
  File "/opt/anaconda3/lib/python3.9/site-packages/pandas_gbq/load.py", line 240, in load_chunks
    load_parquet(
  File "/opt/anaconda3/lib/python3.9/site-packages/pandas_gbq/load.py", line 131, in load_parquet
    client.load_table_from_dataframe(
  File "/opt/anaconda3/lib/python3.9/site-packages/google/cloud/bigquery/job/base.py", line 728, in result
    return super(_AsyncJob, self).result(timeout=timeout, **kwargs)
  File "/opt/anaconda3/lib/python3.9/site-packages/google/api_core/future/polling.py", line 132, in result
    self._blocking_poll(timeout=timeout, **kwargs)
  File "/opt/anaconda3/lib/python3.9/site-packages/google/api_core/future/polling.py", line 110, in _blocking_poll
    retry_(self._done_or_raise)(**kwargs)
  File "/opt/anaconda3/lib/python3.9/site-packages/google/api_core/retry.py", line 283, in retry_wrapped_func
    return retry_target(
  File "/opt/anaconda3/lib/python3.9/site-packages/google/api_core/retry.py", line 218, in retry_target
    time.sleep(sleep)
  File "/opt/anaconda3/lib/python3.9/site-packages/airflow/models/taskinstance.py", line 1410, in signal_handler
    raise AirflowException("Task received SIGTERM signal")
airflow.exceptions.AirflowException: Task received SIGTERM signal

During handling of the above exception, another exception occurred:

Traceback (most recent call last):
  File "/opt/anaconda3/lib/python3.9/site-packages/airflow/models/taskinstance.py", line 2093, in email_alert
    send_email(self.task.email, subject, html_content)
  File "/opt/anaconda3/lib/python3.9/site-packages/airflow/utils/email.py", line 55, in send_email
    return backend(
  File "/opt/anaconda3/lib/python3.9/site-packages/airflow/utils/email.py", line 102, in send_email_smtp
    send_mime_email(e_from=smtp_mail_from, e_to=recipients, mime_msg=msg, conn_id=conn_id, dryrun=dryrun)
  File "/opt/anaconda3/lib/python3.9/site-packages/airflow/utils/email.py", line 210, in send_mime_email
    conn = _get_smtp_connection(smtp_host, smtp_port, smtp_timeout, smtp_ssl)
  File "/opt/anaconda3/lib/python3.9/site-packages/airflow/utils/email.py", line 244, in _get_smtp_connection
    else smtplib.SMTP(host=host, port=port, timeout=timeout)
  File "/opt/anaconda3/lib/python3.9/smtplib.py", line 255, in __init__
    (code, msg) = self.connect(host, port)
  File "/opt/anaconda3/lib/python3.9/smtplib.py", line 341, in connect
    self.sock = self._get_socket(host, port, self.timeout)
  File "/opt/anaconda3/lib/python3.9/smtplib.py", line 312, in _get_socket
    return socket.create_connection((host, port), timeout,
  File "/opt/anaconda3/lib/python3.9/socket.py", line 844, in create_connection
    raise err
  File "/opt/anaconda3/lib/python3.9/socket.py", line 832, in create_connection
    sock.connect(sa)
ConnectionRefusedError: [Errno 61] Connection refused

During handling of the above exception, another exception occurred:

Traceback (most recent call last):
  File "/opt/anaconda3/lib/python3.9/site-packages/airflow/models/taskinstance.py", line 1749, in handle_failure
    self.email_alert(error)
  File "/opt/anaconda3/lib/python3.9/site-packages/airflow/models/taskinstance.py", line 2095, in email_alert
    send_email(self.task.email, subject, html_content_err)
  File "/opt/anaconda3/lib/python3.9/site-packages/airflow/utils/email.py", line 55, in send_email
    return backend(
  File "/opt/anaconda3/lib/python3.9/site-packages/airflow/utils/email.py", line 102, in send_email_smtp
    send_mime_email(e_from=smtp_mail_from, e_to=recipients, mime_msg=msg, conn_id=conn_id, dryrun=dryrun)
  File "/opt/anaconda3/lib/python3.9/site-packages/airflow/utils/email.py", line 210, in send_mime_email
    conn = _get_smtp_connection(smtp_host, smtp_port, smtp_timeout, smtp_ssl)
  File "/opt/anaconda3/lib/python3.9/site-packages/airflow/utils/email.py", line 244, in _get_smtp_connection
    else smtplib.SMTP(host=host, port=port, timeout=timeout)
  File "/opt/anaconda3/lib/python3.9/smtplib.py", line 255, in __init__
    (code, msg) = self.connect(host, port)
  File "/opt/anaconda3/lib/python3.9/smtplib.py", line 341, in connect
    self.sock = self._get_socket(host, port, self.timeout)
  File "/opt/anaconda3/lib/python3.9/smtplib.py", line 312, in _get_socket
    return socket.create_connection((host, port), timeout,
  File "/opt/anaconda3/lib/python3.9/socket.py", line 844, in create_connection
    raise err
  File "/opt/anaconda3/lib/python3.9/socket.py", line 832, in create_connection
    sock.connect(sa)
ConnectionRefusedError: [Errno 61] Connection refused
[2022-09-03 14:03:43,426] {standard_task_runner.py:89} ERROR - Failed to execute job 650 for task field_rename
Traceback (most recent call last):
  File "/opt/anaconda3/lib/python3.9/site-packages/airflow/task/task_runner/standard_task_runner.py", line 85, in _start_by_fork
    args.func(args, dag=self.dag)
  File "/opt/anaconda3/lib/python3.9/site-packages/airflow/cli/cli_parser.py", line 48, in command
    return func(*args, **kwargs)
  File "/opt/anaconda3/lib/python3.9/site-packages/airflow/utils/cli.py", line 92, in wrapper
    return f(*args, **kwargs)
  File "/opt/anaconda3/lib/python3.9/site-packages/airflow/cli/commands/task_command.py", line 298, in task_run
    _run_task_by_selected_method(args, dag, ti)
  File "/opt/anaconda3/lib/python3.9/site-packages/airflow/cli/commands/task_command.py", line 107, in _run_task_by_selected_method
    _run_raw_task(args, ti)
  File "/opt/anaconda3/lib/python3.9/site-packages/airflow/cli/commands/task_command.py", line 180, in _run_raw_task
    ti._run_raw_task(
  File "/opt/anaconda3/lib/python3.9/site-packages/airflow/utils/session.py", line 70, in wrapper
    return func(*args, session=session, **kwargs)
  File "/opt/anaconda3/lib/python3.9/site-packages/airflow/models/taskinstance.py", line 1329, in _run_raw_task
    self._execute_task_with_callbacks(context)
  File "/opt/anaconda3/lib/python3.9/site-packages/airflow/models/taskinstance.py", line 1455, in _execute_task_with_callbacks
    result = self._execute_task(context, self.task)
  File "/opt/anaconda3/lib/python3.9/site-packages/airflow/models/taskinstance.py", line 1511, in _execute_task
    result = execute_callable(context=context)
  File "/opt/anaconda3/lib/python3.9/site-packages/airflow/operators/python.py", line 174, in execute
    return_value = self.execute_callable()
  File "/opt/anaconda3/lib/python3.9/site-packages/airflow/operators/python.py", line 185, in execute_callable
    return self.python_callable(*self.op_args, **self.op_kwargs)
  File "/Users/theonewiththelion/airflow/dags/etl_airflowv2.py", line 109, in transformation_rename
    pandas_gbq.to_gbq(df_transformed_austin_crime, table_id, project_id='crafty-shield-359406', if_exists='replace')
  File "/opt/anaconda3/lib/python3.9/site-packages/pandas_gbq/gbq.py", line 1198, in to_gbq
    connector.load_data(
  File "/opt/anaconda3/lib/python3.9/site-packages/pandas_gbq/gbq.py", line 591, in load_data
    chunks = load.load_chunks(
  File "/opt/anaconda3/lib/python3.9/site-packages/pandas_gbq/load.py", line 240, in load_chunks
    load_parquet(
  File "/opt/anaconda3/lib/python3.9/site-packages/pandas_gbq/load.py", line 131, in load_parquet
    client.load_table_from_dataframe(
  File "/opt/anaconda3/lib/python3.9/site-packages/google/cloud/bigquery/job/base.py", line 728, in result
    return super(_AsyncJob, self).result(timeout=timeout, **kwargs)
  File "/opt/anaconda3/lib/python3.9/site-packages/google/api_core/future/polling.py", line 132, in result
    self._blocking_poll(timeout=timeout, **kwargs)
  File "/opt/anaconda3/lib/python3.9/site-packages/google/api_core/future/polling.py", line 110, in _blocking_poll
    retry_(self._done_or_raise)(**kwargs)
  File "/opt/anaconda3/lib/python3.9/site-packages/google/api_core/retry.py", line 283, in retry_wrapped_func
    return retry_target(
  File "/opt/anaconda3/lib/python3.9/site-packages/google/api_core/retry.py", line 218, in retry_target
    time.sleep(sleep)
  File "/opt/anaconda3/lib/python3.9/site-packages/airflow/models/taskinstance.py", line 1410, in signal_handler
    raise AirflowException("Task received SIGTERM signal")
airflow.exceptions.AirflowException: Task received SIGTERM signal
[2022-09-03 14:03:43,444] {process_utils.py:70} INFO - Process psutil.Process(pid=41323, status='terminated', exitcode=1, started='14:03:38') (41323) terminated with exit code 1
[2022-09-03 14:03:43,445] {process_utils.py:70} INFO - Process psutil.Process(pid=41324, status='terminated', started='14:03:39') (41324) terminated with exit code None
